{"e": "depthUpdate", "E": 1773437557714, "s": "BTCUSDT", "U": 90101519129, "u": 90101519548, "b": [["71196.80000000", "0.85080000"], ["71196.79000000", "0.00024000"], ["71196.59000000", "0.00000000"], ["71196.01000000", "0.00008000"], ["71196.00000000", "0.00000000"], ["71195.99000000", "0.00000000"], ["71195.22000000", "0.00000000"], ["71195.21000000", "0.00000000"], ["71194.89000000", "0.00000000"], ["71194.53000000", "0.00000000"], ["71194.20000000", "0.00000000"], ["71193.88000000", "0.00008000"], ["71193.87000000", "0.00016000"], ["71193.74000000", "0.00008000"], ["71193.33000000", "0.00000000"], ["71193.19000000", "0.00008000"], ["71193.18000000", "0.01564000"], ["71192.90000000", "0.00000000"], ["71192.89000000", "0.00000000"], ["71192.65000000", "0.00000000"], ["71191.89000000", "0.00008000"], ["71191.88000000", "0.00131000"], ["71191.87000000", "0.00000000"], ["71191.86000000", "0.00000000"], ["71191.55000000", "0.00000000"], ["71191.41000000", "0.00008000"], ["71191.40000000", "0.02494000"], ["71188.90000000", "0.19092000"], ["71188.89000000", "0.08161000"], ["71188.87000000", "0.00000000"], ["71188.86000000", "0.02216000"], ["71188.77000000", "0.00000000"], ["71188.76000000", "0.02416000"], ["71188.75000000", "0.00000000"], ["71188.74000000", "0.02816000"], ["71188.59000000", "0.00000000"], ["71188.58000000", "0.21485000"], ["71188.57000000", "0.00000000"], ["71188.47000000", "0.02816000"], ["71188.12000000", "0.05416000"], ["71187.54000000", "0.00200000"], ["71187.36000000", "0.00000000"], ["71187.27000000", "0.00069000"], ["71187.11000000", "0.18962000"], ["71186.27000000", "0.00837000"], ["71185.79000000", "0.00141000"], ["71185.71000000", "0.00187000"], ["71185.05000000", "0.00029000"], ["71185.02000000", "0.02821000"], ["71184.65000000", "0.00000000"], ["71184.63000000", "0.00000000"], ["71182.76000000", "0.23075000"], ["71182.70000000", "0.00480000"], ["71182.06000000", "1.43380000"], ["71180.43000000", "0.00702000"], ["71179.71000000", "0.21850000"], ["71179.54000000", "0.19002000"], ["71179.22000000", "2.64555000"], ["71179.20000000", "0.00000000"], ["71177.43000000", "0.02008000"], ["71177.26000000", "0.04215000"], ["71176.20000000", "0.00000000"], ["71174.47000000", "0.42137000"], ["71174.46000000", "0.00000000"], ["71171.00000000", "1.42116000"], ["71170.98000000", "0.00000000"], ["71170.75000000", "0.00140000"], ["71170.44000000", "0.50575000"], ["71169.74000000", "0.00200000"], ["71169.73000000", "0.00000000"], ["71168.70000000", "0.00200000"], ["71168.48000000", "0.19680000"], ["71167.78000000", "0.50568000"], ["71167.14000000", "0.00000000"], ["71164.56000000", "0.37885000"], ["71163.19000000", "0.00000000"], ["71162.23000000", "0.50580000"], ["71162.20000000", "0.00200000"], ["71160.12000000", "0.00000000"], ["71159.06000000", "0.00000000"], ["71157.28000000", "0.00000000"], ["71154.66000000", "0.00000000"], ["71153.81000000", "0.00000000"], ["71151.61000000", "0.00361000"], ["71143.59000000", "0.05548000"], ["71138.21000000", "0.03086000"], ["71134.01000000", "0.00000000"], ["71130.04000000", "0.00000000"], ["71126.89000000", "0.04387000"], ["71119.78000000", "0.00000000"], ["71104.63000000", "0.06314000"], ["71085.57000000", "0.00000000"], ["71085.02000000", "0.09783000"], ["71082.56000000", "0.07928000"], ["64077.12000000", "0.00036000"]], "a": [["71196.81000000", "1.59064000"], ["71198.22000000", "0.15932000"], ["71198.23000000", "0.00016000"], ["71198.24000000", "0.16854000"], ["71199.41000000", "0.02000000"], ["71199.80000000", "0.00141000"], ["71199.98000000", "0.00702000"], ["71199.99000000", "0.00032000"], ["71200.00000000", "0.11893000"], ["71200.49000000", "0.00141000"], ["71200.90000000", "0.00702000"], ["71201.04000000", "0.00016000"], ["71201.05000000", "0.02583000"], ["71201.47000000", "0.01569000"], ["71202.76000000", "0.37055000"], ["71202.77000000", "0.00702000"], ["71202.78000000", "0.10016000"], ["71203.25000000", "0.00016000"], ["71204.28000000", "1.67950000"], ["71204.29000000", "0.00000000"], ["71204.30000000", "1.68098000"], ["71205.73000000", "0.06900000"], ["71205.81000000", "0.00000000"], ["71205.82000000", "0.00008000"], ["71205.91000000", "1.43380000"], ["71207.74000000", "0.00000000"], ["71207.76000000", "1.32495000"], ["71207.77000000", "0.00000000"], ["71208.11000000", "0.00000000"], ["71208.53000000", "0.00040000"], ["71208.74000000", "0.00000000"], ["71209.27000000", "0.00000000"], ["71209.87000000", "0.42136000"], ["71209.89000000", "0.00000000"], ["71210.26000000", "0.00069000"], ["71210.27000000", "0.00000000"], ["71211.03000000", "0.00530000"], ["71211.14000000", "0.00361000"], ["71211.50000000", "0.00200000"], ["71211.83000000", "0.85373000"], ["71212.08000000", "0.50545000"], ["71213.07000000", "1.48271000"], ["71213.84000000", "0.00000000"], ["71213.86000000", "0.00000000"], ["71214.55000000", "0.00000000"], ["71215.06000000", "0.00000000"], ["71215.37000000", "0.00000000"], ["71215.89000000", "0.00000000"], ["71217.74000000", "0.03448000"], ["71218.50000000", "0.00200000"], ["71219.20000000", "0.00000000"], ["71219.25000000", "0.05581000"], ["71222.28000000", "0.04215000"], ["71225.40000000", "0.00000000"], ["71228.13000000", "0.00000000"], ["71228.54000000", "0.00000000"], ["71230.99000000", "0.00000000"], ["71233.20000000", "0.00000000"], ["71233.33000000", "0.00625000"], ["71241.80000000", "0.00140000"], ["71243.76000000", "0.07068000"], ["71245.00000000", "0.00000000"], ["71250.80000000", "0.00000000"], ["71262.07000000", "0.00000000"], ["71264.21000000", "0.70150000"], ["71265.04000000", "0.00000000"], ["71265.16000000", "0.51461000"], ["71280.00000000", "0.00128000"], ["71304.57000000", "0.00000000"], ["71314.30000000", "0.00000000"], ["71322.03000000", "0.00399000"], ["71331.69000000", "0.00000000"], ["71356.95000000", "0.01213000"], ["71370.52000000", "0.02809000"], ["71381.69000000", "0.04197000"], ["71386.99000000", "0.00000000"], ["71388.31000000", "0.00000000"]]}
{"e": "depthUpdate", "E": 1773437557815, "s": "BTCUSDT", "U": 90101519549, "u": 90101519693, "b": [["71196.80000000", "1.02387000"], ["71196.01000000", "0.00000000"], ["71193.88000000", "0.00000000"], ["71193.87000000", "0.00000000"], ["71193.19000000", "0.00008000"], ["71193.18000000", "0.00016000"], ["71192.88000000", "0.00200000"], ["71192.19000000", "0.00029000"], ["71191.89000000", "0.00115000"], ["71191.88000000", "0.00000000"], ["71191.40000000", "0.00016000"], ["71191.10000000", "0.00200000"], ["71189.32000000", "0.00340000"], ["71188.90000000", "0.54364000"], ["71188.89000000", "0.08177000"], ["71188.58000000", "0.00016000"], ["71188.53000000", "0.01124000"], ["71188.47000000", "0.02800000"], ["71188.12000000", "0.05400000"], ["71187.89000000", "0.09711000"], ["71186.39000000", "0.00562000"], ["71186.38000000", "0.00562000"], ["71186.20000000", "0.09711000"], ["71185.79000000", "0.00000000"], ["71185.63000000", "0.86199000"], ["71185.62000000", "1.43380000"], ["71185.28000000", "1.09643000"], ["71185.02000000", "0.00000000"], ["71182.07000000", "2.13315000"], ["71182.06000000", "2.53023000"], ["71179.71000000", "0.00000000"], ["71179.54000000", "0.00009000"], ["71179.22000000", "1.68082000"], ["71178.64000000", "0.00200000"], ["71177.26000000", "0.00000000"], ["71177.24000000", "0.04215000"], ["71174.47000000", "0.00000000"], ["71171.01000000", "0.42136000"], ["71169.56000000", "0.06000000"], ["71164.40000000", "0.00000000"], ["71162.62000000", "0.00000000"], ["71160.84000000", "0.00000000"], ["71155.07000000", "0.02803000"], ["71138.80000000", "0.04387000"], ["71126.89000000", "0.00000000"], ["71109.83000000", "0.48728000"], ["71080.72000000", "0.04426000"], ["64077.12000000", "0.00054000"]], "a": [["71196.81000000", "1.49400000"], ["71198.20000000", "0.00016000"], ["71198.21000000", "0.10287000"], ["71198.22000000", "0.00216000"], ["71198.24000000", "0.16854000"], ["71198.54000000", "0.00016000"], ["71198.55000000", "0.02575000"], ["71199.40000000", "0.00016000"], ["71199.41000000", "0.02016000"], ["71199.98000000", "0.00718000"], ["71199.99000000", "0.00016000"], ["71200.00000000", "0.11893000"], ["71200.13000000", "0.00000000"], ["71200.49000000", "0.00000000"], ["71201.04000000", "0.00000000"], ["71201.20000000", "0.04040000"], ["71201.55000000", "0.00000000"], ["71202.74000000", "0.40384000"], ["71202.75000000", "1.09643000"], ["71202.76000000", "0.00000000"], ["71202.78000000", "0.10000000"], ["71203.25000000", "0.00000000"], ["71204.30000000", "1.68082000"], ["71204.57000000", "0.00000000"], ["71209.78000000", "0.06000000"], ["71217.54000000", "0.00000000"], ["71219.25000000", "0.00000000"], ["71221.35000000", "0.00000000"], ["71222.28000000", "0.00000000"], ["71223.59000000", "0.37885000"], ["71225.71000000", "0.04423000"], ["71225.94000000", "0.02748000"], ["71227.14000000", "0.00000000"], ["71227.15000000", "0.00000000"], ["71230.04000000", "0.05581000"], ["71232.94000000", "0.00000000"], ["71236.54000000", "0.48641000"], ["71294.29000000", "0.15965000"]]}
{"e": "aggTrade", "E": 1773437557838, "s": "BTCUSDT", "a": 3904057844, "p": "71196.81000000", "q": "0.01404000", "f": 6104984212, "l": 6104984212, "T": 1773437557838, "m": false, "M": true}
{"e": "depthUpdate", "E": 1773437557914, "s": "BTCUSDT", "U": 90101519694, "u": 90101519756, "b": [["71196.80000000", "1.02371000"], ["71193.19000000", "0.00000000"], ["71193.18000000", "0.00000000"], ["71192.19000000", "0.00147000"], ["71191.89000000", "0.00000000"], ["71191.41000000", "0.00000000"], ["71191.40000000", "0.00000000"], ["71188.74000000", "0.02800000"], ["71188.58000000", "0.00000000"], ["71187.10000000", "0.00000000"], ["71186.74000000", "0.00141000"], ["71182.76000000", "0.00011000"], ["71166.86000000", "0.00000000"], ["71164.03000000", "0.02400000"], ["71160.34000000", "0.03522000"], ["71149.96000000", "0.11570000"], ["71138.20000000", "0.00000000"], ["71073.20000000", "0.05267000"], ["64080.00000000", "0.04327000"], ["64077.12000000", "0.00090000"], ["64076.00000000", "0.00010000"], ["56957.00000000", "0.00470000"]], "a": [["71196.81000000", "1.57692000"], ["71198.21000000", "0.10303000"], ["71198.22000000", "0.00200000"], ["71198.24000000", "0.16854000"], ["71198.55000000", "0.02591000"], ["71199.62000000", "0.00141000"], ["71200.90000000", "0.00718000"], ["71201.05000000", "0.02599000"], ["71210.26000000", "0.00000000"], ["71212.12000000", "0.02000000"], ["71212.47000000", "0.02000000"], ["71216.78000000", "0.50568000"], ["71222.39000000", "0.00000000"], ["71270.16000000", "0.06450000"], ["71292.23000000", "0.07835000"]]}
{"e": "depthUpdate", "E": 1773437558015, "s": "BTCUSDT", "U": 90101519757, "u": 90101519792, "b": [["71196.80000000", "1.02387000"], ["71195.01000000", "0.00015000"], ["71189.96000000", "0.00008000"], ["71189.95000000", "0.01124000"], ["71189.32000000", "0.00348000"], ["71189.31000000", "0.09711000"], ["71189.14000000", "0.00000000"], ["71188.90000000", "0.41218000"], ["71188.53000000", "0.00000000"], ["71187.89000000", "0.00000000"], ["71186.39000000", "0.00000000"], ["71186.38000000", "0.00000000"], ["71185.44000000", "0.00008000"], ["71181.84000000", "0.00300000"], ["71169.43000000", "0.00361000"], ["71151.61000000", "0.00000000"], ["71129.24000000", "0.00000000"], ["71128.40000000", "0.48723000"], ["71039.87000000", "0.00000000"], ["71039.79000000", "0.00862000"], ["71027.51000000", "0.00000000"], ["64077.12000000", "0.00126000"], ["56957.44000000", "0.00035000"], ["56957.00000000", "0.00070000"]], "a": [["71209.00000000", "0.01000000"], ["71218.21000000", "0.00000000"], ["71220.02000000", "0.00000000"], ["71225.29000000", "0.00702000"], ["71244.74000000", "0.00000000"], ["71248.55000000", "0.00868000"], ["71322.03000000", "0.00000000"], ["71330.27000000", "0.00399000"]]}
{"e": "kline", "E": 1773437558047, "s": "BTCUSDT", "k": {"t": 1773437520000, "T": 1773437579999, "s": "BTCUSDT", "i": "1m", "f": 6104983042, "L": 6104984212, "o": "71164.00000000", "c": "71196.81000000", "h": "71200.00000000", "l": "71155.65000000", "v": "14.68178000", "n": 1171, "x": false, "q": "1044834.07666060", "V": "11.81526000", "Q": "840779.46637980", "B": "0"}}
{"e": "aggTrade", "E": 1773437558070, "s": "BTCUSDT", "a": 3904057845, "p": "71196.80000000", "q": "0.00308000", "f": 6104984213, "l": 6104984216, "T": 1773437558070, "m": true, "M": true}
{"e": "aggTrade", "E": 1773437558096, "s": "BTCUSDT", "a": 3904057846, "p": "71196.80000000", "q": "0.00028000", "f": 6104984217, "l": 6104984217, "T": 1773437558095, "m": true, "M": true}
{"e": "depthUpdate", "E": 1773437558114, "s": "BTCUSDT", "U": 90101519793, "u": 90101519852, "b": [["71196.80000000", "1.02067000"], ["71194.62000000", "0.00141000"], ["71192.73000000", "0.00057000"], ["71190.31000000", "0.00008000"], ["71190.30000000", "0.02482000"], ["71189.95000000", "0.01140000"], ["71189.31000000", "0.09727000"], ["71188.74000000", "0.02816000"], ["71129.85000000", "0.00000000"], ["71033.99000000", "0.07295000"], ["71033.33000000", "0.07348000"], ["71032.24000000", "0.07295000"], ["71028.65000000", "0.07295000"], ["71026.02000000", "0.07295000"], ["71024.73000000", "0.07295000"], ["71023.27000000", "0.07295000"], ["71022.00000000", "0.07415000"], ["71018.68000000", "0.07295000"], ["71017.23000000", "0.07295000"], ["71016.74000000", "0.07295000"], ["71015.80000000", "0.07295000"], ["71015.09000000", "0.07295000"], ["71012.50000000", "0.07295000"], ["71011.60000000", "0.17189000"], ["71010.92000000", "0.07295000"], ["71009.43000000", "0.07295000"], ["71007.00000000", "0.07308000"], ["71004.67000000", "0.07295000"], ["71004.24000000", "0.02199000"], ["70840.82000000", "0.10000000"], ["70819.56000000", "0.18567000"], ["64077.12000000", "0.00144000"]], "a": [["71196.81000000", "1.57644000"], ["71203.92000000", "0.10000000"], ["71208.20000000", "0.14051000"], ["71208.86000000", "0.00000000"], ["71215.98000000", "0.00141000"], ["71220.38000000", "0.00000000"], ["71222.39000000", "0.04215000"], ["71222.71000000", "0.00000000"], ["71225.28000000", "0.30000000"], ["71246.64000000", "0.50000000"], ["71268.00000000", "0.70120000"]]}
{"e": "depthUpdate", "E": 1773437558214, "s": "BTCUSDT", "U": 90101519853, "u": 90101519875, "b": [["71178.70000000", "0.00444000"], ["71170.99000000", "1.76079000"], ["71022.34000000", "0.07295000"], ["71021.35000000", "0.07295000"], ["71018.79000000", "0.07295000"], ["71016.95000000", "0.07295000"], ["71015.91000000", "0.07295000"], ["71015.30000000", "0.07295000"], ["71014.13000000", "0.07295000"], ["71012.53000000", "0.07295000"], ["71011.02000000", "0.07295000"], ["71010.30000000", "0.07295000"], ["71008.75000000", "0.07295000"], ["71006.41000000", "0.07295000"], ["64077.12000000", "0.00180000"], ["56957.44000000", "0.00000000"]], "a": [["71211.15000000", "0.02000000"], ["71222.39000000", "0.04215000"], ["71246.34000000", "0.02199000"]]}
{"e": "depthUpdate", "E": 1773437558314, "s": "BTCUSDT", "U": 90101519876, "u": 90101519917, "b": [["71196.80000000", "1.02075000"], ["71192.12000000", "0.01847000"], ["71192.11000000", "0.01580000"], ["71164.38000000", "0.02800000"], ["71161.44000000", "0.03400000"], ["71085.62000000", "0.00114000"], ["71062.61000000", "0.00011000"], ["70196.80000000", "0.00020000"], ["64077.12000000", "0.00198000"]], "a": [["71196.81000000", "1.57739000"], ["71201.47000000", "0.00000000"], ["71208.92000000", "0.02000000"], ["71211.06000000", "0.02000000"], ["71211.77000000", "0.02000000"], ["71211.86000000", "0.02000000"], ["71219.65000000", "0.00000000"], ["71219.76000000", "0.00000000"], ["71222.39000000", "0.00000000"], ["71225.27000000", "0.19799000"], ["71246.63000000", "0.15971000"], ["71254.70000000", "0.00000000"], ["71267.15000000", "0.00000000"], ["71268.48000000", "0.02000000"], ["71275.94000000", "0.91607000"], ["71323.42000000", "0.00000000"]]}
{"e": "aggTrade", "E": 1773437558347, "s": "BTCUSDT", "a": 3904057847, "p": "71196.81000000", "q": "0.00632000", "f": 6104984218, "l": 6104984218, "T": 1773437558346, "m": false, "M": true}
{"e": "aggTrade", "E": 1773437558347, "s": "BTCUSDT", "a": 3904057848, "p": "71196.81000000", "q": "0.00181000", "f": 6104984219, "l": 6104984219, "T": 1773437558346, "m": false, "M": true}
{"e": "aggTrade", "E": 1773437558351, "s": "BTCUSDT", "a": 3904057849, "p": "71196.80000000", "q": "0.02635000", "f": 6104984220, "l": 6104984221, "T": 1773437558351, "m": true, "M": true}
{"e": "depthUpdate", "E": 1773437558414, "s": "BTCUSDT", "U": 90101519918, "u": 90101519962, "b": [["71196.80000000", "1.01180000"], ["71192.13000000", "0.01683000"], ["71192.12000000", "0.00040000"], ["71192.11000000", "0.01596000"], ["71190.31000000", "0.00000000"], ["71190.30000000", "0.00000000"], ["71188.76000000", "0.02400000"], ["71188.74000000", "0.02800000"], ["71186.20000000", "0.00000000"], ["71175.98000000", "0.42134000"], ["71171.01000000", "0.00000000"], ["71067.52000000", "0.23991000"], ["70196.80000000", "0.00000000"], ["64077.12000000", "0.00216000"]], "a": [["71196.81000000", "1.56926000"], ["71200.90000000", "0.00016000"], ["71203.52000000", "0.00702000"], ["71208.93000000", "0.02000000"], ["71216.83000000", "0.00000000"], ["71218.94000000", "0.02000000"], ["71219.05000000", "0.00140000"], ["71222.39000000", "0.00000000"], ["71268.48000000", "0.00000000"], ["71308.44000000", "0.23936000"], ["71335.38000000", "0.00114000"]]}
{"e": "aggTrade", "E": 1773437558469, "s": "BTCUSDT", "a": 3904057850, "p": "71196.80000000", "q": "0.14053000", "f": 6104984222, "l": 6104984223, "T": 1773437558469, "m": true, "M": true}
{"e": "depthUpdate", "E": 1773437558514, "s": "BTCUSDT", "U": 90101519963, "u": 90101520017, "b": [["71196.80000000", "0.87290000"], ["71192.15000000", "0.01616000"], ["71192.14000000", "0.00008000"], ["71192.13000000", "0.00024000"], ["71192.12000000", "0.00024000"], ["71192.11000000", "0.00000000"], ["71192.01000000", "0.01587000"], ["71190.16000000", "0.02490000"], ["71188.90000000", "0.34745000"], ["69780.68000000", "0.00000000"], ["64077.12000000", "0.00234000"], ["64077.00000000", "0.07803000"], ["56957.44000000", "0.00035000"]], "a": [["71196.81000000", "1.58516000"], ["71200.00000000", "0.11824000"], ["71200.90000000", "0.00000000"], ["71201.20000000", "0.04056000"], ["71222.39000000", "0.04215000"], ["71248.55000000", "0.00000000"]]}
{"e": "depthUpdate", "E": 1773437558614, "s": "BTCUSDT", "U": 90101520018, "u": 90101520139, "b": [["71196.80000000", "0.02007000"], ["71196.79000000", "0.00048000"], ["71192.88000000", "0.00000000"], ["71192.19000000", "0.00118000"], ["71192.16000000", "0.00024000"], ["71192.15000000", "0.01600000"], ["71192.13000000", "0.00000000"], ["71192.12000000", "0.00000000"], ["71192.02000000", "0.00016000"], ["71191.10000000", "0.00000000"], ["71190.17000000", "0.00016000"], ["71189.96000000", "0.00024000"], ["71189.95000000", "0.00016000"], ["71189.32000000", "0.00356000"], ["71189.31000000", "0.00016000"], ["71187.48000000", "0.01124000"], ["71186.84000000", "0.09711000"], ["71180.11000000", "0.00008000"], ["71178.70000000", "0.00012000"], ["71177.43000000", "0.00008000"], ["71177.24000000", "0.00000000"], ["71175.99000000", "0.00000000"], ["71175.98000000", "0.00000000"], ["71171.03000000", "0.02000000"], ["71171.01000000", "0.42136000"], ["71164.40000000", "0.00200000"], ["71162.62000000", "0.00200000"], ["71160.34000000", "0.00000000"], ["71149.96000000", "0.00000000"], ["71128.41000000", "0.29829000"], ["71112.16000000", "0.00000000"], ["71104.63000000", "0.00000000"], ["71082.56000000", "0.00000000"], ["71067.52000000", "0.00000000"], ["64077.12000000", "0.00288000"], ["56957.44000000", "0.00000000"]], "a": [["71196.81000000", "1.59247000"], ["71198.20000000", "0.00000000"], ["71198.23000000", "0.00000000"], ["71198.54000000", "0.00000000"], ["71199.40000000", "0.00000000"], ["71199.98000000", "0.00016000"], ["71199.99000000", "0.00000000"], ["71202.73000000", "0.18242000"], ["71206.75000000", "0.05183000"], ["71208.95000000", "0.14043000"], ["71218.50000000", "0.00000000"], ["71221.90000000", "0.00200000"], ["71222.39000000", "0.00000000"], ["71236.89000000", "0.00433000"], ["71237.57000000", "0.00427000"], ["71246.15000000", "0.00000000"], ["71246.53000000", "0.00000000"], ["71267.20000000", "2.63530000"], ["71325.25000000", "0.00399000"], ["71330.27000000", "0.00000000"]]}
{"e": "depthUpdate", "E": 1773437558714, "s": "BTCUSDT", "U": 90101520140, "u": 90101520334, "b": [["71196.80000000", "0.23309000"], ["71196.79000000", "0.00040000"], ["71192.19000000", "0.00000000"], ["71192.17000000", "0.00029000"], ["71192.16000000", "0.00129000"], ["71192.15000000", "0.00016000"], ["71192.14000000", "0.00000000"], ["71192.02000000", "0.00024000"], ["71192.01000000", "0.01603000"], ["71190.17000000", "0.00024000"], ["71189.96000000", "0.00000000"], ["71189.95000000", "0.00000000"], ["71189.32000000", "0.00140000"], ["71189.31000000", "0.00000000"], ["71188.91000000", "0.00016000"], ["71188.90000000", "0.34761000"], ["71188.87000000", "0.00008000"], ["71187.48000000", "0.00000000"], ["71186.84000000", "0.00000000"], ["71185.99000000", "0.03524000"], ["71185.35000000", "0.09711000"], ["71177.79000000", "0.04000000"], ["71177.33000000", "0.00000000"], ["71177.28000000", "0.02007000"], ["71176.69000000", "0.08996000"], ["71175.45000000", "0.02459000"], ["71174.71000000", "0.00000000"], ["71159.06000000", "0.00200000"], ["71158.94000000", "0.03486000"], ["71153.47000000", "0.00000000"], ["71153.08000000", "0.02800000"], ["71150.80000000", "0.00000000"], ["71149.36000000", "0.00000000"], ["71148.24000000", "0.12088000"], ["71143.89000000", "0.00433000"], ["71143.03000000", "0.00632000"], ["71138.95000000", "0.50597000"], ["71115.10000000", "0.00000000"], ["71103.24000000", "0.06478000"], ["71081.17000000", "0.07561000"], ["71080.72000000", "0.00000000"], ["71039.79000000", "0.00000000"], ["71024.51000000", "0.00862000"], ["64077.12000000", "0.00306000"]], "a": [["71196.81000000", "1.59920000"], ["71199.41000000", "0.02016000"], ["71199.98000000", "0.00000000"], ["71201.20000000", "0.04056000"], ["71202.73000000", "0.18258000"], ["71202.77000000", "0.00000000"], ["71204.27000000", "0.42144000"], ["71209.67000000", "0.05267000"], ["71209.87000000", "0.00000000"], ["71210.26000000", "0.00069000"], ["71217.38000000", "0.50541000"], ["71218.16000000", "0.02460000"], ["71218.80000000", "0.05610000"], ["71219.86000000", "0.50540000"], ["71221.99000000", "0.02007000"], ["71223.74000000", "0.36725000"], ["71229.52000000", "0.00434000"], ["71230.04000000", "0.00000000"], ["71238.01000000", "0.00000000"], ["71242.79000000", "0.00000000"], ["71246.14000000", "0.04277000"], ["71246.64000000", "1.41218000"], ["71265.31000000", "0.00000000"], ["71294.29000000", "0.16139000"], ["71308.44000000", "0.00000000"], ["71319.26000000", "0.00399000"], ["71325.25000000", "0.00000000"]]}
{"e": "aggTrade", "E": 1773437558716, "s": "BTCUSDT", "a": 3904057851, "p": "71196.80000000", "q": "0.01975000", "f": 6104984224, "l": 6104984238, "T": 1773437558715, "m": true, "M": true}
{"e": "aggTrade", "E": 1773437558716, "s": "BTCUSDT", "a": 3904057852, "p": "71196.79000000", "q": "0.00040000", "f": 6104984239, "l": 6104984243, "T": 1773437558715, "m": true, "M": true}
{"e": "aggTrade", "E": 1773437558716, "s": "BTCUSDT", "a": 3904057853, "p": "71195.01000000", "q": "0.00015000", "f": 6104984244, "l": 6104984244, "T": 1773437558715, "m": true, "M": true}
{"e": "aggTrade", "E": 1773437558716, "s": "BTCUSDT", "a": 3904057854, "p": "71195.00000000", "q": "0.00300000", "f": 6104984245, "l": 6104984245, "T": 1773437558715, "m": true, "M": true}
{"e": "aggTrade", "E": 1773437558716, "s": "BTCUSDT", "a": 3904057855, "p": "71194.62000000", "q": "0.00141000", "f": 6104984246, "l": 6104984246, "T": 1773437558715, "m": true, "M": true}
{"e": "aggTrade", "E": 1773437558716, "s": "BTCUSDT", "a": 3904057856, "p": "71194.13000000", "q": "0.00039000", "f": 6104984247, "l": 6104984248, "T": 1773437558715, "m": true, "M": true}
{"e": "aggTrade", "E": 1773437558716, "s": "BTCUSDT", "a": 3904057857, "p": "71193.74000000", "q": "0.00008000", "f": 6104984249, "l": 6104984249, "T": 1773437558715, "m": true, "M": true}
{"e": "aggTrade", "E": 1773437558716, "s": "BTCUSDT", "a": 3904057858, "p": "71193.66000000", "q": "0.00008000", "f": 6104984250, "l": 6104984250, "T": 1773437558715, "m": true, "M": true}
{"e": "depthUpdate", "E": 1773437558814, "s": "BTCUSDT", "U": 90101520335, "u": 90101520618, "b": [["71196.80000000", "0.00000000"], ["71196.79000000", "0.00000000"], ["71195.01000000", "0.00000000"], ["71195.00000000", "0.00000000"], ["71194.62000000", "0.00000000"], ["71194.13000000", "0.00000000"], ["71193.74000000", "0.00000000"], ["71193.66000000", "0.00000000"], ["71193.56000000", "1.08501000"], ["71193.55000000", "0.00064000"], ["71192.17000000", "0.00121000"], ["71192.16000000", "0.00000000"], ["71192.15000000", "0.00000000"], ["71190.16000000", "0.02506000"], ["71190.02000000", "0.00000000"], ["71189.32000000", "0.00000000"], ["71188.91000000", "0.00024000"], ["71188.90000000", "0.08090000"], ["71188.89000000", "0.00016000"], ["71188.87000000", "0.00016000"], ["71188.77000000", "0.00008000"], ["71188.76000000", "0.02416000"], ["71188.74000000", "0.02816000"], ["71188.47000000", "0.02816000"], ["71187.54000000", "0.00000000"], ["71187.11000000", "0.00000000"], ["71185.37000000", "0.07615000"], ["71183.61000000", "0.00140000"], ["71181.47000000", "0.00008000"], ["71178.76000000", "0.00141000"], ["71176.79000000", "0.00000000"], ["71168.32000000", "0.00000000"], ["71165.08000000", "0.00702000"], ["71160.84000000", "0.00200000"], ["71155.65000000", "0.00000000"], ["71152.73000000", "0.00011000"], ["71148.75000000", "0.00000000"], ["71145.30000000", "0.00011000"], ["71139.22000000", "0.00435000"], ["71116.57000000", "0.00000000"], ["71113.34000000", "0.00350000"], ["71084.29000000", "0.04847000"], ["71081.74000000", "0.04573000"], ["71072.02000000", "0.00000000"], ["71066.03000000", "0.00000000"], ["71001.39000000", "0.07295000"], ["64077.12000000", "0.00000000"], ["64074.21000000", "0.00018000"], ["49837.31000000", "0.00000000"], ["49836.06000000", "0.00000000"]], "a": [["71193.57000000", "1.40292000"], ["71193.67000000", "0.00032000"], ["71194.14000000", "0.00000000"], ["71194.62000000", "0.00000000"], ["71194.63000000", "0.00016000"], ["71194.66000000", "0.00200000"], ["71194.99000000", "0.04787000"], ["71195.00000000", "0.00000000"], ["71195.01000000", "0.00016000"], ["71195.02000000", "0.00000000"], ["71196.44000000", "0.00200000"], ["71196.56000000", "0.00141000"], ["71196.79000000", "0.22207000"], ["71196.80000000", "0.00016000"], ["71196.81000000", "0.09624000"], ["71196.82000000", "0.00000000"], ["71197.04000000", "0.00000000"], ["71197.15000000", "0.00000000"], ["71197.18000000", "0.00000000"], ["71198.21000000", "0.00016000"], ["71198.23000000", "0.00000000"], ["71198.24000000", "0.00016000"], ["71199.80000000", "0.00000000"], ["71200.00000000", "0.11808000"], ["71201.05000000", "0.02583000"], ["71201.20000000", "0.04040000"], ["71201.42000000", "0.00008000"], ["71202.21000000", "0.07439000"], ["71202.73000000", "0.00000000"], ["71204.27000000", "0.00008000"], ["71205.73000000", "0.00000000"], ["71207.74000000", "0.42137000"], ["71209.97000000", "0.00000000"], ["71210.26000000", "0.00137000"], ["71221.99000000", "0.00000000"], ["71222.15000000", "0.00702000"], ["71223.14000000", "0.00000000"], ["71224.92000000", "0.00000000"], ["71225.29000000", "0.00000000"], ["71230.64000000", "0.00011000"], ["71237.00000000", "0.00000000"], ["71237.57000000", "0.00438000"], ["71244.56000000", "0.00350000"], ["71246.15000000", "0.00868000"], ["71254.55000000", "0.01076000"], ["71294.29000000", "0.22104000"], ["71308.44000000", "0.23399000"]]}
{"e": "depthUpdate", "E": 1773437558914, "s": "BTCUSDT", "U": 90101520619, "u": 90101520692, "b": [["71193.56000000", "1.08500000"], ["71193.55000000", "0.00056000"], ["71192.32000000", "0.00008000"], ["71192.17000000", "0.00000000"], ["71192.02000000", "0.00148000"], ["71189.81000000", "0.00000000"], ["71188.90000000", "0.08090000"], ["71188.89000000", "0.00000000"], ["71188.12000000", "0.05416000"], ["71184.74000000", "0.00022000"], ["71182.70000000", "0.00119000"], ["71177.28000000", "0.00000000"], ["71175.59000000", "0.00011000"], ["71168.48000000", "0.19439000"], ["71161.37000000", "0.00000000"], ["71154.26000000", "0.00021000"], ["71147.14000000", "0.00000000"], ["71140.03000000", "0.00000000"], ["71132.92000000", "0.00000000"], ["71125.81000000", "0.00000000"], ["71118.70000000", "0.00000000"], ["71111.59000000", "0.00000000"], ["71104.48000000", "0.00000000"], ["71097.37000000", "0.00000000"], ["71090.25000000", "0.00000000"], ["71083.14000000", "0.00000000"], ["71076.03000000", "0.00000000"], ["71063.88000000", "0.00008000"], ["64074.21000000", "0.00054000"]], "a": [["71193.57000000", "1.40308000"], ["71193.67000000", "0.00016000"], ["71194.63000000", "0.00000000"], ["71194.97000000", "0.00016000"], ["71194.98000000", "0.00000000"], ["71194.99000000", "0.00016000"], ["71195.01000000", "0.00000000"], ["71196.77000000", "0.08521000"], ["71196.78000000", "0.00000000"], ["71196.79000000", "0.00016000"], ["71196.81000000", "0.09343000"], ["71198.21000000", "0.00000000"], ["71198.24000000", "0.00000000"], ["71200.00000000", "0.11824000"], ["71201.05000000", "0.02599000"], ["71204.03000000", "0.00000000"], ["71210.26000000", "0.00069000"], ["71211.14000000", "0.00000000"], ["71215.98000000", "0.00000000"], ["71218.26000000", "0.00000000"], ["71225.37000000", "0.00008000"], ["71232.48000000", "0.00000000"], ["71239.59000000", "0.00000000"], ["71246.70000000", "0.00000000"], ["71253.81000000", "0.00000000"], ["71260.92000000", "0.00000000"], ["71268.03000000", "0.00000000"], ["71275.15000000", "0.00000000"], ["71282.26000000", "0.00000000"], ["71289.37000000", "0.00000000"], ["71294.29000000", "0.15965000"], ["71319.26000000", "0.00000000"], ["71324.94000000", "0.00399000"]]}
{"e": "depthUpdate", "E": 1773437559014, "s": "BTCUSDT", "U": 90101520693, "u": 90101520719, "b": [["71165.08000000", "0.00000000"], ["64074.21000000", "0.00072000"], ["56954.85000000", "0.00035000"]], "a": [["71193.57000000", "1.46635000"], ["71194.97000000", "0.00000000"], ["71194.99000000", "0.00000000"], ["71196.75000000", "0.00016000"], ["71196.76000000", "0.05022000"], ["71196.77000000", "0.00016000"], ["71196.79000000", "0.00000000"], ["71196.81000000", "0.03032000"]]}
