{"e": "depthUpdate", "E": 1773437544614, "s": "BTCUSDT", "U": 90101510870, "u": 90101510938, "b": [["71176.70000000", "0.00008000"], ["71175.42000000", "0.02552000"], ["71174.57000000", "0.00000000"], ["71170.95000000", "2.53379000"], ["71165.08000000", "0.00008000"], ["71156.02000000", "0.00000000"], ["71114.33000000", "0.02400000"], ["71106.25000000", "0.19763000"], ["71043.96000000", "0.00000000"], ["65000.00000000", "180.96342000"], ["64059.79000000", "0.00090000"], ["64059.00000000", "0.00000000"], ["56942.04000000", "0.00000000"]], "a": [["71177.55000000", "0.00372000"], ["71177.56000000", "0.00048000"], ["71179.18000000", "0.10016000"], ["71180.00000000", "0.00000000"], ["71180.01000000", "0.00000000"], ["71180.37000000", "0.00024000"], ["71180.38000000", "0.01584000"], ["71180.42000000", "0.08087000"], ["71182.63000000", "0.00000000"], ["71182.69000000", "0.00000000"], ["71182.70000000", "0.00859000"], ["71183.41000000", "0.00141000"], ["71183.44000000", "0.00016000"], ["71183.45000000", "0.02543000"], ["71184.91000000", "0.00016000"], ["71184.92000000", "0.08169000"], ["71189.58000000", "0.00000000"], ["71196.55000000", "0.14046000"], ["71197.27000000", "0.14046000"], ["71200.31000000", "0.41212000"], ["71201.29000000", "0.50582000"], ["71275.83000000", "0.00000000"], ["71323.91000000", "0.00000000"], ["71367.69000000", "0.00399000"], ["71372.87000000", "0.00000000"]]}
{"e": "aggTrade", "E": 1773437544624, "s": "BTCUSDT", "a": 3904057731, "p": "71177.55000000", "q": "0.00029000", "f": 6104983884, "l": 6104983884, "T": 1773437544623, "m": false, "M": true}
{"e": "depthUpdate", "E": 1773437544714, "s": "BTCUSDT", "U": 90101510939, "u": 90101510968, "b": [["71177.54000000", "4.44725000"], ["71175.96000000", "2.53518000"], ["71175.86000000", "0.00141000"], ["71168.85000000", "0.06254000"], ["71166.28000000", "0.00000000"], ["71114.46000000", "0.02200000"], ["64059.79000000", "0.00108000"]], "a": [["71177.55000000", "0.40809000"], ["71182.70000000", "0.00859000"], ["71183.45000000", "0.02559000"], ["71184.92000000", "0.00016000"], ["71185.08000000", "0.08190000"], ["71189.59000000", "0.01818000"], ["71189.69000000", "0.41817000"], ["71204.33000000", "0.00141000"], ["71217.08000000", "0.91256000"], ["71239.45000000", "0.00000000"]]}
{"e": "aggTrade", "E": 1773437544804, "s": "BTCUSDT", "a": 3904057732, "p": "71177.55000000", "q": "0.00011000", "f": 6104983885, "l": 6104983885, "T": 1773437544804, "m": false, "M": true}
{"e": "depthUpdate", "E": 1773437544815, "s": "BTCUSDT", "U": 90101510969, "u": 90101510990, "b": [["71177.54000000", "4.44736000"], ["71175.95000000", "0.00000000"], ["71159.12000000", "0.00015000"], ["64059.79000000", "0.00126000"]], "a": [["71177.55000000", "0.40798000"], ["71183.45000000", "0.02559000"], ["71184.91000000", "0.00000000"], ["71184.92000000", "0.00000000"], ["71185.07000000", "0.00008000"], ["71185.08000000", "0.08206000"], ["71197.30000000", "0.03509000"], ["71207.81000000", "0.11633000"], ["71223.73000000", "0.36460000"], ["71226.49000000", "0.06284000"], ["71240.72000000", "0.07588000"], ["71246.14000000", "0.05698000"]]}
{"e": "depthUpdate", "E": 1773437544914, "s": "BTCUSDT", "U": 90101510991, "u": 90101510997, "b": [["71161.04000000", "0.00356000"], ["71160.97000000", "0.00702000"], ["71160.96000000", "0.00996000"], ["64059.79000000", "0.00162000"]], "a": [["71212.46000000", "0.00445000"], ["71216.02000000", "0.00000000"]]}
{"e": "depthUpdate", "E": 1773437545014, "s": "BTCUSDT", "U": 90101510998, "u": 90101511023, "b": [["71175.95000000", "0.01591000"], ["71170.42000000", "0.00000000"], ["71166.18000000", "0.00236000"], ["71164.22000000", "0.00000000"], ["71162.59000000", "0.36335000"], ["71161.90000000", "0.00702000"], ["71157.60000000", "0.00000000"], ["71145.90000000", "0.00000000"], ["71137.77000000", "0.05548000"], ["64059.79000000", "0.00198000"], ["56942.04000000", "0.00035000"], ["56942.00000000", "0.00018000"]], "a": [["71180.38000000", "0.00016000"], ["71182.22000000", "0.00000000"], ["71183.41000000", "0.00000000"], ["71183.43000000", "0.00000000"], ["71183.45000000", "0.00016000"], ["71185.40000000", "0.02588000"], ["71192.50000000", "0.00300000"], ["71201.29000000", "0.00000000"], ["71203.88000000", "0.00000000"], ["71207.81000000", "0.00000000"], ["71208.42000000", "0.11719000"], ["71294.55000000", "0.02200000"]]}
{"e": "depthUpdate", "E": 1773437545114, "s": "BTCUSDT", "U": 90101511024, "u": 90101511118, "b": [["71175.96000000", "2.53518000"], ["71175.95000000", "0.01599000"], ["71170.96000000", "0.89959000"], ["71167.81000000", "0.00000000"], ["71163.30000000", "0.00702000"], ["71157.81000000", "0.00000000"], ["71128.46000000", "0.50604000"], ["71020.71000000", "0.00000000"], ["71020.06000000", "0.00000000"], ["71018.37000000", "0.00000000"], ["71015.63000000", "0.09596000"], ["71014.56000000", "0.19192000"], ["71014.44000000", "0.00000000"], ["71012.10000000", "0.00862000"], ["71012.09000000", "0.00000000"], ["71011.96000000", "0.00000000"], ["71010.67000000", "0.00000000"], ["71010.62000000", "0.00000000"], ["71009.40000000", "0.00000000"], ["71008.77000000", "0.00000000"], ["71008.75000000", "0.00000000"], ["71007.69000000", "0.00000000"], ["71007.02000000", "0.00000000"], ["71004.90000000", "0.00000000"], ["71004.44000000", "0.00000000"], ["71002.34000000", "0.00000000"], ["71001.66000000", "0.00000000"], ["71000.32000000", "0.00000000"], ["70999.49000000", "0.00000000"], ["70998.81000000", "0.00000000"], ["70998.75000000", "0.00000000"], ["70997.64000000", "0.00000000"], ["70997.58000000", "0.00000000"], ["70996.75000000", "0.00000000"], ["70996.52000000", "0.00000000"], ["70994.94000000", "0.00000000"], ["70993.81000000", "0.00000000"], ["70990.39000000", "0.00016000"], ["70990.24000000", "0.00000000"], ["70988.21000000", "0.00000000"], ["70987.25000000", "0.00000000"], ["64059.79000000", "0.00216000"], ["64059.00000000", "0.00010000"], ["37454.70000000", "0.00040000"]], "a": [["71177.55000000", "0.40774000"], ["71177.56000000", "0.00032000"], ["71179.18000000", "0.10016000"], ["71180.37000000", "0.00000000"], ["71180.38000000", "0.00000000"], ["71182.69000000", "0.00008000"], ["71182.70000000", "0.00859000"], ["71183.43000000", "0.00141000"], ["71183.44000000", "0.00000000"], ["71183.45000000", "0.00000000"], ["71183.62000000", "0.01613000"], ["71185.06000000", "0.00016000"], ["71185.07000000", "0.03245000"], ["71185.08000000", "0.08206000"], ["71185.39000000", "0.00016000"], ["71185.40000000", "0.02604000"], ["71189.59000000", "0.00024000"], ["71197.30000000", "0.00000000"], ["71198.49000000", "0.02512000"], ["71200.31000000", "0.29553000"], ["71201.28000000", "0.50582000"], ["71204.02000000", "0.37889000"], ["71226.49000000", "0.00000000"], ["71237.44000000", "0.00000000"], ["71240.72000000", "0.00000000"]]}
{"e": "depthUpdate", "E": 1773437545214, "s": "BTCUSDT", "U": 90101511119, "u": 90101511148, "b": [["71167.54000000", "0.02800000"], ["71113.34000000", "0.02800000"], ["64059.79000000", "0.00234000"], ["64059.00000000", "0.00020000"], ["56942.04000000", "0.00000000"]], "a": [["71177.55000000", "0.40782000"], ["71179.53000000", "0.00008000"], ["71182.70000000", "0.00859000"], ["71183.61000000", "0.00016000"], ["71183.62000000", "0.01629000"], ["71185.07000000", "0.03261000"], ["71185.39000000", "0.00000000"], ["71189.37000000", "0.00702000"], ["71189.59000000", "0.00008000"], ["71200.31000000", "0.41212000"]]}
{"e": "depthUpdate", "E": 1773437545314, "s": "BTCUSDT", "U": 90101511149, "u": 90101511159, "b": [["71167.19000000", "0.02800000"], ["71167.18000000", "0.02600000"], ["71165.05000000", "0.02400000"], ["71164.25000000", "0.03400000"], ["71159.59000000", "0.00000000"], ["71156.64000000", "1.27198000"], ["71071.29000000", "0.10000000"], ["64059.79000000", "0.00270000"], ["64059.00000000", "0.00000000"]], "a": [["71267.55000000", "0.10000000"]]}
{"e": "depthUpdate", "E": 1773437545414, "s": "BTCUSDT", "U": 90101511160, "u": 90101511170, "b": [["71159.94000000", "0.00000000"], ["71159.58000000", "0.00000000"], ["71157.45000000", "0.00000000"], ["71112.74000000", "0.00000000"], ["71055.82000000", "0.00008000"], ["64059.79000000", "0.00297000"], ["64059.00000000", "0.00000000"]], "a": [["71326.27000000", "0.38713000"], ["78295.30000000", "0.00008000"]]}
{"e": "depthUpdate", "E": 1773437545514, "s": "BTCUSDT", "U": 90101511171, "u": 90101511185, "b": [["71177.54000000", "4.44725000"], ["71175.96000000", "2.53387000"], ["71154.60000000", "1.09643000"], ["69758.90000000", "0.00008000"], ["64059.79000000", "0.00306000"], ["64059.00000000", "0.00000000"], ["56942.04000000", "0.00035000"]], "a": [["71197.31000000", "0.00000000"], ["71212.83000000", "0.00021000"], ["71219.43000000", "0.00021000"], ["71223.73000000", "0.00000000"], ["71227.43000000", "0.00021000"], ["78295.30000000", "0.00000000"]]}
{"e": "depthUpdate", "E": 1773437545615, "s": "BTCUSDT", "U": 90101511186, "u": 90101511194, "b": [["71149.16000000", "0.50590000"], ["71128.46000000", "0.00000000"], ["64059.79000000", "0.00360000"], ["56942.04000000", "0.00000000"]], "a": [["71197.32000000", "0.03610000"], ["71226.50000000", "0.06471000"], ["71240.74000000", "0.07684000"]]}
{"e": "aggTrade", "E": 1773437545712, "s": "BTCUSDT", "a": 3904057733, "p": "71177.55000000", "q": "0.00087000", "f": 6104983886, "l": 6104983886, "T": 1773437545712, "m": false, "M": true}
{"e": "depthUpdate", "E": 1773437545714, "s": "BTCUSDT", "U": 90101511195, "u": 90101511203, "b": [["64059.79000000", "0.00378000"], ["64059.00000000", "0.00010000"], ["64057.00000000", "0.00000000"], ["56942.00000000", "0.00018000"]], "a": [["71177.55000000", "0.40695000"], ["71210.73000000", "0.00000000"], ["71210.97000000", "0.00000000"], ["71267.55000000", "0.00000000"]]}
{"e": "depthUpdate", "E": 1773437545814, "s": "BTCUSDT", "U": 90101511204, "u": 90101511208, "b": [["71012.10000000", "0.00000000"], ["71009.40000000", "0.00862000"], ["64059.79000000", "0.00396000"]], "a": [["71212.46000000", "0.00200000"], ["71213.61000000", "0.37133000"], ["71229.29000000", "0.16520000"]]}
{"e": "aggTrade", "E": 1773437545887, "s": "BTCUSDT", "a": 3904057734, "p": "71177.55000000", "q": "0.00245000", "f": 6104983887, "l": 6104983896, "T": 1773437545887, "m": false, "M": true}
{"e": "aggTrade", "E": 1773437545887, "s": "BTCUSDT", "a": 3904057735, "p": "71177.56000000", "q": "0.00032000", "f": 6104983897, "l": 6104983900, "T": 1773437545887, "m": false, "M": true}
{"e": "aggTrade", "E": 1773437545887, "s": "BTCUSDT", "a": 3904057736, "p": "71178.49000000", "q": "0.00008000", "f": 6104983901, "l": 6104983901, "T": 1773437545887, "m": false, "M": true}
{"e": "aggTrade", "E": 1773437545887, "s": "BTCUSDT", "a": 3904057737, "p": "71179.17000000", "q": "0.00032000", "f": 6104983902, "l": 6104983905, "T": 1773437545887, "m": false, "M": true}
{"e": "aggTrade", "E": 1773437545887, "s": "BTCUSDT", "a": 3904057738, "p": "71179.18000000", "q": "0.00315000", "f": 6104983906, "l": 6104983906, "T": 1773437545887, "m": false, "M": true}
{"e": "depthUpdate", "E": 1773437545914, "s": "BTCUSDT", "U": 90101511209, "u": 90101511426, "b": [["71179.17000000", "3.34515000"], ["71179.16000000", "0.00008000"], ["71178.48000000", "0.00000000"], ["71177.55000000", "2.44199000"], ["71177.54000000", "0.38719000"], ["71177.53000000", "0.00000000"], ["71176.27000000", "0.00008000"], ["71175.97000000", "0.00008000"], ["71173.37000000", "0.00008000"], ["71172.63000000", "0.00008000"], ["71172.05000000", "0.00702000"], ["71171.53000000", "0.03511000"], ["71170.42000000", "0.00000000"], ["71168.85000000", "0.00000000"], ["71166.78000000", "0.42842000"], ["71166.54000000", "0.50577000"], ["71166.00000000", "0.00000000"], ["71163.30000000", "0.00000000"], ["71162.60000000", "0.00000000"], ["71152.63000000", "0.00000000"], ["71149.16000000", "0.00000000"], ["71107.45000000", "0.00868000"], ["71106.25000000", "0.00000000"], ["71084.73000000", "0.00000000"], ["71084.64000000", "0.00000000"], ["71077.68000000", "0.00000000"], ["71053.86000000", "0.00000000"], ["68266.55000000", "0.07019000"], ["68252.32000000", "0.00000000"], ["64059.79000000", "0.00000000"], ["49824.66000000", "0.00000000"]], "a": [["71177.55000000", "0.00000000"], ["71177.56000000", "0.00000000"], ["71178.49000000", "0.00000000"], ["71179.17000000", "0.00000000"], ["71179.18000000", "0.09781000"], ["71179.19000000", "0.00048000"], ["71180.42000000", "0.00016000"], ["71180.55000000", "0.00000000"], ["71182.18000000", "0.00141000"], ["71183.43000000", "0.00000000"], ["71183.61000000", "0.00024000"], ["71184.89000000", "0.00000000"], ["71185.07000000", "0.00032000"], ["71185.08000000", "0.00016000"], ["71185.39000000", "0.00008000"], ["71189.31000000", "0.00016000"], ["71189.37000000", "0.00718000"], ["71190.81000000", "0.00000000"], ["71192.48000000", "0.00702000"], ["71193.47000000", "0.02000000"], ["71193.99000000", "0.00702000"], ["71195.87000000", "0.12000000"], ["71196.04000000", "1.09643000"], ["71196.55000000", "0.00000000"], ["71197.32000000", "0.00014000"], ["71197.67000000", "0.14046000"], ["71200.50000000", "0.00000000"], ["71201.28000000", "0.00000000"], ["71204.02000000", "0.00000000"], ["71204.09000000", "0.00140000"], ["71205.76000000", "0.37889000"], ["71206.03000000", "0.00000000"], ["71208.51000000", "0.00000000"], ["71210.64000000", "0.00000000"], ["71212.65000000", "0.00702000"], ["71218.95000000", "0.01129000"], ["71226.50000000", "0.00000000"], ["71240.74000000", "0.00000000"], ["71251.74000000", "0.00008000"]]}
{"e": "depthUpdate", "E": 1773437546014, "s": "BTCUSDT", "U": 90101511427, "u": 90101511561, "b": [["71179.17000000", "3.37919000"], ["71178.64000000", "0.00200000"], ["71177.56000000", "0.89979000"], ["71177.55000000", "0.18467000"], ["71177.54000000", "0.05719000"], ["71176.27000000", "0.00000000"], ["71175.97000000", "0.00000000"], ["71175.86000000", "0.00000000"], ["71175.42000000", "0.02560000"], ["71174.55000000", "0.00141000"], ["71173.58000000", "0.04461000"], ["71170.98000000", "1.39174000"], ["71170.97000000", "1.68082000"], ["71170.96000000", "0.00321000"], ["71169.91000000", "0.00000000"], ["71169.74000000", "0.08161000"], ["71169.20000000", "0.00300000"], ["71166.77000000", "0.00364000"], ["71166.18000000", "0.00200000"], ["71163.48000000", "0.00000000"], ["71150.16000000", "0.00000000"], ["71085.83000000", "0.49597000"], ["71067.82000000", "0.00000000"], ["64061.26000000", "0.00036000"], ["56943.34000000", "0.00035000"]], "a": [["71179.18000000", "0.50231000"], ["71179.19000000", "0.00032000"], ["71180.41000000", "0.00000000"], ["71180.42000000", "0.00000000"], ["71183.62000000", "0.01629000"], ["71184.17000000", "0.00300000"], ["71184.98000000", "0.00000000"], ["71185.06000000", "0.00000000"], ["71185.07000000", "0.00000000"], ["71185.08000000", "0.00000000"], ["71185.39000000", "0.00024000"], ["71185.40000000", "0.02604000"], ["71186.62000000", "0.02837000"], ["71186.63000000", "0.08853000"], ["71189.31000000", "0.00000000"], ["71189.67000000", "0.54908000"], ["71189.68000000", "1.68098000"], ["71189.69000000", "0.00016000"], ["71189.70000000", "0.00016000"], ["71190.37000000", "0.01016000"], ["71193.77000000", "0.87630000"], ["71196.03000000", "1.09643000"], ["71196.04000000", "0.00000000"], ["71196.13000000", "0.00000000"], ["71197.27000000", "0.00000000"], ["71197.67000000", "0.00000000"], ["71199.83000000", "0.00000000"], ["71200.31000000", "0.29553000"], ["71200.42000000", "0.00000000"], ["71200.55000000", "0.00000000"], ["71202.68000000", "0.10701000"], ["71202.85000000", "0.00000000"], ["71205.76000000", "0.00000000"], ["71208.66000000", "0.00000000"], ["71332.69000000", "0.04597000"], ["71367.69000000", "0.00000000"], ["71368.94000000", "0.00399000"], ["71375.03000000", "0.00000000"]]}
{"e": "kline", "E": 1773437546022, "s": "BTCUSDT", "k": {"t": 1773437520000, "T": 1773437579999, "s": "BTCUSDT", "i": "1m", "f": 6104983042, "L": 6104983906, "o": "71164.00000000", "c": "71179.18000000", "h": "71179.18000000", "l": "71155.65000000", "v": "12.31908000", "n": 865, "x": false, "q": "876613.29250900", "V": "11.19607000", "Q": "796694.16832930", "B": "0"}}
{"e": "aggTrade", "E": 1773437546082, "s": "BTCUSDT", "a": 3904057739, "p": "71179.17000000", "q": "0.00015000", "f": 6104983907, "l": 6104983907, "T": 1773437546081, "m": true, "M": true}
{"e": "depthUpdate", "E": 1773437546114, "s": "BTCUSDT", "U": 90101511562, "u": 90101511628, "b": [["71179.17000000", "3.37904000"], ["71172.05000000", "0.00000000"], ["71166.54000000", "0.50619000"], ["71067.16000000", "0.04426000"], ["71018.42000000", "0.07296000"], ["71017.57000000", "0.07296000"], ["71015.25000000", "0.07296000"], ["71013.40000000", "0.07296000"], ["71011.10000000", "0.07296000"], ["71009.71000000", "0.07296000"], ["71008.82000000", "0.07296000"], ["71007.96000000", "0.07296000"], ["71004.60000000", "0.07296000"], ["71002.64000000", "0.07296000"], ["71000.51000000", "0.07296000"], ["70999.98000000", "0.07296000"], ["70999.30000000", "0.07296000"], ["70998.47000000", "0.07296000"], ["70996.47000000", "0.07296000"], ["70994.58000000", "0.07296000"], ["70993.06000000", "0.07296000"], ["70989.07000000", "0.07296000"], ["64061.26000000", "0.00054000"], ["37454.70000000", "0.00000000"]], "a": [["71179.18000000", "0.50223000"], ["71179.19000000", "0.00040000"], ["71182.37000000", "0.00008000"], ["71184.61000000", "0.00141000"], ["71185.40000000", "0.02604000"], ["71186.61000000", "0.00016000"], ["71186.62000000", "0.02853000"], ["71186.63000000", "0.08869000"], ["71189.37000000", "0.00718000"], ["71189.66000000", "0.00008000"], ["71189.67000000", "0.54916000"], ["71189.68000000", "1.68098000"], ["71189.69000000", "0.00000000"], ["71189.70000000", "0.00000000"], ["71190.37000000", "0.01000000"], ["71201.98000000", "0.14046000"], ["71202.46000000", "0.50581000"], ["71202.70000000", "0.14046000"], ["71205.41000000", "0.37889000"], ["71338.83000000", "0.00000000"], ["71361.22000000", "0.00399000"], ["71368.94000000", "0.00000000"]]}
{"e": "depthUpdate", "E": 1773437546214, "s": "BTCUSDT", "U": 90101511629, "u": 90101511660, "b": [["71177.56000000", "0.89987000"], ["71173.58000000", "0.04453000"], ["71159.29000000", "0.13296000"], ["71128.45000000", "0.00000000"], ["71012.72000000", "0.07296000"], ["71010.50000000", "0.07296000"], ["71009.62000000", "0.07296000"], ["71008.78000000", "0.07296000"], ["71005.97000000", "0.07296000"], ["71002.76000000", "0.07296000"], ["71001.60000000", "0.07296000"], ["71000.39000000", "0.07296000"], ["70999.88000000", "0.07296000"], ["70998.98000000", "0.07296000"], ["70997.03000000", "0.07296000"], ["70995.34000000", "0.07296000"], ["70994.11000000", "0.07296000"], ["70991.42000000", "0.07296000"], ["70987.64000000", "0.07296000"], ["70543.08000000", "0.00019000"], ["70528.92000000", "0.00000000"], ["64061.26000000", "0.00090000"], ["56943.34000000", "0.00000000"], ["42740.18000000", "0.00045000"], ["42711.72000000", "0.00000000"], ["42710.58000000", "0.00000000"], ["42709.45000000", "0.00015000"], ["42709.20000000", "0.00045000"], ["42708.35000000", "0.00015000"], ["42679.15000000", "0.00000000"], ["42669.21000000", "0.00015000"]], "a": [["71200.31000000", "0.52707000"]]}
{"e": "depthUpdate", "E": 1773437546314, "s": "BTCUSDT", "U": 90101511661, "u": 90101511666, "b": [["71172.05000000", "0.00702000"], ["71112.75000000", "0.02600000"], ["71092.80000000", "0.02400000"], ["64061.26000000", "0.00126000"]], "a": [["71207.66000000", "0.00702000"]]}
{"e": "depthUpdate", "E": 1773437546414, "s": "BTCUSDT", "U": 90101511667, "u": 90101511681, "b": [["71178.12000000", "0.00008000"], ["71175.95000000", "0.01611000"], ["70988.18000000", "0.00000000"], ["64061.26000000", "0.00144000"], ["64061.00000000", "0.00020000"]], "a": [["71179.53000000", "0.00000000"], ["71197.59000000", "0.03449000"], ["71214.01000000", "0.00000000"], ["71226.77000000", "0.06416000"], ["71241.01000000", "0.07843000"]]}
{"e": "aggTrade", "E": 1773437546427, "s": "BTCUSDT", "a": 3904057740, "p": "71179.18000000", "q": "0.00272000", "f": 6104983908, "l": 6104983908, "T": 1773437546427, "m": false, "M": true}
{"e": "depthUpdate", "E": 1773437546514, "s": "BTCUSDT", "U": 90101511682, "u": 90101511695, "b": [["71179.17000000", "3.38186000"], ["71013.41000000", "0.00862000"], ["71009.40000000", "0.00000000"], ["71007.77000000", "0.02200000"], ["69758.90000000", "0.00000000"], ["64061.26000000", "0.00162000"], ["64061.00000000", "0.00000000"], ["56943.34000000", "0.00035000"]], "a": [["71179.18000000", "0.49951000"], ["71209.15000000", "0.00141000"], ["71214.01000000", "0.00000000"], ["71298.89000000", "0.00000000"], ["71362.44000000", "0.02809000"]]}
{"e": "depthUpdate", "E": 1773437546614, "s": "BTCUSDT", "U": 90101511696, "u": 90101511697, "b": [["64061.26000000", "0.00180000"], ["56943.34000000", "0.00000000"]], "a": []}
{"e": "aggTrade", "E": 1773437546706, "s": "BTCUSDT", "a": 3904057741, "p": "71179.18000000", "q": "0.00007000", "f": 6104983909, "l": 6104983909, "T": 1773437546705, "m": false, "M": true}
{"e": "depthUpdate", "E": 1773437546714, "s": "BTCUSDT", "U": 90101511698, "u": 90101511705, "b": [["71076.20000000", "0.02809000"], ["71002.23000000", "0.00000000"], ["64061.26000000", "0.00216000"]], "a": [["71179.18000000", "0.49944000"], ["71184.61000000", "0.00000000"], ["71214.01000000", "0.04215000"], ["71368.23000000", "0.00000000"]]}
{"e": "depthUpdate", "E": 1773437546816, "s": "BTCUSDT", "U": 90101511706, "u": 90101511716, "b": [["64061.26000000", "0.00252000"]], "a": [["71184.51000000", "0.00141000"], ["71214.01000000", "0.00000000"], ["73593.10000000", "0.00000000"], ["73607.04000000", "0.01340000"]]}
{"e": "aggTrade", "E": 1773437546846, "s": "BTCUSDT", "a": 3904057742, "p": "71179.18000000", "q": "0.00360000", "f": 6104983910, "l": 6104983910, "T": 1773437546845, "m": false, "M": true}
{"e": "depthUpdate", "E": 1773437546914, "s": "BTCUSDT", "U": 90101511717, "u": 90101511725, "b": [["64061.26000000", "0.00270000"], ["64061.00000000", "0.00010000"], ["64059.00000000", "0.00000000"]], "a": [["71179.18000000", "0.49584000"], ["71214.03000000", "0.04215000"]]}
{"e": "depthUpdate", "E": 1773437547014, "s": "BTCUSDT", "U": 90101511726, "u": 90101511739, "b": [["71120.57000000", "0.19534000"], ["71053.10000000", "0.05338000"], ["71039.58000000", "0.00000000"], ["71003.66000000", "6.64683000"], ["64061.26000000", "0.00288000"], ["56943.34000000", "0.00035000"]], "a": [["71180.24000000", "0.00008000"], ["71214.03000000", "0.00000000"], ["71218.06000000", "0.26544000"], ["71370.96000000", "0.41526000"], ["71401.37000000", "0.00000000"], ["71402.08000000", "0.00000000"], ["71406.94000000", "0.05338000"], ["71407.60000000", "0.05338000"]]}
{"e": "depthUpdate", "E": 1773437547114, "s": "BTCUSDT", "U": 90101511740, "u": 90101511748, "b": [["71172.05000000", "0.00000000"], ["71164.93000000", "0.00702000"], ["70812.63000000", "0.00000000"], ["70791.38000000", "0.00000000"], ["64061.26000000", "0.00306000"]], "a": [["71179.18000000", "0.40538000"], ["71200.53000000", "0.00000000"], ["71221.88000000", "0.00000000"], ["71243.24000000", "0.00000000"]]}
{"e": "depthUpdate", "E": 1773437547214, "s": "BTCUSDT", "U": 90101511749, "u": 90101511772, "b": [["71179.17000000", "3.47866000"], ["71169.74000000", "0.00200000"], ["71159.29000000", "0.07296000"], ["64061.26000000", "0.00324000"], ["56943.34000000", "0.00000000"]], "a": [["71179.18000000", "0.00088000"], ["71184.51000000", "0.00000000"], ["71186.63000000", "0.00016000"], ["71189.68000000", "0.00016000"], ["71190.37000000", "0.01008000"], ["71196.03000000", "0.00000000"], ["71199.56000000", "0.00015000"], ["71201.97000000", "0.42138000"], ["71243.03000000", "0.73331000"]]}
{"e": "aggTrade", "E": 1773437547258, "s": "BTCUSDT", "a": 3904057743, "p": "71179.18000000", "q": "0.00088000", "f": 6104983911, "l": 6104983921, "T": 1773437547258, "m": false, "M": true}
{"e": "depthUpdate", "E": 1773437547314, "s": "BTCUSDT", "U": 90101511773, "u": 90101512081, "b": [["71179.18000000", "6.97758000"], ["71179.17000000", "1.28777000"], ["71179.16000000", "0.00000000"], ["71177.91000000", "0.00029000"], ["71177.56000000", "0.00008000"], ["71177.55000000", "0.00008000"], ["71173.59000000", "0.03192000"], ["71173.58000000", "0.07453000"], ["71173.01000000", "0.00000000"], ["71172.05000000", "0.00702000"], ["71170.90000000", "0.50574000"], ["71169.00000000", "0.00702000"], ["71166.97000000", "0.14050000"], ["71166.19000000", "0.00702000"], ["71165.28000000", "0.12140000"], ["71164.93000000", "0.00000000"], ["71163.17000000", "0.06000000"], ["71161.90000000", "0.00000000"], ["71160.97000000", "0.00000000"], ["71160.70000000", "0.00200000"], ["71154.80000000", "0.00200000"], ["71154.40000000", "0.00200000"], ["71151.55000000", "0.00000000"], ["71151.50000000", "0.05557000"], ["71146.00000000", "0.00120000"], ["71145.67000000", "0.70267000"], ["71145.22000000", "0.02711000"], ["71141.37000000", "0.00000000"], ["71140.10000000", "0.00000000"], ["71139.70000000", "0.00000000"], ["71137.77000000", "0.00000000"], ["71129.52000000", "0.02400000"], ["71124.25000000", "0.10399000"], ["71110.35000000", "0.00057000"], ["71107.11000000", "0.00000000"], ["71105.49000000", "0.07589000"], ["71094.18000000", "0.00000000"], ["71079.23000000", "0.00000000"], ["71077.34000000", "0.00000000"], ["71073.58000000", "0.10000000"], ["71047.17000000", "0.00000000"], ["70986.60000000", "0.00000000"], ["70985.88000000", "0.00000000"], ["70985.42000000", "0.00000000"], ["70985.37000000", "0.00000000"], ["70983.85000000", "0.00000000"], ["70983.15000000", "0.00000000"], ["70179.18000000", "0.00020000"], ["64061.26000000", "0.00000000"]], "a": [["71179.18000000", "0.00000000"], ["71179.19000000", "0.00096000"], ["71179.20000000", "0.00040000"], ["71182.18000000", "0.00000000"], ["71182.19000000", "0.00000000"], ["71182.24000000", "0.00000000"], ["71182.42000000", "0.00000000"], ["71182.43000000", "0.00000000"], ["71182.53000000", "0.00000000"], ["71182.99000000", "0.00000000"], ["71183.00000000", "0.00000000"], ["71183.03000000", "0.00141000"], ["71183.62000000", "0.00016000"], ["71185.40000000", "0.00016000"], ["71185.98000000", "0.00000000"], ["71186.49000000", "0.00016000"], ["71186.50000000", "0.08773000"], ["71186.55000000", "0.00000000"], ["71186.61000000", "0.00000000"], ["71186.62000000", "0.00016000"], ["71186.63000000", "0.00000000"], ["71187.54000000", "0.00000000"], ["71188.53000000", "0.00141000"], ["71189.32000000", "0.00000000"], ["71189.37000000", "0.00016000"], ["71189.66000000", "0.00016000"], ["71189.67000000", "0.04719000"], ["71189.68000000", "0.00000000"], ["71190.37000000", "0.00016000"], ["71190.82000000", "0.00008000"], ["71191.33000000", "0.00000000"], ["71191.37000000", "0.00000000"], ["71192.47000000", "0.00702000"], ["71192.49000000", "0.00000000"], ["71193.47000000", "0.00000000"], ["71193.77000000", "0.54902000"], ["71193.99000000", "0.00000000"], ["71195.20000000", "0.00000000"], ["71195.27000000", "0.04000000"], ["71195.48000000", "0.00000000"], ["71195.87000000", "0.03000000"], ["71196.87000000", "0.00702000"], ["71197.37000000", "0.08000000"], ["71197.59000000", "0.00000000"], ["71198.08000000", "0.00000000"], ["71198.33000000", "0.00000000"], ["71199.80000000", "0.00000000"], ["71199.95000000", "0.00000000"], ["71199.99000000", "1.09643000"], ["71200.86000000", "0.00000000"], ["71201.97000000", "0.00000000"], ["71201.98000000", "0.00000000"], ["71202.70000000", "0.00000000"], ["71202.98000000", "0.00000000"], ["71203.14000000", "0.00000000"], ["71203.82000000", "0.14044000"], ["71204.19000000", "0.42137000"], ["71204.33000000", "0.00000000"], ["71205.31000000", "0.06000000"], ["71205.98000000", "0.00000000"], ["71207.28000000", "0.00000000"], ["71208.42000000", "0.00000000"], ["71208.82000000", "0.00000000"], ["71209.02000000", "0.00000000"], ["71209.60000000", "0.00200000"], ["71210.55000000", "0.00000000"], ["71211.48000000", "0.12100000"], ["71211.62000000", "0.00000000"], ["71212.65000000", "0.00000000"], ["71212.72000000", "0.00000000"], ["71213.51000000", "0.00000000"], ["71214.72000000", "0.50543000"], ["71215.77000000", "0.00000000"], ["71216.02000000", "0.00200000"], ["71216.78000000", "0.00702000"], ["71217.08000000", "0.00000000"], ["71217.26000000", "0.00702000"], ["71217.80000000", "0.00200000"], ["71218.82000000", "0.00000000"], ["71219.94000000", "0.01028000"], ["71220.71000000", "0.00000000"], ["71220.86000000", "0.00000000"], ["71224.64000000", "0.00000000"], ["71226.77000000", "0.00000000"], ["71227.51000000", "0.00000000"], ["71227.98000000", "0.00428000"], ["71228.98000000", "0.00000000"], ["71230.05000000", "0.00000000"], ["71233.55000000", "0.04423000"], ["71234.16000000", "0.00029000"], ["71237.21000000", "0.00000000"], ["71237.66000000", "0.00000000"], ["71238.91000000", "0.00000000"], ["71241.01000000", "0.00000000"], ["71241.70000000", "0.00702000"], ["71241.75000000", "0.00000000"], ["71243.21000000", "0.00000000"], ["71244.28000000", "0.00000000"], ["71261.63000000", "0.70153000"], ["71275.36000000", "0.10000000"], ["71278.36000000", "0.00000000"], ["71282.52000000", "0.00000000"], ["71283.58000000", "0.00000000"], ["71292.02000000", "0.00000000"], ["71293.99000000", "0.00994000"], ["71295.09000000", "0.00000000"], ["71296.49000000", "0.00000000"], ["71297.65000000", "0.00000000"], ["71300.50000000", "0.00000000"], ["71309.06000000", "0.00000000"], ["71321.72000000", "0.00000000"], ["71325.90000000", "0.00000000"], ["71329.37000000", "0.00000000"], ["71331.91000000", "0.00000000"], ["71334.85000000", "0.00000000"], ["71335.09000000", "0.00000000"], ["71335.92000000", "0.00000000"], ["71336.05000000", "0.00000000"], ["71336.76000000", "0.00000000"], ["71337.12000000", "0.00000000"], ["71337.21000000", "0.00000000"], ["71340.56000000", "0.08995000"], ["71343.02000000", "0.08995000"], ["71343.10000000", "0.08995000"], ["71349.01000000", "0.00000000"], ["71350.72000000", "0.00000000"], ["71352.57000000", "0.00000000"], ["71361.22000000", "0.00000000"], ["71389.66000000", "0.00399000"]]}
{"e": "aggTrade", "E": 1773437547334, "s": "BTCUSDT", "a": 3904057744, "p": "71179.19000000", "q": "0.00080000", "f": 6104983922, "l": 6104983931, "T": 1773437547334, "m": false, "M": true}
{"e": "aggTrade", "E": 1773437547334, "s": "BTCUSDT", "a": 3904057745, "p": "71179.20000000", "q": "0.00032000", "f": 6104983932, "l": 6104983935, "T": 1773437547334, "m": false, "M": true}
{"e": "aggTrade", "E": 1773437547334, "s": "BTCUSDT", "a": 3904057746, "p": "71179.90000000", "q": "0.00241000", "f": 6104983936, "l": 6104983936, "T": 1773437547334, "m": false, "M": true}
{"e": "aggTrade", "E": 1773437547336, "s": "BTCUSDT", "a": 3904057747, "p": "71181.27000000", "q": "0.00039000", "f": 6104983937, "l": 6104983940, "T": 1773437547336, "m": false, "M": true}
{"e": "aggTrade", "E": 1773437547336, "s": "BTCUSDT", "a": 3904057748, "p": "71181.42000000", "q": "0.00008000", "f": 6104983941, "l": 6104983941, "T": 1773437547336, "m": false, "M": true}
{"e": "aggTrade", "E": 1773437547336, "s": "BTCUSDT", "a": 3904057749, "p": "71181.60000000", "q": "0.00008000", "f": 6104983942, "l": 6104983942, "T": 1773437547336, "m": false, "M": true}
{"e": "aggTrade", "E": 1773437547336, "s": "BTCUSDT", "a": 3904057750, "p": "71182.37000000", "q": "0.00008000", "f": 6104983943, "l": 6104983943, "T": 1773437547336, "m": false, "M": true}
{"e": "aggTrade", "E": 1773437547336, "s": "BTCUSDT", "a": 3904057751, "p": "71182.69000000", "q": "0.00008000", "f": 6104983944, "l": 6104983944, "T": 1773437547336, "m": false, "M": true}
{"e": "depthUpdate", "E": 1773437547414, "s": "BTCUSDT", "U": 90101512082, "u": 90101512639, "b": [["71182.69000000", "4.11224000"], ["71182.68000000", "0.00008000"], ["71182.36000000", "0.00000000"], ["71182.20000000", "0.00200000"], ["71181.59000000", "0.00000000"], ["71181.46000000", "0.00000000"], ["71181.41000000", "0.00000000"], ["71181.36000000", "0.00000000"], ["71181.27000000", "1.50114000"], ["71181.26000000", "0.00364000"], ["71181.25000000", "0.00000000"], ["71181.20000000", "0.00000000"], ["71181.11000000", "0.00021000"], ["71181.10000000", "0.26675000"], ["71180.42000000", "0.00200000"], ["71180.23000000", "0.00000000"], ["71179.99000000", "0.00000000"], ["71179.89000000", "0.00000000"], ["71179.54000000", "0.00009000"], ["71179.19000000", "0.00702000"], ["71179.18000000", "2.83518000"], ["71179.17000000", "0.03364000"], ["71177.56000000", "0.00000000"], ["71177.55000000", "0.00000000"], ["71177.54000000", "0.02832000"], ["71177.43000000", "0.00008000"], ["71176.69000000", "0.00996000"], ["71175.97000000", "0.76943000"], ["71175.56000000", "0.00008000"], ["71173.59000000", "0.03184000"], ["71173.58000000", "0.04932000"], ["71173.28000000", "0.02000000"], ["71172.05000000", "0.00000000"], ["71171.88000000", "0.12025000"], ["71170.99000000", "0.42838000"], ["71170.96000000", "0.00329000"], ["71170.91000000", "0.00140000"], ["71170.70000000", "0.02810000"], ["71170.42000000", "0.00241000"], ["71166.97000000", "0.00000000"], ["71166.78000000", "0.00702000"], ["71166.50000000", "0.00140000"], ["71166.19000000", "0.00000000"], ["71166.18000000", "0.00209000"], ["71166.05000000", "0.00118000"], ["71166.02000000", "0.00012000"], ["71164.59000000", "0.00191000"], ["71162.83000000", "0.00000000"], ["71161.34000000", "0.02459000"], ["71156.91000000", "0.00070000"], ["71156.39000000", "0.00000000"], ["71156.03000000", "0.00000000"], ["71153.72000000", "0.00000000"], ["71153.64000000", "0.00000000"], ["71153.61000000", "0.00000000"], ["71152.15000000", "0.00000000"], ["71152.10000000", "0.00000000"], ["71151.94000000", "0.00000000"], ["71147.09000000", "0.01133000"], ["71146.36000000", "0.00000000"], ["71140.34000000", "0.00011000"], ["71136.14000000", "0.00444000"], ["71135.46000000", "0.00000000"], ["71130.01000000", "0.00000000"], ["71124.89000000", "0.00000000"], ["71124.79000000", "0.30007000"], ["71103.81000000", "0.05338000"], ["71103.80000000", "0.00000000"], ["71102.00000000", "0.05544000"], ["71100.16000000", "0.05262000"], ["71093.20000000", "0.59467000"], ["71093.19000000", "0.00000000"], ["71091.16000000", "0.00000000"], ["71088.85000000", "0.08896000"], ["71087.66000000", "0.00000000"], ["71085.83000000", "0.00000000"], ["71085.82000000", "0.00000000"], ["71081.74000000", "0.02656000"], ["71080.97000000", "0.03197000"], ["71076.46000000", "0.07297000"], ["71056.67000000", "0.00000000"], ["71036.91000000", "0.00000000"], ["71022.59000000", "0.05340000"], ["71008.82000000", "0.16192000"], ["71007.01000000", "0.08896000"], ["71004.61000000", "0.08896000"], ["71003.03000000", "0.08896000"], ["71001.36000000", "0.08896000"], ["70989.37000000", "0.04917000"], ["70988.81000000", "1.06144000"], ["70974.65000000", "0.00000000"], ["70954.61000000", "0.00000000"], ["64064.43000000", "0.00036000"], ["64061.27000000", "0.00000000"], ["49827.15000000", "0.00000000"], ["49825.90000000", "0.00000000"]], "a": [["71179.19000000", "0.00000000"], ["71179.20000000", "0.00000000"], ["71179.90000000", "0.00000000"], ["71180.24000000", "0.00000000"], ["71181.27000000", "0.00000000"], ["71181.42000000", "0.00000000"], ["71181.47000000", "0.00000000"], ["71181.60000000", "0.00000000"], ["71182.37000000", "0.00000000"], ["71182.69000000", "0.00000000"], ["71182.70000000", "0.00931000"], ["71182.71000000", "0.00040000"], ["71183.03000000", "0.00000000"], ["71183.61000000", "0.00000000"], ["71183.62000000", "0.00000000"], ["71183.97000000", "0.00008000"], ["71184.20000000", "0.00000000"], ["71184.27000000", "0.00000000"], ["71185.39000000", "0.00000000"], ["71185.40000000", "0.00000000"], ["71185.53000000", "0.00000000"], ["71185.67000000", "0.00024000"], ["71185.68000000", "0.00000000"], ["71185.70000000", "0.00141000"], ["71186.17000000", "0.00000000"], ["71186.49000000", "0.00008000"], ["71186.50000000", "0.00016000"], ["71186.62000000", "0.00000000"], ["71187.30000000", "0.01597000"], ["71187.45000000", "0.00024000"], ["71187.46000000", "0.00000000"], ["71188.49000000", "0.00029000"], ["71188.53000000", "0.00000000"], ["71188.76000000", "0.00000000"], ["71189.37000000", "0.00000000"], ["71189.66000000", "0.00008000"], ["71189.67000000", "0.00016000"], ["71189.71000000", "0.00000000"], ["71189.75000000", "0.02544000"], ["71190.09000000", "0.08617000"], ["71190.37000000", "0.00000000"], ["71190.82000000", "0.00000000"], ["71190.83000000", "0.00016000"], ["71191.10000000", "0.00000000"], ["71191.29000000", "0.00000000"], ["71191.30000000", "0.00000000"], ["71192.47000000", "0.00000000"], ["71192.48000000", "0.00000000"], ["71193.34000000", "0.00000000"], ["71193.37000000", "0.00140000"], ["71193.75000000", "0.00000000"], ["71193.76000000", "0.00016000"], ["71195.64000000", "0.00029000"], ["71195.99000000", "0.00702000"], ["71196.04000000", "1.68082000"], ["71196.05000000", "0.00000000"], ["71196.09000000", "0.00702000"], ["71196.87000000", "0.00000000"], ["71197.90000000", "0.24500000"], ["71198.31000000", "0.00000000"], ["71199.06000000", "0.00140000"], ["71199.98000000", "0.00702000"], ["71199.99000000", "0.00000000"], ["71200.31000000", "0.29553000"], ["71200.83000000", "0.00542000"], ["71201.01000000", "0.02000000"], ["71201.26000000", "0.00000000"], ["71201.30000000", "0.00000000"], ["71201.54000000", "0.00000000"], ["71202.05000000", "0.00000000"], ["71202.12000000", "0.03486000"], ["71202.46000000", "0.00000000"], ["71202.69000000", "0.00000000"], ["71203.82000000", "0.00000000"], ["71204.05000000", "0.02460000"], ["71204.17000000", "1.53170000"], ["71204.18000000", "2.53023000"], ["71204.19000000", "0.00000000"], ["71204.20000000", "0.00000000"], ["71204.21000000", "0.00000000"], ["71204.22000000", "1.68082000"], ["71205.41000000", "0.00000000"], ["71205.96000000", "0.42136000"], ["71207.66000000", "0.00000000"], ["71207.98000000", "0.00000000"], ["71211.48000000", "0.00000000"], ["71211.98000000", "0.04891000"], ["71212.07000000", "0.00000000"], ["71213.30000000", "0.00140000"], ["71213.97000000", "0.00118000"], ["71214.48000000", "0.00012000"], ["71216.76000000", "0.00000000"], ["71216.77000000", "0.00000000"], ["71218.05000000", "0.13687000"], ["71218.32000000", "0.00000000"], ["71221.36000000", "0.00200000"], ["71223.89000000", "0.00349000"], ["71225.86000000", "0.00625000"], ["71227.21000000", "0.03816000"], ["71227.30000000", "0.00000000"], ["71230.45000000", "0.00000000"], ["71231.30000000", "0.06259000"], ["71236.89000000", "0.00000000"], ["71236.96000000", "0.00868000"], ["71237.09000000", "0.00008000"], ["71238.83000000", "0.00000000"], ["71244.68000000", "0.00000000"], ["71245.54000000", "0.07650000"], ["71249.55000000", "0.01730000"], ["71254.67000000", "0.00008000"], ["71256.08000000", "0.00008000"], ["71260.72000000", "0.01133000"], ["71275.07000000", "0.05759000"], ["71278.44000000", "0.00000000"], ["71280.69000000", "0.06387000"], ["71288.41000000", "0.02809000"], ["71288.78000000", "0.00000000"], ["71292.74000000", "7.01227000"], ["71296.77000000", "0.06791000"], ["71303.30000000", "0.00008000"], ["71303.54000000", "0.04600000"], ["71321.23000000", "0.07571000"], ["71336.52000000", "0.00000000"], ["71344.50000000", "0.08896000"], ["71352.34000000", "0.00000000"], ["71355.58000000", "0.04098000"], ["71357.66000000", "0.04098000"], ["71367.16000000", "0.02809000"], ["71370.08000000", "0.02809000"], ["71379.24000000", "0.00000000"], ["71389.66000000", "0.00000000"], ["71392.76000000", "0.08896000"], ["71399.67000000", "0.00399000"], ["71454.40000000", "0.00000000"]]}
{"e": "depthUpdate", "E": 1773437547514, "s": "BTCUSDT", "U": 90101512640, "u": 90101512858, "b": [["71182.69000000", "4.14934000"], ["71181.67000000", "0.00008000"], ["71181.27000000", "0.77359000"], ["71181.26000000", "0.00356000"], ["71181.10000000", "0.26675000"], ["71181.02000000", "0.02590000"], ["71180.47000000", "0.00141000"], ["71179.22000000", "0.00838000"], ["71179.19000000", "0.00008000"], ["71179.18000000", "2.53518000"], ["71179.17000000", "0.01908000"], ["71178.12000000", "0.00000000"], ["71177.54000000", "0.02832000"], ["71176.70000000", "0.00000000"], ["71176.69000000", "0.01004000"], ["71175.97000000", "0.76951000"], ["71175.96000000", "2.53379000"], ["71175.95000000", "0.00012000"], ["71175.57000000", "0.00702000"], ["71175.42000000", "0.00000000"], ["71174.55000000", "0.00000000"], ["71173.59000000", "0.07002000"], ["71173.58000000", "0.03356000"], ["71170.47000000", "0.00702000"], ["71168.96000000", "0.00000000"], ["71167.50000000", "0.06000000"], ["71166.19000000", "0.00009000"], ["71166.18000000", "0.00200000"], ["71163.17000000", "0.00000000"], ["71161.97000000", "0.00107000"], ["71152.93000000", "0.00000000"], ["71150.05000000", "0.03496000"], ["71149.85000000", "0.14639000"], ["71148.82000000", "0.02794000"], ["71145.22000000", "0.00000000"], ["71144.66000000", "1.09643000"], ["71140.70000000", "0.00180000"], ["71140.33000000", "0.00000000"], ["71123.85000000", "0.00291000"], ["71109.34000000", "0.00000000"], ["71097.88000000", "0.08896000"], ["71096.57000000", "0.08896000"], ["71093.31000000", "0.08896000"], ["71089.19000000", "0.08896000"], ["71078.51000000", "0.07296000"], ["71076.37000000", "0.07296000"], ["71062.83000000", "0.09210000"], ["71024.84000000", "0.00000000"], ["70993.57000000", "0.00000000"], ["70988.50000000", "0.00000000"], ["70988.41000000", "0.00000000"], ["70987.08000000", "0.00000000"], ["69763.85000000", "0.00008000"], ["56946.16000000", "0.00035000"]], "a": [["71182.70000000", "0.00923000"], ["71182.71000000", "0.00032000"], ["71185.67000000", "0.00000000"], ["71185.70000000", "0.00000000"], ["71185.87000000", "0.00000000"], ["71185.91000000", "0.00141000"], ["71186.49000000", "0.00000000"], ["71186.50000000", "0.00000000"], ["71187.29000000", "0.00008000"], ["71187.30000000", "0.00016000"], ["71187.36000000", "0.00024000"], ["71187.37000000", "0.00000000"], ["71187.45000000", "0.00000000"], ["71189.66000000", "0.00000000"], ["71189.67000000", "0.00000000"], ["71189.74000000", "0.00008000"], ["71189.75000000", "0.00016000"], ["71190.08000000", "0.00024000"], ["71190.09000000", "0.11110000"], ["71190.83000000", "0.00000000"], ["71192.88000000", "0.00000000"], ["71193.77000000", "0.54918000"], ["71195.26000000", "0.00000000"], ["71195.27000000", "0.00000000"], ["71195.87000000", "0.00000000"], ["71196.02000000", "0.00000000"], ["71196.08000000", "0.00008000"], ["71197.37000000", "0.00000000"], ["71198.49000000", "0.01810000"], ["71200.31000000", "0.09200000"], ["71200.57000000", "0.15009000"], ["71202.12000000", "0.00000000"], ["71203.47000000", "0.00000000"], ["71204.60000000", "0.00000000"], ["71207.65000000", "0.00000000"], ["71209.15000000", "0.00000000"], ["71210.50000000", "0.00000000"], ["71210.83000000", "0.50546000"], ["71211.89000000", "0.00140000"], ["71211.90000000", "0.00000000"], ["71213.05000000", "0.37888000"], ["71213.61000000", "0.00000000"], ["71213.75000000", "0.00000000"], ["71213.77000000", "0.00193000"], ["71214.15000000", "0.00000000"], ["71215.22000000", "0.12111000"], ["71216.04000000", "0.00702000"], ["71217.26000000", "0.00000000"], ["71218.82000000", "0.50540000"], ["71218.95000000", "0.00000000"], ["71219.54000000", "0.14625000"], ["71219.58000000", "0.00200000"], ["71221.16000000", "0.00702000"], ["71224.62000000", "0.00702000"], ["71224.75000000", "0.00702000"], ["71231.30000000", "0.00000000"], ["71232.65000000", "0.00000000"], ["71233.79000000", "0.00000000"], ["71236.71000000", "0.00000000"], ["71236.96000000", "0.00000000"], ["71239.62000000", "0.00000000"], ["71242.98000000", "0.00000000"], ["71244.05000000", "0.00000000"], ["71245.54000000", "0.00000000"], ["71245.83000000", "3.44242000"], ["71246.14000000", "0.00000000"], ["71246.89000000", "0.00000000"], ["71248.02000000", "0.00000000"], ["71251.31000000", "0.01075000"], ["71252.96000000", "0.00110000"], ["71265.16000000", "0.51461000"], ["71265.33000000", "0.00000000"], ["71280.69000000", "0.00000000"], ["71288.41000000", "0.00000000"], ["71303.12000000", "0.00000000"], ["71305.17000000", "0.00000000"], ["71307.16000000", "0.00000000"], ["71307.17000000", "0.00000000"], ["71309.14000000", "0.00000000"], ["71311.28000000", "0.00000000"], ["71311.45000000", "0.00000000"], ["71332.13000000", "0.00000000"], ["71334.01000000", "0.00000000"], ["71336.13000000", "0.00000000"], ["71342.86000000", "0.00000000"], ["71370.62000000", "0.02669000"], ["71378.29000000", "0.00000000"], ["71378.64000000", "0.00399000"], ["71378.86000000", "0.00000000"], ["71392.92000000", "0.08896000"], ["71395.39000000", "0.08896000"], ["71399.67000000", "0.00000000"]]}
{"e": "depthUpdate", "E": 1773437547614, "s": "BTCUSDT", "U": 90101512859, "u": 90101512945, "b": [["71182.69000000", "4.16841000"], ["71181.10000000", "0.26675000"], ["71181.02000000", "0.02598000"], ["71179.22000000", "0.00846000"], ["71179.19000000", "0.00000000"], ["71175.97000000", "0.76943000"], ["71166.50000000", "0.00149000"], ["71166.19000000", "0.00000000"], ["71132.93000000", "0.07236000"], ["71130.05000000", "0.04215000"], ["71120.24000000", "0.00057000"], ["71110.35000000", "0.00000000"], ["71107.23000000", "0.00000000"], ["71104.70000000", "0.48920000"], ["71098.07000000", "0.00000000"], ["71093.31000000", "0.00000000"], ["71089.19000000", "0.00000000"], ["71088.85000000", "0.00000000"], ["71080.97000000", "0.00997000"], ["71076.37000000", "0.00000000"], ["71067.16000000", "0.00000000"], ["71047.79000000", "1.14610000"], ["71047.38000000", "0.02200000"], ["71013.36000000", "0.08896000"], ["71012.37000000", "0.08896000"], ["71012.33000000", "0.08896000"], ["64064.43000000", "0.00054000"], ["56946.16000000", "0.00000000"]], "a": [["71182.70000000", "0.00891000"], ["71182.71000000", "0.00024000"], ["71186.41000000", "0.00000000"], ["71187.29000000", "0.00000000"], ["71187.30000000", "0.00000000"], ["71187.36000000", "0.00000000"], ["71187.38000000", "0.01584000"], ["71189.74000000", "0.00000000"], ["71189.75000000", "0.00000000"], ["71192.08000000", "0.00141000"], ["71194.14000000", "0.01038000"], ["71196.03000000", "0.00016000"], ["71207.72000000", "0.00000000"], ["71208.49000000", "0.14044000"], ["71209.21000000", "0.14044000"], ["71209.82000000", "0.50580000"], ["71214.84000000", "0.00141000"], ["71219.21000000", "0.00000000"], ["71223.90000000", "0.00000000"], ["71227.21000000", "0.01147000"], ["71227.49000000", "0.00434000"], ["71231.40000000", "0.48645000"], ["71231.85000000", "0.03511000"], ["71233.08000000", "0.03680000"], ["71236.70000000", "0.00000000"], ["71237.94000000", "0.00000000"], ["71239.46000000", "0.84851000"], ["71250.91000000", "0.00000000"], ["71253.66000000", "0.48630000"], ["71253.94000000", "0.04215000"], ["71275.36000000", "0.00000000"], ["71282.52000000", "0.00000000"], ["71286.86000000", "0.02200000"], ["71288.36000000", "1.14223000"], ["71311.10000000", "1.14187000"], ["71367.46000000", "0.00076000"], ["71367.97000000", "0.00000000"], ["71372.10000000", "0.00399000"], ["71378.64000000", "0.00000000"]]}
{"e": "depthUpdate", "E": 1773437547714, "s": "BTCUSDT", "U": 90101512946, "u": 90101513014, "b": [["71182.69000000", "4.31068000"], ["71179.54000000", "0.00017000"], ["71174.58000000", "0.00000000"], ["71174.46000000", "0.22864000"], ["71174.45000000", "0.50572000"], ["71173.59000000", "0.00377000"], ["71155.51000000", "0.00000000"], ["71152.69000000", "0.02753000"], ["71148.82000000", "0.00000000"], ["71118.21000000", "0.00000000"], ["71092.80000000", "0.00000000"], ["71077.28000000", "0.04425000"], ["71047.38000000", "0.00000000"], ["70959.35000000", "0.00034000"], ["70949.98000000", "0.00000000"], ["64064.43000000", "0.00090000"]], "a": [["71182.70000000", "0.00899000"], ["71185.91000000", "0.00000000"], ["71186.26000000", "0.00000000"], ["71186.30000000", "0.00000000"], ["71186.56000000", "0.00000000"], ["71186.70000000", "0.00000000"], ["71187.37000000", "0.00024000"], ["71187.38000000", "0.01600000"], ["71187.49000000", "0.00141000"], ["71192.08000000", "0.00000000"], ["71193.56000000", "0.00000000"], ["71195.99000000", "0.00718000"], ["71201.81000000", "0.00000000"], ["71205.33000000", "0.00000000"], ["71206.13000000", "0.03527000"], ["71210.83000000", "0.00000000"], ["71215.22000000", "0.00000000"], ["71216.42000000", "0.00000000"], ["71218.95000000", "0.50540000"], ["71219.21000000", "0.00000000"], ["71225.41000000", "0.00702000"], ["71227.65000000", "0.35869000"], ["71234.52000000", "0.00000000"], ["71235.32000000", "0.06447000"], ["71248.76000000", "0.00000000"], ["71249.00000000", "0.91215000"], ["71249.56000000", "0.07857000"], ["71250.06000000", "0.06015000"], ["71290.84000000", "0.12527000"], ["71315.94000000", "0.02809000"], ["71339.60000000", "0.02809000"], ["71359.15000000", "0.02809000"], ["71368.32000000", "0.02809000"], ["71392.57000000", "0.08896000"], ["71394.88000000", "0.08896000"]]}
{"e": "aggTrade", "E": 1773437547728, "s": "BTCUSDT", "a": 3904057752, "p": "71182.70000000", "q": "0.00907000", "f": 6104983945, "l": 6104983954, "T": 1773437547727, "m": false, "M": true}
{"e": "aggTrade", "E": 1773437547728, "s": "BTCUSDT", "a": 3904057753, "p": "71182.71000000", "q": "0.00032000", "f": 6104983955, "l": 6104983958, "T": 1773437547727, "m": false, "M": true}
{"e": "aggTrade", "E": 1773437547729, "s": "BTCUSDT", "a": 3904057754, "p": "71183.23000000", "q": "0.00147000", "f": 6104983959, "l": 6104983959, "T": 1773437547729, "m": false, "M": true}
{"e": "aggTrade", "E": 1773437547729, "s": "BTCUSDT", "a": 3904057755, "p": "71183.97000000", "q": "0.00008000", "f": 6104983960, "l": 6104983960, "T": 1773437547729, "m": false, "M": true}
{"e": "aggTrade", "E": 1773437547729, "s": "BTCUSDT", "a": 3904057756, "p": "71184.00000000", "q": "0.00040000", "f": 6104983961, "l": 6104983961, "T": 1773437547729, "m": false, "M": true}
{"e": "aggTrade", "E": 1773437547729, "s": "BTCUSDT", "a": 3904057757, "p": "71184.17000000", "q": "0.00300000", "f": 6104983962, "l": 6104983962, "T": 1773437547729, "m": false, "M": true}
{"e": "aggTrade", "E": 1773437547729, "s": "BTCUSDT", "a": 3904057758, "p": "71184.35000000", "q": "0.00008000", "f": 6104983963, "l": 6104983963, "T": 1773437547729, "m": false, "M": true}
{"e": "aggTrade", "E": 1773437547731, "s": "BTCUSDT", "a": 3904057759, "p": "71185.00000000", "q": "0.00049000", "f": 6104983964, "l": 6104983967, "T": 1773437547730, "m": false, "M": true}
{"e": "aggTrade", "E": 1773437547731, "s": "BTCUSDT", "a": 3904057760, "p": "71185.14000000", "q": "0.00015000", "f": 6104983968, "l": 6104983968, "T": 1773437547730, "m": false, "M": true}
{"e": "aggTrade", "E": 1773437547731, "s": "BTCUSDT", "a": 3904057761, "p": "71186.00000000", "q": "0.00040000", "f": 6104983969, "l": 6104983969, "T": 1773437547730, "m": false, "M": true}
{"e": "aggTrade", "E": 1773437547731, "s": "BTCUSDT", "a": 3904057762, "p": "71186.92000000", "q": "0.00008000", "f": 6104983970, "l": 6104983970, "T": 1773437547730, "m": false, "M": true}
{"e": "aggTrade", "E": 1773437547731, "s": "BTCUSDT", "a": 3904057763, "p": "71187.28000000", "q": "0.00008000", "f": 6104983971, "l": 6104983971, "T": 1773437547730, "m": false, "M": true}
{"e": "aggTrade", "E": 1773437547731, "s": "BTCUSDT", "a": 3904057764, "p": "71187.37000000", "q": "0.00008000", "f": 6104983972, "l": 6104983972, "T": 1773437547730, "m": false, "M": true}
{"e": "aggTrade", "E": 1773437547744, "s": "BTCUSDT", "a": 3904057765, "p": "71187.38000000", "q": "0.00128000", "f": 6104983973, "l": 6104983988, "T": 1773437547743, "m": false, "M": true}
{"e": "aggTrade", "E": 1773437547744, "s": "BTCUSDT", "a": 3904057766, "p": "71187.39000000", "q": "0.00064000", "f": 6104983989, "l": 6104983996, "T": 1773437547743, "m": false, "M": true}
{"e": "aggTrade", "E": 1773437547744, "s": "BTCUSDT", "a": 3904057767, "p": "71188.00000000", "q": "0.00040000", "f": 6104983997, "l": 6104983997, "T": 1773437547743, "m": false, "M": true}
{"e": "aggTrade", "E": 1773437547744, "s": "BTCUSDT", "a": 3904057768, "p": "71188.57000000", "q": "0.00092000", "f": 6104983998, "l": 6104983998, "T": 1773437547743, "m": false, "M": true}
{"e": "aggTrade", "E": 1773437547813, "s": "BTCUSDT", "a": 3904057769, "p": "71188.57000000", "q": "0.00013000", "f": 6104983999, "l": 6104983999, "T": 1773437547812, "m": false, "M": true}
{"e": "depthUpdate", "E": 1773437547814, "s": "BTCUSDT", "U": 90101513015, "u": 90101513793, "b": [["71188.56000000", "5.61205000"], ["71188.55000000", "0.00008000"], ["71188.48000000", "0.00000000"], ["71187.99000000", "0.00000000"], ["71187.54000000", "0.00200000"], ["71187.48000000", "0.00000000"], ["71187.47000000", "0.00000000"], ["71187.39000000", "0.36436000"], ["71187.38000000", "0.00021000"], ["71187.37000000", "0.40722000"], ["71187.36000000", "0.00000000"], ["71187.27000000", "0.00000000"], ["71186.91000000", "0.00000000"], ["71185.99000000", "0.00000000"], ["71185.76000000", "0.00200000"], ["71185.13000000", "0.00000000"], ["71185.09000000", "0.00000000"], ["71185.00000000", "1.19531000"], ["71184.99000000", "0.00364000"], ["71184.98000000", "0.00000000"], ["71184.63000000", "0.00000000"], ["71184.54000000", "0.00000000"], ["71184.53000000", "0.00356000"], ["71184.34000000", "0.00000000"], ["71184.16000000", "0.00000000"], ["71183.99000000", "0.00000000"], ["71183.98000000", "0.00200000"], ["71183.96000000", "0.00000000"], ["71183.40000000", "0.00000000"], ["71183.22000000", "2.53023000"], ["71183.15000000", "0.00000000"], ["71183.14000000", "0.00364000"], ["71183.08000000", "0.00000000"], ["71182.99000000", "0.00000000"], ["71182.98000000", "0.27652000"], ["71182.96000000", "0.00000000"], ["71182.91000000", "0.00000000"], ["71182.79000000", "0.00000000"], ["71182.70000000", "0.00000000"], ["71182.69000000", "0.49216000"], ["71182.68000000", "0.00000000"], ["71181.27000000", "0.00008000"], ["71181.11000000", "0.00723000"], ["71179.87000000", "0.00361000"], ["71179.55000000", "0.00702000"], ["71179.20000000", "1.49249000"], ["71179.19000000", "1.68082000"], ["71179.18000000", "2.53379000"], ["71179.17000000", "0.01900000"], ["71178.37000000", "0.50569000"], ["71177.55000000", "0.00702000"], ["71177.54000000", "0.02824000"], ["71176.70000000", "0.00140000"], ["71176.69000000", "0.00996000"], ["71176.54000000", "0.00000000"], ["71175.98000000", "0.61571000"], ["71175.59000000", "0.00372000"], ["71175.57000000", "0.00000000"], ["71173.60000000", "0.00482000"], ["71173.56000000", "0.00000000"], ["71173.49000000", "0.00141000"], ["71171.88000000", "0.00000000"], ["71171.18000000", "0.06000000"], ["71170.99000000", "0.00702000"], ["71170.15000000", "0.00000000"], ["71169.00000000", "0.00000000"], ["71168.40000000", "0.00200000"], ["71167.50000000", "0.00000000"], ["71166.86000000", "0.05267000"], ["71166.78000000", "0.00000000"], ["71166.48000000", "0.00140000"], ["71166.44000000", "0.00018000"], ["71166.00000000", "0.00313000"], ["71164.90000000", "0.00200000"], ["71163.35000000", "0.00070000"], ["71161.90000000", "0.00200000"], ["71161.89000000", "0.00000000"], ["71159.93000000", "0.02677000"], ["71159.19000000", "0.00000000"], ["71159.06000000", "0.00000000"], ["71157.28000000", "0.00000000"], ["71156.17000000", "0.00000000"], ["71155.50000000", "0.00000000"], ["71154.79000000", "0.03548000"], ["71153.35000000", "0.70260000"], ["71153.30000000", "0.00000000"], ["71152.34000000", "0.00000000"], ["71151.59000000", "0.00000000"], ["71150.10000000", "0.00000000"], ["71150.05000000", "0.00000000"], ["71148.39000000", "0.00000000"], ["71147.64000000", "0.04387000"], ["71147.54000000", "0.11736000"], ["71146.80000000", "0.00000000"], ["71142.72000000", "0.00000000"], ["71142.16000000", "0.00627000"], ["71141.87000000", "0.00430000"], ["71141.33000000", "0.00000000"], ["71139.98000000", "0.00424000"], ["71139.29000000", "0.00011000"], ["71136.15000000", "0.00000000"], ["71135.21000000", "1.43380000"], ["71131.71000000", "0.00000000"], ["71131.57000000", "0.00013000"], ["71129.49000000", "0.00000000"], ["71128.01000000", "0.00000000"], ["71117.95000000", "0.53957000"], ["71115.33000000", "0.00000000"], ["71103.75000000", "0.46104000"], ["71101.74000000", "0.00000000"], ["71100.20000000", "0.08896000"], ["71096.01000000", "0.13346000"], ["71094.78000000", "0.00000000"], ["71094.55000000", "0.00000000"], ["71094.37000000", "0.00000000"], ["71090.81000000", "0.08896000"], ["71085.01000000", "0.05834000"], ["71084.84000000", "0.08896000"], ["71083.87000000", "0.00947000"], ["71081.74000000", "0.04494000"], ["71080.76000000", "0.07297000"], ["71077.38000000", "0.07297000"], ["71076.46000000", "0.00000000"], ["71075.32000000", "0.00000000"], ["71073.20000000", "0.00000000"], ["71063.88000000", "0.00000000"], ["71022.54000000", "0.20949000"], ["71015.89000000", "0.08896000"], ["71004.35000000", "0.00000000"], ["71002.29000000", "1.20000000"], ["70994.02000000", "0.00000000"], ["70993.86000000", "0.00000000"], ["70993.68000000", "0.00000000"], ["70993.61000000", "0.00000000"], ["70983.45000000", "0.00000000"], ["70131.89000000", "1.74330000"], ["70116.32000000", "0.00000000"], ["64069.71000000", "0.00018000"], ["64064.43000000", "0.00000000"], ["64064.00000000", "0.00000000"], ["49830.89000000", "0.00000000"], ["49829.64000000", "0.00000000"], ["49828.40000000", "0.00000000"]], "a": [["71182.70000000", "0.00000000"], ["71182.71000000", "0.00000000"], ["71183.23000000", "0.00000000"], ["71183.97000000", "0.00000000"], ["71184.00000000", "0.00000000"], ["71184.17000000", "0.00000000"], ["71184.35000000", "0.00000000"], ["71185.00000000", "0.00000000"], ["71185.14000000", "0.00000000"], ["71186.00000000", "0.00000000"], ["71186.92000000", "0.00000000"], ["71187.28000000", "0.00000000"], ["71187.37000000", "0.00000000"], ["71187.38000000", "0.00000000"], ["71187.39000000", "0.00000000"], ["71187.49000000", "0.00000000"], ["71187.65000000", "0.00000000"], ["71188.00000000", "0.00000000"], ["71188.04000000", "0.00000000"], ["71188.49000000", "0.00000000"], ["71188.57000000", "0.40635000"], ["71188.58000000", "0.00056000"], ["71189.47000000", "0.00024000"], ["71189.48000000", "0.01575000"], ["71190.01000000", "0.00000000"], ["71190.08000000", "0.00008000"], ["71190.09000000", "0.00016000"], ["71190.68000000", "0.00000000"], ["71191.25000000", "0.00024000"], ["71191.26000000", "0.02590000"], ["71192.10000000", "0.00000000"], ["71193.37000000", "0.00000000"], ["71193.76000000", "0.00008000"], ["71193.77000000", "0.00016000"], ["71194.13000000", "0.00008000"], ["71194.66000000", "0.00000000"], ["71195.88000000", "0.00000000"], ["71195.99000000", "0.00016000"], ["71196.02000000", "0.00016000"], ["71196.03000000", "0.00000000"], ["71196.04000000", "0.00016000"], ["71196.09000000", "0.00000000"], ["71196.10000000", "0.00000000"], ["71196.44000000", "0.00000000"], ["71196.89000000", "0.00141000"], ["71197.89000000", "0.00016000"], ["71197.90000000", "0.24508000"], ["71198.49000000", "0.00000000"], ["71199.06000000", "0.00000000"], ["71199.11000000", "0.02000000"], ["71199.55000000", "0.00702000"], ["71199.83000000", "0.00008000"], ["71199.98000000", "0.00000000"], ["71200.57000000", "0.07009000"], ["71201.01000000", "0.00000000"], ["71201.75000000", "0.00702000"], ["71202.68000000", "0.00000000"], ["71203.08000000", "0.08000000"], ["71203.99000000", "0.00702000"], ["71204.09000000", "0.00000000"], ["71204.17000000", "0.51512000"], ["71204.18000000", "0.00000000"], ["71205.31000000", "0.00000000"], ["71205.96000000", "0.00000000"], ["71205.97000000", "0.00000000"], ["71206.13000000", "0.00000000"], ["71206.31000000", "0.00000000"], ["71206.40000000", "0.00000000"], ["71206.59000000", "0.00000000"], ["71206.77000000", "0.01810000"], ["71207.08000000", "0.00140000"], ["71207.53000000", "0.00000000"], ["71207.61000000", "0.00000000"], ["71208.49000000", "0.00000000"], ["71209.21000000", "0.00000000"], ["71209.81000000", "2.53023000"], ["71211.10000000", "0.00200000"], ["71211.40000000", "0.06000000"], ["71211.97000000", "0.52834000"], ["71214.72000000", "0.00000000"], ["71215.23000000", "0.50543000"], ["71216.77000000", "0.00000000"], ["71216.78000000", "0.00000000"], ["71217.54000000", "0.00000000"], ["71218.05000000", "0.46467000"], ["71218.06000000", "0.00000000"], ["71218.07000000", "0.00000000"], ["71218.80000000", "0.00229000"], ["71220.90000000", "0.00200000"], ["71221.16000000", "0.00000000"], ["71221.38000000", "1.26910000"], ["71222.26000000", "0.00000000"], ["71222.48000000", "0.00702000"], ["71222.71000000", "0.00000000"], ["71222.88000000", "0.50537000"], ["71223.14000000", "0.00200000"], ["71224.92000000", "0.00200000"], ["71224.93000000", "0.15128000"], ["71225.18000000", "0.00000000"], ["71225.41000000", "0.00000000"], ["71227.65000000", "0.00000000"], ["71230.49000000", "0.00000000"], ["71231.07000000", "0.00000000"], ["71231.98000000", "0.00351000"], ["71233.08000000", "0.00015000"], ["71235.32000000", "0.00000000"], ["71235.69000000", "0.09437000"], ["71235.77000000", "0.00000000"], ["71236.80000000", "0.00000000"], ["71237.57000000", "0.77653000"], ["71241.70000000", "0.00000000"], ["71241.80000000", "0.00000000"], ["71243.55000000", "0.05581000"], ["71245.83000000", "2.53023000"], ["71247.41000000", "0.00000000"], ["71247.97000000", "0.00000000"], ["71249.56000000", "0.00000000"], ["71250.01000000", "0.00000000"], ["71250.06000000", "0.00000000"], ["71251.04000000", "0.00000000"], ["71253.13000000", "1.12399000"], ["71253.27000000", "0.00702000"], ["71255.76000000", "0.00000000"], ["71257.28000000", "0.53377000"], ["71260.26000000", "0.00000000"], ["71267.09000000", "0.70147000"], ["71276.01000000", "0.14958000"], ["71286.98000000", "0.54644000"], ["71289.39000000", "0.00000000"], ["71303.53000000", "0.00140000"], ["71307.47000000", "0.05818000"], ["71311.09000000", "0.84595000"], ["71311.17000000", "0.00000000"], ["71317.91000000", "0.52473000"], ["71317.92000000", "1.40196000"], ["71319.72000000", "0.00000000"], ["71326.26000000", "0.19744000"], ["71329.78000000", "0.00000000"], ["71366.38000000", "0.21642000"], ["71372.10000000", "0.00000000"], ["71405.88000000", "0.00399000"]]}
{"e": "aggTrade", "E": 1773437547853, "s": "BTCUSDT", "a": 3904057770, "p": "71188.56000000", "q": "0.01474000", "f": 6104984000, "l": 6104984000, "T": 1773437547853, "m": true, "M": true}
{"e": "depthUpdate", "E": 1773437547914, "s": "BTCUSDT", "U": 90101513794, "u": 90101513907, "b": [["71188.56000000", "5.93293000"], ["71187.39000000", "0.00008000"], ["71187.37000000", "0.40722000"], ["71185.00000000", "0.84232000"], ["71184.99000000", "0.00356000"], ["71183.22000000", "2.53031000"], ["71183.14000000", "0.00356000"], ["71182.98000000", "0.00364000"], ["71182.69000000", "0.16216000"], ["71181.44000000", "0.00702000"], ["71181.27000000", "0.00000000"], ["71181.11000000", "0.00731000"], ["71181.10000000", "0.00364000"], ["71181.02000000", "0.02590000"], ["71179.88000000", "0.06030000"], ["71179.22000000", "0.00838000"], ["71177.43000000", "0.02008000"], ["71177.08000000", "0.02400000"], ["71176.72000000", "0.02800000"], ["71170.77000000", "0.00140000"], ["71168.99000000", "0.00356000"], ["71163.87000000", "0.00000000"], ["71143.10000000", "0.03086000"], ["71128.56000000", "0.00000000"], ["71128.22000000", "0.48715000"], ["71096.57000000", "0.00000000"], ["71077.38000000", "0.00000000"], ["71016.10000000", "0.08895000"], ["64069.71000000", "0.00036000"], ["64069.00000000", "0.00103000"], ["64061.00000000", "0.00000000"]], "a": [["71188.57000000", "0.40574000"], ["71189.48000000", "0.00016000"], ["71190.08000000", "0.00000000"], ["71190.09000000", "0.00000000"], ["71191.26000000", "0.00016000"], ["71193.76000000", "0.00000000"], ["71193.77000000", "0.00000000"], ["71194.14000000", "0.01038000"], ["71195.99000000", "0.00000000"], ["71196.02000000", "0.00000000"], ["71196.04000000", "0.00000000"], ["71196.07000000", "0.04820000"], ["71196.08000000", "0.07809000"], ["71196.89000000", "0.00000000"], ["71197.11000000", "0.00016000"], ["71197.12000000", "0.02016000"], ["71197.21000000", "0.00016000"], ["71197.22000000", "0.02016000"], ["71197.89000000", "0.00000000"], ["71197.90000000", "0.24516000"], ["71197.91000000", "0.04016000"], ["71199.24000000", "0.00140000"], ["71209.82000000", "0.00000000"], ["71213.05000000", "0.00000000"], ["71215.64000000", "0.37888000"], ["71220.90000000", "0.00000000"], ["71224.37000000", "0.00702000"], ["71227.98000000", "0.00000000"], ["71237.01000000", "0.00434000"], ["71255.94000000", "0.00000000"], ["71260.33000000", "0.00000000"], ["71276.37000000", "0.11966000"], ["71278.54000000", "0.09305000"], ["71289.28000000", "0.04353000"], ["71290.84000000", "0.00000000"], ["71388.70000000", "0.00399000"], ["71395.55000000", "0.00000000"], ["71405.88000000", "0.00000000"]]}
{"e": "aggTrade", "E": 1773437547967, "s": "BTCUSDT", "a": 3904057771, "p": "71188.57000000", "q": "0.00072000", "f": 6104984001, "l": 6104984006, "T": 1773437547966, "m": false, "M": true}
{"e": "aggTrade", "E": 1773437547967, "s": "BTCUSDT", "a": 3904057772, "p": "71188.57000000", "q": "0.00072000", "f": 6104984007, "l": 6104984009, "T": 1773437547966, "m": false, "M": true}
{"e": "depthUpdate", "E": 1773437548014, "s": "BTCUSDT", "U": 90101513908, "u": 90101514125, "b": [["71188.56000000", "5.32603000"], ["71187.39000000", "0.00000000"], ["71187.37000000", "0.10722000"], ["71185.44000000", "0.00029000"], ["71183.57000000", "0.00300000"], ["71183.22000000", "2.53031000"], ["71182.98000000", "0.00356000"], ["71182.97000000", "0.00996000"], ["71182.69000000", "0.16216000"], ["71181.67000000", "0.00000000"], ["71181.44000000", "0.00710000"], ["71181.42000000", "0.00008000"], ["71181.11000000", "0.00731000"], ["71181.10000000", "0.00356000"], ["71181.02000000", "0.02598000"], ["71180.88000000", "0.03000000"], ["71179.88000000", "0.00008000"], ["71179.70000000", "0.02185000"], ["71179.68000000", "0.12000000"], ["71179.55000000", "0.00000000"], ["71178.58000000", "0.00300000"], ["71177.54000000", "0.00356000"], ["71176.28000000", "0.00008000"], ["71176.22000000", "0.14048000"], ["71174.91000000", "0.00008000"], ["71174.84000000", "0.06000000"], ["71173.58000000", "0.00356000"], ["71171.18000000", "0.00000000"], ["71169.20000000", "0.00000000"], ["71166.44000000", "0.00000000"], ["71165.28000000", "0.00140000"], ["71165.08000000", "0.00000000"], ["71164.21000000", "0.00000000"], ["71163.52000000", "0.00000000"], ["71162.59000000", "0.36035000"], ["71161.30000000", "0.00000000"], ["71157.55000000", "0.00170000"], ["71154.79000000", "0.00000000"], ["71133.16000000", "0.00000000"], ["71119.00000000", "1.40588000"], ["71090.59000000", "0.00000000"], ["71086.36000000", "0.08596000"], ["71077.30000000", "0.07296000"], ["71077.28000000", "0.00000000"], ["71061.86000000", "0.00000000"], ["64069.71000000", "0.00072000"], ["56950.85000000", "0.00035000"]], "a": [["71188.57000000", "0.00080000"], ["71188.58000000", "0.00048000"], ["71189.47000000", "0.00008000"], ["71189.48000000", "0.00000000"], ["71190.91000000", "0.00000000"], ["71191.25000000", "0.00000000"], ["71191.26000000", "0.00000000"], ["71194.13000000", "0.00024000"], ["71194.14000000", "0.01038000"], ["71194.20000000", "0.01612000"], ["71194.87000000", "0.00141000"], ["71195.84000000", "0.07393000"], ["71196.05000000", "0.00024000"], ["71196.06000000", "0.00024000"], ["71196.07000000", "0.02505000"], ["71196.08000000", "0.00024000"], ["71197.11000000", "0.00000000"], ["71197.12000000", "0.00016000"], ["71197.21000000", "0.00000000"], ["71197.22000000", "0.00016000"], ["71197.89000000", "0.00008000"], ["71197.91000000", "0.00016000"], ["71197.93000000", "0.00016000"], ["71198.54000000", "0.00300000"], ["71198.97000000", "0.00000000"], ["71199.11000000", "0.00008000"], ["71200.05000000", "0.00000000"], ["71200.16000000", "0.00000000"], ["71200.31000000", "0.05176000"], ["71200.32000000", "0.00000000"], ["71200.40000000", "0.00000000"], ["71200.57000000", "0.00009000"], ["71200.76000000", "0.00000000"], ["71200.83000000", "0.00000000"], ["71200.87000000", "0.00000000"], ["71202.19000000", "0.00000000"], ["71202.28000000", "0.00000000"], ["71202.55000000", "0.00021000"], ["71203.08000000", "0.00000000"], ["71203.53000000", "0.00300000"], ["71206.71000000", "0.02000000"], ["71206.98000000", "0.15000000"], ["71207.78000000", "0.00000000"], ["71208.00000000", "0.05387000"], ["71208.25000000", "0.00000000"], ["71208.98000000", "0.00000000"], ["71211.03000000", "0.00530000"], ["71212.54000000", "0.50579000"], ["71215.23000000", "0.00000000"], ["71218.34000000", "0.00000000"], ["71218.80000000", "0.00029000"], ["71218.82000000", "0.00000000"], ["71219.54000000", "0.14625000"], ["71223.78000000", "0.00000000"], ["71227.21000000", "0.50534000"], ["71236.97000000", "0.00000000"], ["71237.43000000", "0.00131000"], ["71238.17000000", "0.00000000"], ["71241.84000000", "0.00021000"], ["71243.87000000", "0.00000000"], ["71251.20000000", "0.00000000"], ["71251.67000000", "0.00000000"], ["71252.41000000", "0.00000000"], ["71253.61000000", "0.91209000"], ["71260.53000000", "0.00008000"], ["71261.40000000", "0.00008000"], ["71289.28000000", "0.12106000"], ["71320.70000000", "0.04597000"], ["71323.47000000", "0.04597000"], ["71325.94000000", "0.04597000"], ["71328.15000000", "0.04597000"], ["71328.76000000", "0.19953000"], ["71331.38000000", "0.04597000"], ["71333.82000000", "0.04597000"], ["71336.40000000", "0.04597000"], ["71338.65000000", "0.04597000"], ["71340.64000000", "0.04597000"], ["71346.48000000", "0.00000000"], ["71378.13000000", "0.00000000"], ["71395.98000000", "0.08896000"]]}
{"e": "kline", "E": 1773437548015, "s": "BTCUSDT", "k": {"t": 1773437520000, "T": 1773437579999, "s": "BTCUSDT", "i": "1m", "f": 6104983042, "L": 6104984009, "o": "71164.00000000", "c": "71188.57000000", "h": "71188.57000000", "l": "71155.65000000", "v": "12.36599000", "n": 968, "x": false, "q": "879952.55733600", "V": "11.22809000", "Q": "798973.43690640", "B": "0"}}
{"e": "aggTrade", "E": 1773437548022, "s": "BTCUSDT", "a": 3904057773, "p": "71188.57000000", "q": "0.00014000", "f": 6104984010, "l": 6104984011, "T": 1773437548022, "m": false, "M": true}
{"e": "aggTrade", "E": 1773437548061, "s": "BTCUSDT", "a": 3904057774, "p": "71188.57000000", "q": "0.00090000", "f": 6104984012, "l": 6104984023, "T": 1773437548060, "m": false, "M": true}
{"e": "aggTrade", "E": 1773437548061, "s": "BTCUSDT", "a": 3904057775, "p": "71188.58000000", "q": "0.00048000", "f": 6104984024, "l": 6104984029, "T": 1773437548060, "m": false, "M": true}
{"e": "aggTrade", "E": 1773437548063, "s": "BTCUSDT", "a": 3904057776, "p": "71189.38000000", "q": "0.00289000", "f": 6104984030, "l": 6104984036, "T": 1773437548063, "m": false, "M": true}
{"e": "aggTrade", "E": 1773437548063, "s": "BTCUSDT", "a": 3904057777, "p": "71189.39000000", "q": "0.00016000", "f": 6104984037, "l": 6104984038, "T": 1773437548063, "m": false, "M": true}
{"e": "aggTrade", "E": 1773437548063, "s": "BTCUSDT", "a": 3904057778, "p": "71189.47000000", "q": "0.00008000", "f": 6104984039, "l": 6104984039, "T": 1773437548063, "m": false, "M": true}
{"e": "depthUpdate", "E": 1773437548114, "s": "BTCUSDT", "U": 90101514126, "u": 90101514593, "b": [["71189.80000000", "3.06940000"], ["71189.58000000", "2.04816000"], ["71189.47000000", "0.00000000"], ["71189.46000000", "0.00008000"], ["71189.38000000", "0.00021000"], ["71189.37000000", "0.47033000"], ["71189.32000000", "0.00200000"], ["71188.96000000", "0.00000000"], ["71188.87000000", "0.00000000"], ["71188.86000000", "0.27695000"], ["71188.66000000", "0.00000000"], ["71188.57000000", "0.30000000"], ["71188.56000000", "2.87089000"], ["71188.55000000", "0.00000000"], ["71187.56000000", "0.02562000"], ["71187.37000000", "0.01011000"], ["71187.25000000", "0.01555000"], ["71186.55000000", "0.00009000"], ["71185.47000000", "0.02584000"], ["71185.39000000", "0.00141000"], ["71183.22000000", "2.53031000"], ["71182.97000000", "0.01004000"], ["71182.69000000", "0.14606000"], ["71182.68000000", "0.00702000"], ["71181.88000000", "0.50567000"], ["71181.44000000", "0.00000000"], ["71181.11000000", "0.00723000"], ["71181.02000000", "0.00000000"], ["71180.98000000", "0.02000000"], ["71180.47000000", "0.00000000"], ["71179.90000000", "0.00241000"], ["71179.88000000", "0.00000000"], ["71179.20000000", "1.03195000"], ["71179.17000000", "0.00356000"], ["71177.55000000", "0.00000000"], ["71176.71000000", "0.00702000"], ["71176.22000000", "0.00000000"], ["71174.84000000", "0.00000000"], ["71174.47000000", "0.00702000"], ["71173.28000000", "0.00000000"], ["71170.99000000", "0.00000000"], ["71163.26000000", "0.00000000"], ["71160.84000000", "0.00000000"], ["71159.10000000", "0.03500000"], ["71156.29000000", "0.02742000"], ["71152.72000000", "0.01144000"], ["71152.69000000", "0.00000000"], ["71151.45000000", "0.00241000"], ["71144.13000000", "0.00000000"], ["71131.38000000", "0.06271000"], ["71113.13000000", "0.00000000"], ["71106.19000000", "0.04641000"], ["71104.70000000", "0.00189000"], ["71103.26000000", "0.00242000"], ["71102.93000000", "0.05337000"], ["71085.01000000", "0.14730000"], ["71084.01000000", "0.00000000"], ["71078.28000000", "0.04847000"], ["71063.37000000", "0.00000000"], ["71022.59000000", "0.00000000"], ["71004.24000000", "0.00000000"], ["70994.19000000", "0.00000000"], ["70832.62000000", "0.10000000"], ["70811.37000000", "0.18570000"], ["64070.82000000", "0.00018000"], ["64069.71000000", "0.00000000"], ["49832.13000000", "0.00000000"]], "a": [["71188.57000000", "0.00000000"], ["71188.58000000", "0.00000000"], ["71189.38000000", "0.00000000"], ["71189.39000000", "0.00000000"], ["71189.47000000", "0.00000000"], ["71189.59000000", "0.00000000"], ["71189.81000000", "0.00433000"], ["71189.82000000", "0.00048000"], ["71190.75000000", "0.00000000"], ["71193.65000000", "0.00000000"], ["71194.14000000", "0.01038000"], ["71194.19000000", "0.00008000"], ["71194.20000000", "0.00016000"], ["71194.35000000", "0.00000000"], ["71194.87000000", "0.00000000"], ["71195.83000000", "0.00016000"], ["71195.84000000", "0.00016000"], ["71195.97000000", "0.00000000"], ["71196.05000000", "0.00008000"], ["71196.06000000", "0.00008000"], ["71196.07000000", "0.00024000"], ["71196.08000000", "0.00008000"], ["71196.69000000", "0.00000000"], ["71196.88000000", "0.00000000"], ["71197.12000000", "0.00000000"], ["71197.22000000", "0.00000000"], ["71197.89000000", "0.00016000"], ["71197.90000000", "0.00016000"], ["71197.91000000", "0.00000000"], ["71197.93000000", "0.00000000"], ["71198.09000000", "0.00000000"], ["71198.22000000", "0.00000000"], ["71199.11000000", "0.00000000"], ["71199.55000000", "0.00718000"], ["71199.56000000", "0.00031000"], ["71199.98000000", "0.21514000"], ["71199.99000000", "0.10000000"], ["71200.00000000", "0.61847000"], ["71200.31000000", "0.00000000"], ["71202.55000000", "0.00000000"], ["71206.73000000", "0.00008000"], ["71207.91000000", "0.00000000"], ["71208.00000000", "0.00120000"], ["71209.45000000", "0.00000000"], ["71209.81000000", "0.00000000"], ["71210.65000000", "0.00000000"], ["71210.75000000", "0.00000000"], ["71210.79000000", "0.00000000"], ["71211.39000000", "0.00000000"], ["71211.40000000", "0.00000000"], ["71211.47000000", "0.14042000"], ["71211.57000000", "0.03563000"], ["71211.68000000", "0.00140000"], ["71212.54000000", "0.00000000"], ["71215.64000000", "0.00000000"], ["71216.57000000", "0.00000000"], ["71217.04000000", "0.06000000"], ["71217.12000000", "0.37888000"], ["71218.05000000", "0.00000000"], ["71218.93000000", "0.09191000"], ["71218.95000000", "0.00000000"], ["71219.27000000", "0.00141000"], ["71220.00000000", "0.00128000"], ["71221.14000000", "0.00000000"], ["71221.28000000", "0.00000000"], ["71221.34000000", "0.30000000"], ["71221.95000000", "0.00000000"], ["71222.13000000", "0.11642000"], ["71222.48000000", "0.00000000"], ["71223.89000000", "0.00000000"], ["71224.37000000", "0.00000000"], ["71224.62000000", "0.00000000"], ["71224.89000000", "0.00000000"], ["71224.93000000", "0.28266000"], ["71226.70000000", "0.00200000"], ["71226.92000000", "0.00702000"], ["71227.97000000", "0.00702000"], ["71228.48000000", "0.00200000"], ["71230.40000000", "0.00350000"], ["71231.40000000", "0.00000000"], ["71231.85000000", "0.02809000"], ["71233.69000000", "0.00702000"], ["71234.74000000", "0.36742000"], ["71235.85000000", "0.00702000"], ["71238.64000000", "0.00000000"], ["71239.47000000", "0.00000000"], ["71239.91000000", "0.00000000"], ["71240.58000000", "1.68082000"], ["71240.76000000", "0.06405000"], ["71242.70000000", "0.50000000"], ["71245.32000000", "0.00021000"], ["71247.05000000", "0.01144000"], ["71251.04000000", "0.00000000"], ["71252.87000000", "0.00000000"], ["71253.60000000", "1.20150000"], ["71253.80000000", "0.00000000"], ["71254.08000000", "0.00000000"], ["71254.13000000", "0.00000000"], ["71254.82000000", "0.00000000"], ["71255.00000000", "0.07547000"], ["71257.15000000", "0.04854000"], ["71261.46000000", "0.02949000"], ["71264.06000000", "0.70000000"], ["71275.14000000", "0.70140000"], ["71287.00000000", "0.02949000"], ["71287.98000000", "0.00000000"], ["71295.22000000", "0.05898000"], ["71302.49000000", "0.00140000"], ["71319.73000000", "0.00000000"], ["71341.36000000", "0.00000000"], ["71341.79000000", "0.00000000"], ["71347.84000000", "0.00000000"], ["71388.70000000", "0.00000000"], ["71403.11000000", "0.00399000"]]}
{"e": "aggTrade", "E": 1773437548144, "s": "BTCUSDT", "a": 3904057779, "p": "71189.81000000", "q": "0.00425000", "f": 6104984040, "l": 6104984048, "T": 1773437548144, "m": false, "M": true}
{"e": "aggTrade", "E": 1773437548144, "s": "BTCUSDT", "a": 3904057780, "p": "71189.82000000", "q": "0.00040000", "f": 6104984049, "l": 6104984053, "T": 1773437548144, "m": false, "M": true}
{"e": "aggTrade", "E": 1773437548144, "s": "BTCUSDT", "a": 3904057781, "p": "71190.00000000", "q": "0.00040000", "f": 6104984054, "l": 6104984054, "T": 1773437548144, "m": false, "M": true}
{"e": "aggTrade", "E": 1773437548144, "s": "BTCUSDT", "a": 3904057782, "p": "71190.21000000", "q": "0.00008000", "f": 6104984055, "l": 6104984055, "T": 1773437548144, "m": false, "M": true}
{"e": "aggTrade", "E": 1773437548144, "s": "BTCUSDT", "a": 3904057783, "p": "71191.80000000", "q": "0.00119000", "f": 6104984056, "l": 6104984056, "T": 1773437548144, "m": false, "M": true}
{"e": "depthUpdate", "E": 1773437548214, "s": "BTCUSDT", "U": 90101514594, "u": 90101514913, "b": [["71191.79000000", "4.08283000"], ["71191.78000000", "0.00008000"], ["71191.10000000", "0.00200000"], ["71190.20000000", "0.00000000"], ["71189.99000000", "0.00000000"], ["71189.90000000", "0.00000000"], ["71189.82000000", "0.61838000"], ["71189.81000000", "0.00021000"], ["71189.80000000", "0.06643000"], ["71189.79000000", "0.00000000"], ["71189.70000000", "0.01562000"], ["71189.59000000", "0.00000000"], ["71189.58000000", "0.05363000"], ["71189.46000000", "0.00000000"], ["71189.38000000", "0.00000000"], ["71189.37000000", "0.00364000"], ["71188.86000000", "0.27695000"], ["71188.58000000", "0.51969000"], ["71188.57000000", "0.30008000"], ["71188.56000000", "2.53387000"], ["71187.56000000", "0.02570000"], ["71187.37000000", "0.01011000"], ["71187.25000000", "0.01555000"], ["71185.47000000", "0.00000000"], ["71185.02000000", "1.31135000"], ["71185.01000000", "1.68082000"], ["71185.00000000", "0.00000000"], ["71183.22000000", "2.53023000"], ["71182.97000000", "0.00996000"], ["71182.76000000", "0.00011000"], ["71182.70000000", "0.00480000"], ["71182.69000000", "0.14598000"], ["71182.68000000", "0.00000000"], ["71179.54000000", "0.00009000"], ["71178.43000000", "0.14047000"], ["71178.08000000", "0.02800000"], ["71174.46000000", "0.16782000"], ["71170.77000000", "0.00000000"], ["71162.62000000", "0.00000000"], ["71162.59000000", "0.00356000"], ["71131.59000000", "0.01076000"], ["71120.00000000", "0.00614000"], ["71117.47000000", "0.00000000"], ["71116.28000000", "0.00000000"], ["71113.28000000", "0.48726000"], ["71111.62000000", "0.00350000"], ["71104.84000000", "0.00000000"], ["71103.75000000", "0.04970000"], ["71102.92000000", "0.00000000"], ["71090.26000000", "0.00000000"], ["71085.02000000", "0.09783000"], ["71085.01000000", "0.08896000"], ["71078.28000000", "0.01372000"], ["71063.92000000", "0.00000000"], ["70700.00000000", "0.65713000"], ["68280.80000000", "0.07027000"], ["68266.55000000", "0.00000000"], ["64072.62000000", "0.00018000"], ["64070.82000000", "0.00000000"], ["56950.85000000", "0.00000000"], ["49833.38000000", "0.00000000"]], "a": [["71189.81000000", "0.00000000"], ["71189.82000000", "0.00000000"], ["71190.00000000", "0.00000000"], ["71190.21000000", "0.00000000"], ["71191.80000000", "0.00427000"], ["71191.81000000", "0.00056000"], ["71192.72000000", "0.00114000"], ["71193.54000000", "0.00000000"], ["71194.14000000", "0.01038000"], ["71194.19000000", "0.00000000"], ["71194.20000000", "0.00000000"], ["71195.15000000", "0.00008000"], ["71195.64000000", "0.00000000"], ["71195.83000000", "0.00000000"], ["71195.84000000", "0.00000000"], ["71196.07000000", "0.00008000"], ["71196.40000000", "0.00029000"], ["71197.21000000", "0.00024000"], ["71197.22000000", "0.08891000"], ["71197.89000000", "0.00000000"], ["71197.90000000", "0.00000000"], ["71198.16000000", "0.00000000"], ["71198.83000000", "0.00000000"], ["71199.55000000", "0.00016000"], ["71199.57000000", "0.08128000"], ["71199.79000000", "0.00000000"], ["71199.94000000", "0.01590000"], ["71199.97000000", "0.00016000"], ["71199.98000000", "0.21538000"], ["71199.99000000", "0.10016000"], ["71200.00000000", "0.61863000"], ["71200.41000000", "0.00000000"], ["71200.57000000", "0.00000000"], ["71200.92000000", "0.00000000"], ["71201.58000000", "0.00000000"], ["71201.75000000", "0.00000000"], ["71201.78000000", "0.02759000"], ["71202.46000000", "0.00000000"], ["71203.52000000", "0.00702000"], ["71203.99000000", "0.00000000"], ["71206.98000000", "0.07000000"], ["71207.52000000", "0.00000000"], ["71207.99000000", "0.00702000"], ["71209.47000000", "0.02689000"], ["71209.48000000", "0.08000000"], ["71211.47000000", "0.00000000"], ["71211.57000000", "0.00000000"], ["71211.97000000", "0.10701000"], ["71211.98000000", "0.00000000"], ["71212.14000000", "0.00000000"], ["71214.18000000", "0.42131000"], ["71214.84000000", "0.00000000"], ["71217.12000000", "0.00000000"], ["71218.93000000", "0.17013000"], ["71220.06000000", "0.04891000"], ["71220.10000000", "0.00000000"], ["71222.13000000", "0.00000000"], ["71222.70000000", "0.00000000"], ["71223.54000000", "0.37888000"], ["71224.68000000", "0.00702000"], ["71225.86000000", "0.00000000"], ["71226.88000000", "0.00000000"], ["71226.92000000", "0.00000000"], ["71227.31000000", "0.00241000"], ["71232.73000000", "0.00702000"], ["71240.00000000", "0.48759000"], ["71240.76000000", "0.00000000"], ["71241.33000000", "0.00000000"], ["71250.74000000", "0.01466000"], ["71254.70000000", "0.02000000"], ["71255.00000000", "0.00000000"], ["71255.57000000", "0.00000000"], ["71260.00000000", "0.00120000"], ["71268.30000000", "0.11840000"], ["71289.28000000", "0.00000000"], ["71295.18000000", "0.12105000"], ["71333.90000000", "0.17390000"], ["71352.93000000", "0.08996000"], ["71376.01000000", "0.00000000"], ["71376.58000000", "0.00000000"], ["71377.56000000", "0.00000000"], ["71377.72000000", "0.00000000"], ["71384.56000000", "0.00000000"], ["71393.30000000", "0.00399000"], ["71396.20000000", "0.08896000"], ["71398.07000000", "0.08896000"], ["71398.60000000", "0.17792000"], ["71403.11000000", "0.00000000"], ["71680.00000000", "0.01060000"]]}
{"e": "depthUpdate", "E": 1773437548314, "s": "BTCUSDT", "U": 90101514914, "u": 90101515018, "b": [["71191.79000000", "4.11298000"], ["71189.82000000", "0.04124000"], ["71189.80000000", "0.03643000"], ["71189.70000000", "0.01570000"], ["71189.58000000", "0.05363000"], ["71189.37000000", "0.00356000"], ["71188.86000000", "0.27695000"], ["71188.58000000", "0.51977000"], ["71188.57000000", "0.00008000"], ["71187.56000000", "0.02562000"], ["71187.37000000", "0.01003000"], ["71184.67000000", "0.00702000"], ["71182.69000000", "0.14583000"], ["71177.46000000", "0.05400000"], ["71177.43000000", "0.08008000"], ["71175.33000000", "0.02400000"], ["71174.53000000", "0.03400000"], ["71170.43000000", "0.00014000"], ["71167.19000000", "0.00000000"], ["71164.25000000", "0.00000000"], ["71159.93000000", "0.07759000"], ["71158.50000000", "0.14637000"], ["71154.61000000", "0.00000000"], ["71149.85000000", "0.00000000"], ["71149.07000000", "0.00014000"], ["71146.15000000", "0.00431000"], ["71141.81000000", "0.02800000"], ["71138.87000000", "0.03400000"], ["71136.14000000", "0.00015000"], ["71133.25000000", "0.00000000"], ["71130.40000000", "0.01734000"], ["71127.72000000", "0.00014000"], ["71113.34000000", "0.00000000"], ["71111.90000000", "0.00000000"], ["71106.36000000", "0.00014000"], ["71090.55000000", "0.00000000"], ["71085.00000000", "0.02014000"], ["71078.28000000", "0.04425000"], ["71074.22000000", "0.10795000"], ["71069.20000000", "0.00000000"], ["70179.18000000", "0.00000000"], ["64072.62000000", "0.00036000"]], "a": [["71194.14000000", "0.01038000"], ["71197.22000000", "0.08907000"], ["71197.32000000", "0.00000000"], ["71199.55000000", "0.00000000"], ["71199.57000000", "0.08128000"], ["71199.93000000", "0.00016000"], ["71199.94000000", "0.01606000"], ["71199.98000000", "0.21522000"], ["71200.00000000", "0.61863000"], ["71201.31000000", "0.00141000"], ["71201.78000000", "0.02775000"], ["71209.96000000", "0.02000000"], ["71213.16000000", "0.00064000"], ["71218.68000000", "0.00000000"], ["71218.91000000", "0.30381000"], ["71218.92000000", "0.50579000"], ["71218.93000000", "0.00000000"], ["71219.54000000", "0.00000000"], ["71227.89000000", "0.00000000"], ["71234.52000000", "0.00014000"], ["71240.03000000", "0.00000000"], ["71253.66000000", "0.00000000"], ["71254.59000000", "0.02000000"], ["71255.30000000", "0.02000000"], ["71255.41000000", "0.02000000"], ["71255.87000000", "0.00014000"], ["71261.38000000", "0.00000000"], ["71265.96000000", "0.05398000"], ["71268.48000000", "0.02000000"], ["71277.23000000", "0.00014000"], ["71282.73000000", "0.00000000"], ["71298.59000000", "0.00014000"], ["71368.13000000", "0.03998000"], ["71369.05000000", "0.03998000"], ["71385.69000000", "0.00399000"], ["71393.30000000", "0.00000000"]]}
{"e": "depthUpdate", "E": 1773437548414, "s": "BTCUSDT", "U": 90101515019, "u": 90101515058, "b": [["71191.79000000", "4.11313000"], ["71188.58000000", "0.51977000"], ["71188.57000000", "0.00000000"], ["71187.56000000", "0.02570000"], ["71181.48000000", "0.00008000"], ["71168.64000000", "0.37365000"], ["71167.18000000", "0.00000000"], ["71165.05000000", "0.00000000"], ["71164.85000000", "0.00000000"], ["71161.34000000", "0.00000000"], ["71156.91000000", "0.00000000"], ["71125.59000000", "0.23511000"], ["71112.75000000", "0.00000000"], ["71105.45000000", "0.00010000"], ["71084.77000000", "0.08896000"], ["71074.96000000", "0.00000000"], ["71074.22000000", "1.09696000"], ["70994.24000000", "0.00000000"], ["69895.62000000", "0.00030000"], ["64072.62000000", "0.00072000"]], "a": [["71204.05000000", "0.00000000"], ["71223.08000000", "0.00000000"], ["71223.56000000", "0.00000000"], ["71252.48000000", "0.02000000"], ["71252.98000000", "0.00000000"], ["71268.48000000", "0.00000000"], ["71286.86000000", "0.00000000"], ["71300.88000000", "0.02199000"], ["71314.79000000", "0.00008000"], ["71379.81000000", "0.00399000"], ["71385.69000000", "0.00000000"]]}
{"e": "depthUpdate", "E": 1773437548514, "s": "BTCUSDT", "U": 90101515059, "u": 90101515082, "b": [["71189.82000000", "0.00008000"], ["71189.81000000", "0.03594000"], ["71189.34000000", "0.00839000"], ["71180.68000000", "0.03200000"], ["71179.69000000", "0.42131000"], ["71179.22000000", "0.00000000"], ["71175.98000000", "0.19437000"], ["71125.59000000", "0.00000000"], ["69763.85000000", "0.00000000"], ["64072.62000000", "0.00090000"], ["56953.44000000", "0.00035000"]], "a": [["71201.31000000", "0.00000000"], ["71220.28000000", "0.00702000"], ["71223.56000000", "0.00000000"], ["71223.57000000", "0.00562000"], ["71223.84000000", "0.00000000"], ["71224.39000000", "0.11640000"], ["71251.45000000", "0.02000000"], ["71253.39000000", "0.00000000"], ["71262.37000000", "0.48624000"]]}
{"e": "depthUpdate", "E": 1773437548614, "s": "BTCUSDT", "U": 90101515083, "u": 90101515134, "b": [["71191.79000000", "4.11313000"], ["71190.90000000", "0.00008000"], ["71189.82000000", "0.00000000"], ["71189.81000000", "0.03602000"], ["71189.58000000", "0.05363000"], ["71189.34000000", "0.00847000"], ["71187.56000000", "0.00000000"], ["71187.25000000", "0.00000000"], ["71181.40000000", "0.02400000"], ["71180.69000000", "0.02400000"], ["71178.16000000", "0.41442000"], ["71131.38000000", "0.00000000"], ["71130.05000000", "0.00000000"], ["71129.84000000", "0.00057000"], ["71120.24000000", "0.00000000"], ["71114.33000000", "0.00000000"], ["71113.62000000", "0.02400000"], ["71105.50000000", "0.06260000"], ["71105.49000000", "0.00000000"], ["71092.45000000", "0.00000000"], ["71083.43000000", "0.07883000"], ["71027.29000000", "0.00862000"], ["71013.41000000", "0.00000000"], ["64072.62000000", "0.00126000"], ["56953.44000000", "0.00000000"]], "a": [["71196.40000000", "0.00000000"], ["71199.68000000", "0.00141000"], ["71199.94000000", "0.00016000"], ["71201.78000000", "0.00216000"], ["71206.98000000", "0.03000000"], ["71209.48000000", "0.12000000"], ["71215.32000000", "0.00000000"], ["71216.68000000", "0.14041000"], ["71217.40000000", "0.14041000"], ["71223.57000000", "0.00000000"], ["71224.39000000", "0.00000000"], ["71226.94000000", "0.11640000"], ["71250.73000000", "0.02000000"], ["71251.44000000", "0.02000000"], ["71253.94000000", "0.00000000"], ["71257.25000000", "0.02950000"], ["71271.03000000", "0.00000000"], ["71293.10000000", "0.00000000"]]}
{"e": "depthUpdate", "E": 1773437548714, "s": "BTCUSDT", "U": 90101515135, "u": 90101515182, "b": [["71191.79000000", "4.15718000"], ["71188.56000000", "2.53387000"], ["71184.35000000", "0.00008000"], ["71181.50000000", "0.02200000"], ["71178.30000000", "0.02200000"], ["71113.62000000", "0.00000000"], ["71096.01000000", "0.09854000"], ["71095.42000000", "0.00009000"], ["71085.02000000", "0.13545000"], ["64072.62000000", "0.00144000"]], "a": [["71195.40000000", "0.00029000"], ["71196.08000000", "0.00000000"], ["71199.57000000", "0.08128000"], ["71199.93000000", "0.00000000"], ["71199.94000000", "0.00000000"], ["71199.98000000", "0.21530000"], ["71200.00000000", "0.61863000"], ["71200.31000000", "0.01845000"], ["71200.32000000", "0.01572000"], ["71201.78000000", "0.00200000"], ["71202.10000000", "0.02539000"], ["71209.47000000", "0.04137000"], ["71224.48000000", "0.00141000"], ["71224.68000000", "0.00000000"], ["71226.68000000", "0.00702000"], ["71250.63000000", "0.02000000"], ["71253.84000000", "0.02000000"], ["71257.25000000", "0.02950000"], ["71263.46000000", "0.00008000"], ["71365.15000000", "0.02809000"], ["71374.36000000", "0.02809000"], ["71382.81000000", "0.04198000"], ["71383.99000000", "0.04198000"]]}
{"e": "depthUpdate", "E": 1773437548814, "s": "BTCUSDT", "U": 90101515183, "u": 90101515195, "b": [["71114.46000000", "0.00000000"], ["71111.26000000", "0.00000000"], ["64072.62000000", "0.00180000"]], "a": [["71200.00000000", "0.61863000"], ["71200.31000000", "0.01861000"], ["71200.32000000", "0.01588000"], ["71202.10000000", "0.02547000"]]}
{"e": "depthUpdate", "E": 1773437548914, "s": "BTCUSDT", "U": 90101515196, "u": 90101515200, "b": [["71166.48000000", "0.00150000"], ["64072.62000000", "0.00198000"], ["56953.00000000", "0.00400000"]], "a": [["71255.68000000", "0.02000000"], ["71256.03000000", "0.02000000"]]}
{"e": "aggTrade", "E": 1773437548997, "s": "BTCUSDT", "a": 3904057784, "p": "71191.79000000", "q": "0.14053000", "f": 6104984057, "l": 6104984057, "T": 1773437548997, "m": true, "M": true}
{"e": "depthUpdate", "E": 1773437549014, "s": "BTCUSDT", "U": 90101515201, "u": 90101515218, "b": [["71191.79000000", "4.01665000"], ["71184.67000000", "0.00000000"], ["71176.84000000", "0.00300000"], ["71170.96000000", "0.00029000"], ["64072.62000000", "0.00216000"], ["64072.00000000", "0.00046000"], ["64071.00000000", "1.80417000"], ["64069.00000000", "0.00093000"], ["56953.44000000", "0.00035000"], ["56953.00000000", "0.00000000"]], "a": [["71199.68000000", "0.00000000"], ["71223.64000000", "0.00000000"], ["71234.82000000", "0.26538000"], ["71343.78000000", "0.04598000"]]}
{"e": "depthUpdate", "E": 1773437549114, "s": "BTCUSDT", "U": 90101515219, "u": 90101515279, "b": [["71191.79000000", "4.01796000"], ["71184.67000000", "0.00702000"], ["71177.55000000", "0.00000000"], ["71159.29000000", "0.00000000"], ["71139.51000000", "0.02950000"], ["71080.76000000", "0.00000000"], ["71078.51000000", "0.00000000"], ["71077.30000000", "0.00000000"], ["71068.46000000", "0.24219000"], ["71018.42000000", "0.00000000"], ["71017.57000000", "0.00000000"], ["71015.25000000", "0.00000000"], ["71013.40000000", "0.00000000"], ["71012.72000000", "0.00000000"], ["71011.10000000", "0.00000000"], ["71010.50000000", "0.00000000"], ["71009.71000000", "0.00000000"], ["71009.62000000", "0.00000000"], ["71008.82000000", "0.08896000"], ["71008.78000000", "0.00000000"], ["71007.96000000", "0.00000000"], ["71005.97000000", "0.00000000"], ["71004.60000000", "0.00000000"], ["71002.76000000", "0.00000000"], ["71002.64000000", "0.00000000"], ["71001.60000000", "0.00000000"], ["71000.51000000", "0.00000000"], ["71000.39000000", "0.00000000"], ["70999.98000000", "0.00000000"], ["70999.88000000", "0.00000000"], ["70999.30000000", "0.00000000"], ["70998.98000000", "0.00000000"], ["70998.47000000", "0.00000000"], ["70997.03000000", "0.00000000"], ["70996.47000000", "0.00000000"], ["70995.34000000", "0.00000000"], ["70994.58000000", "0.00000000"], ["70994.11000000", "0.00000000"], ["70993.06000000", "0.00000000"], ["70991.42000000", "0.00000000"], ["70989.07000000", "0.00000000"], ["70987.64000000", "0.00000000"], ["65496.45000000", "0.00016000"], ["64072.62000000", "0.00252000"], ["42715.08000000", "0.00015000"]], "a": [["71192.31000000", "0.00008000"], ["71199.38000000", "0.00141000"], ["71215.39000000", "0.03478000"], ["71223.64000000", "0.00000000"], ["71271.09000000", "0.06453000"], ["71293.16000000", "0.07873000"], ["71309.38000000", "0.24182000"]]}
{"e": "aggTrade", "E": 1773437549125, "s": "BTCUSDT", "a": 3904057785, "p": "71191.80000000", "q": "0.00427000", "f": 6104984058, "l": 6104984066, "T": 1773437549124, "m": false, "M": true}
{"e": "aggTrade", "E": 1773437549125, "s": "BTCUSDT", "a": 3904057786, "p": "71191.81000000", "q": "0.00056000", "f": 6104984067, "l": 6104984073, "T": 1773437549124, "m": false, "M": true}
{"e": "aggTrade", "E": 1773437549125, "s": "BTCUSDT", "a": 3904057787, "p": "71192.00000000", "q": "0.00040000", "f": 6104984074, "l": 6104984074, "T": 1773437549124, "m": false, "M": true}
{"e": "aggTrade", "E": 1773437549125, "s": "BTCUSDT", "a": 3904057788, "p": "71192.24000000", "q": "0.00008000", "f": 6104984075, "l": 6104984075, "T": 1773437549124, "m": false, "M": true}
{"e": "aggTrade", "E": 1773437549125, "s": "BTCUSDT", "a": 3904057789, "p": "71192.31000000", "q": "0.00008000", "f": 6104984076, "l": 6104984076, "T": 1773437549124, "m": false, "M": true}
{"e": "aggTrade", "E": 1773437549125, "s": "BTCUSDT", "a": 3904057790, "p": "71192.50000000", "q": "0.00300000", "f": 6104984077, "l": 6104984077, "T": 1773437549124, "m": false, "M": true}
{"e": "aggTrade", "E": 1773437549125, "s": "BTCUSDT", "a": 3904057791, "p": "71192.72000000", "q": "0.00114000", "f": 6104984078, "l": 6104984078, "T": 1773437549124, "m": false, "M": true}
{"e": "aggTrade", "E": 1773437549125, "s": "BTCUSDT", "a": 3904057792, "p": "71193.14000000", "q": "0.00008000", "f": 6104984079, "l": 6104984079, "T": 1773437549124, "m": false, "M": true}
{"e": "aggTrade", "E": 1773437549125, "s": "BTCUSDT", "a": 3904057793, "p": "71194.00000000", "q": "0.00080000", "f": 6104984080, "l": 6104984081, "T": 1773437549124, "m": false, "M": true}
{"e": "aggTrade", "E": 1773437549125, "s": "BTCUSDT", "a": 3904057794, "p": "71194.13000000", "q": "0.00032000", "f": 6104984082, "l": 6104984085, "T": 1773437549124, "m": false, "M": true}
{"e": "aggTrade", "E": 1773437549125, "s": "BTCUSDT", "a": 3904057795, "p": "71194.14000000", "q": "0.00021000", "f": 6104984086, "l": 6104984086, "T": 1773437549124, "m": false, "M": true}
{"e": "depthUpdate", "E": 1773437549214, "s": "BTCUSDT", "U": 90101515280, "u": 90101515513, "b": [["71194.13000000", "2.75964000"], ["71194.12000000", "0.00008000"], ["71192.88000000", "0.00200000"], ["71192.49000000", "0.17707000"], ["71192.30000000", "0.00000000"], ["71192.23000000", "0.00000000"], ["71191.99000000", "0.00000000"], ["71191.81000000", "1.17490000"], ["71191.80000000", "2.79553000"], ["71191.79000000", "0.37648000"], ["71191.78000000", "0.00000000"], ["71189.81000000", "0.00029000"], ["71189.58000000", "0.00008000"], ["71188.56000000", "2.53379000"], ["71185.45000000", "0.06591000"], ["71184.67000000", "0.00000000"], ["71183.46000000", "0.00140000"], ["71181.60000000", "0.00008000"], ["71181.17000000", "0.02800000"], ["71178.43000000", "0.00000000"], ["71164.40000000", "0.00000000"], ["71163.28000000", "0.00021000"], ["71159.93000000", "0.05582000"], ["71157.80000000", "0.00000000"], ["71152.73000000", "0.00011000"], ["71140.34000000", "0.00000000"], ["71113.33000000", "0.02878000"], ["71101.80000000", "0.00000000"], ["71081.74000000", "0.02656000"], ["70194.13000000", "0.00040000"], ["64074.72000000", "0.00018000"], ["64072.62000000", "0.00000000"], ["56953.44000000", "0.00000000"], ["49835.87000000", "0.00000000"], ["49834.63000000", "0.00000000"]], "a": [["71191.80000000", "0.00000000"], ["71191.81000000", "0.00000000"], ["71192.00000000", "0.00000000"], ["71192.24000000", "0.00000000"], ["71192.31000000", "0.00000000"], ["71192.50000000", "0.00000000"], ["71192.72000000", "0.00000000"], ["71193.14000000", "0.00000000"], ["71194.00000000", "0.00000000"], ["71194.13000000", "0.00000000"], ["71194.14000000", "0.41611000"], ["71194.15000000", "0.00080000"], ["71195.15000000", "0.00000000"], ["71195.40000000", "0.00000000"], ["71196.58000000", "0.00008000"], ["71197.21000000", "0.00008000"], ["71197.22000000", "0.00016000"], ["71199.24000000", "0.00000000"], ["71199.38000000", "0.00000000"], ["71199.56000000", "0.00039000"], ["71199.98000000", "0.21538000"], ["71199.99000000", "0.10032000"], ["71200.32000000", "0.00016000"], ["71201.75000000", "0.08332000"], ["71202.10000000", "0.00016000"], ["71204.16000000", "0.00008000"], ["71215.39000000", "0.00000000"], ["71216.68000000", "0.00000000"], ["71217.96000000", "0.14041000"], ["71220.28000000", "0.00000000"], ["71223.64000000", "0.00562000"], ["71226.94000000", "0.00000000"], ["71231.98000000", "0.00000000"], ["71234.74000000", "0.00000000"], ["71239.45000000", "0.00348000"], ["71254.59000000", "0.04000000"], ["71271.09000000", "0.00000000"], ["71293.16000000", "0.00000000"], ["71300.88000000", "0.00000000"], ["71307.47000000", "0.05818000"], ["71309.38000000", "0.00000000"], ["71333.78000000", "0.09191000"], ["71377.48000000", "0.00000000"], ["71379.81000000", "0.00000000"], ["71398.33000000", "0.00399000"]]}
{"e": "depthUpdate", "E": 1773437549314, "s": "BTCUSDT", "U": 90101515514, "u": 90101515579, "b": [["71194.13000000", "2.78972000"], ["71192.49000000", "0.17715000"], ["71191.81000000", "0.85503000"], ["71191.80000000", "2.79561000"], ["71191.79000000", "0.04640000"], ["71189.81000000", "0.00021000"], ["71189.70000000", "0.01562000"], ["71189.58000000", "0.00000000"], ["71188.86000000", "0.00364000"], ["71188.58000000", "0.51969000"], ["71179.90000000", "0.00000000"], ["71170.42000000", "0.00000000"], ["71160.94000000", "0.00000000"], ["71151.45000000", "0.00000000"], ["71141.97000000", "0.00000000"], ["71132.49000000", "0.00000000"], ["71123.01000000", "0.02669000"], ["71113.53000000", "0.00000000"], ["71112.74000000", "0.02600000"], ["71104.05000000", "0.00000000"], ["71094.56000000", "0.00000000"], ["71086.60000000", "0.10000000"], ["71085.08000000", "0.00000000"], ["64074.72000000", "0.00036000"]], "a": [["71194.14000000", "0.41587000"], ["71194.15000000", "0.00080000"], ["71197.21000000", "0.00000000"], ["71197.22000000", "0.00000000"], ["71198.86000000", "0.00000000"], ["71199.22000000", "0.00141000"], ["71199.97000000", "0.00024000"], ["71200.31000000", "0.00016000"], ["71200.32000000", "0.00000000"], ["71201.74000000", "0.02966000"], ["71201.75000000", "0.08348000"], ["71202.10000000", "0.00000000"], ["71203.52000000", "0.00718000"], ["71204.17000000", "0.51528000"], ["71208.35000000", "0.00000000"], ["71212.06000000", "0.00008000"], ["71217.83000000", "0.00000000"], ["71223.64000000", "0.00000000"], ["71224.61000000", "0.00000000"], ["71227.31000000", "0.00000000"], ["71236.79000000", "0.00000000"], ["71246.27000000", "0.00000000"], ["71247.82000000", "0.00868000"], ["71255.75000000", "0.00000000"], ["71265.24000000", "0.00000000"], ["71274.72000000", "0.00000000"], ["71284.58000000", "0.10000000"], ["71333.78000000", "0.06595000"], ["71333.90000000", "0.08695000"], ["71352.78000000", "0.09095000"]]}
{"e": "depthUpdate", "E": 1773437549414, "s": "BTCUSDT", "U": 90101515580, "u": 90101515609, "b": [["71191.79000000", "0.04648000"], ["71189.70000000", "0.01570000"], ["71189.34000000", "0.00839000"], ["71188.86000000", "0.00356000"], ["71187.28000000", "0.00008000"], ["71185.54000000", "0.00008000"], ["71167.54000000", "0.00000000"], ["71096.45000000", "0.00000000"], ["71067.02000000", "0.00000000"], ["64074.72000000", "0.00054000"]], "a": [["71194.14000000", "0.41579000"], ["71200.00000000", "0.61863000"], ["71200.31000000", "0.00000000"], ["71201.74000000", "0.02982000"], ["71204.81000000", "0.00140000"], ["71219.05000000", "0.02140000"], ["71224.61000000", "0.00000000"], ["71224.62000000", "0.00000000"], ["71266.39000000", "0.00008000"], ["71391.55000000", "0.00399000"], ["71398.33000000", "0.00000000"]]}
{"e": "depthUpdate", "E": 1773437549514, "s": "BTCUSDT", "U": 90101515610, "u": 90101515618, "b": [["71191.81000000", "0.54889000"], ["71179.89000000", "0.00702000"], ["69774.71000000", "0.00008000"], ["64074.72000000", "0.00090000"], ["56955.31000000", "0.00035000"]], "a": [["71222.62000000", "0.00702000"], ["71227.21000000", "0.86307000"]]}
{"e": "depthUpdate", "E": 1773437549614, "s": "BTCUSDT", "U": 90101515619, "u": 90101515626, "b": [["71191.81000000", "0.79869000"], ["65496.45000000", "0.00000000"], ["64074.72000000", "0.00108000"], ["64074.00000000", "0.00780000"], ["56955.31000000", "0.00000000"]], "a": []}
{"e": "depthUpdate", "E": 1773437549714, "s": "BTCUSDT", "U": 90101515627, "u": 90101515654, "b": [["71194.13000000", "2.79128000"], ["71191.79000000", "0.02125000"], ["71190.90000000", "0.00000000"], ["64074.72000000", "0.00144000"]], "a": [["71199.22000000", "0.00000000"], ["71200.49000000", "0.01604000"], ["71202.27000000", "0.02556000"], ["71212.46000000", "0.00200000"], ["71215.78000000", "0.03476000"], ["71217.96000000", "0.00000000"], ["71218.75000000", "0.50540000"], ["71219.27000000", "0.00000000"], ["71224.48000000", "0.00000000"], ["71224.56000000", "0.04215000"], ["71224.93000000", "0.40550000"], ["71227.33000000", "0.11672000"], ["71229.05000000", "0.50533000"], ["71249.00000000", "0.00000000"], ["71271.48000000", "0.06406000"], ["71293.55000000", "0.07582000"]]}
{"e": "depthUpdate", "E": 1773437549814, "s": "BTCUSDT", "U": 90101515655, "u": 90101515684, "b": [["71194.13000000", "2.69448000"], ["71181.88000000", "0.00000000"], ["71160.47000000", "0.50582000"], ["64074.72000000", "0.00180000"]], "a": [["71196.46000000", "0.00029000"], ["71199.16000000", "0.00141000"], ["71200.00000000", "0.61863000"], ["71200.49000000", "0.01620000"], ["71201.75000000", "0.08348000"], ["71202.27000000", "0.02572000"], ["71203.52000000", "0.00702000"], ["71204.16000000", "0.00000000"], ["71204.17000000", "0.51512000"], ["71205.32000000", "0.00021000"], ["71206.77000000", "0.00000000"], ["71214.45000000", "0.01810000"], ["71224.56000000", "0.00000000"], ["71231.64000000", "0.50531000"], ["71245.32000000", "0.00000000"]]}
{"e": "depthUpdate", "E": 1773437549914, "s": "BTCUSDT", "U": 90101515685, "u": 90101515703, "b": [["71169.22000000", "0.00140000"], ["71166.00000000", "0.00000000"], ["71163.35000000", "0.00000000"], ["71160.48000000", "0.20796000"], ["71159.93000000", "0.00356000"], ["71026.57000000", "1.06125000"], ["70988.81000000", "0.00000000"], ["64074.72000000", "0.00198000"]], "a": [["71224.52000000", "0.00000000"], ["71226.17000000", "0.00140000"]]}
{"e": "depthUpdate", "E": 1773437550014, "s": "BTCUSDT", "U": 90101515704, "u": 90101515728, "b": [["71189.14000000", "0.00300000"], ["71184.53000000", "0.00423000"], ["71176.84000000", "0.00000000"], ["71166.54000000", "0.50577000"], ["71166.50000000", "0.00140000"], ["71166.48000000", "0.00140000"], ["71003.66000000", "0.00000000"], ["64074.72000000", "0.00216000"], ["56955.31000000", "0.00035000"], ["56955.00000000", "0.00013000"]], "a": [["71194.14000000", "0.43074000"], ["71209.10000000", "0.00300000"], ["71224.52000000", "0.04215000"], ["71370.96000000", "0.00000000"]]}
{"e": "aggTrade", "E": 1773437550025, "s": "BTCUSDT", "a": 3904057796, "p": "71194.13000000", "q": "0.00014000", "f": 6104984087, "l": 6104984087, "T": 1773437550025, "m": true, "M": true}
{"e": "kline", "E": 1773437550025, "s": "BTCUSDT", "k": {"t": 1773437520000, "T": 1773437579999, "s": "BTCUSDT", "i": "1m", "f": 6104983042, "L": 6104984086, "o": "71164.00000000", "c": "71194.14000000", "h": "71194.14000000", "l": "71155.65000000", "v": "12.52843000", "n": 1045, "x": false, "q": "891516.93577000", "V": "11.25000000", "Q": "800533.23309170", "B": "0"}}
{"e": "depthUpdate", "E": 1773437550114, "s": "BTCUSDT", "U": 90101515729, "u": 90101515766, "b": [["71194.13000000", "2.69550000"], ["71189.34000000", "0.00847000"], ["71178.49000000", "0.00008000"], ["71099.38000000", "0.00000000"], ["71036.95000000", "0.07296000"], ["71035.86000000", "0.07296000"], ["71033.09000000", "0.07296000"], ["71031.24000000", "0.07296000"], ["71029.57000000", "0.07296000"], ["71027.88000000", "0.07296000"], ["71026.41000000", "0.07296000"], ["71023.58000000", "0.07296000"], ["71022.40000000", "0.07296000"], ["71019.94000000", "0.07296000"], ["71018.93000000", "0.07296000"], ["71017.21000000", "0.07296000"], ["71016.28000000", "0.07681000"], ["71014.86000000", "0.07296000"], ["71012.85000000", "0.07296000"], ["71009.70000000", "0.07296000"], ["71006.67000000", "0.07296000"], ["71004.01000000", "0.07296000"], ["70668.35000000", "0.00702000"], ["70666.22000000", "0.00702000"], ["70661.24000000", "0.00702000"], ["64074.72000000", "0.00234000"], ["64074.00000000", "0.00800000"], ["64071.00000000", "1.80407000"]], "a": [["71194.14000000", "0.43058000"], ["71196.46000000", "0.00000000"], ["71213.43000000", "0.14041000"], ["71231.18000000", "0.00011000"], ["71234.76000000", "0.00615000"], ["71238.19000000", "0.00011000"]]}
{"e": "depthUpdate", "E": 1773437550214, "s": "BTCUSDT", "U": 90101515767, "u": 90101515801, "b": [["71192.74000000", "0.00141000"], ["71191.80000000", "2.53031000"], ["71175.98000000", "0.26733000"], ["71029.47000000", "0.07296000"], ["71027.85000000", "0.07296000"], ["71027.06000000", "0.07296000"], ["71027.04000000", "0.07296000"], ["71026.17000000", "0.07296000"], ["71023.58000000", "0.14592000"], ["71022.25000000", "0.07296000"], ["71019.84000000", "0.07296000"], ["71018.79000000", "0.07296000"], ["71017.14000000", "0.07296000"], ["71016.28000000", "0.14977000"], ["71014.82000000", "0.07296000"], ["71012.54000000", "0.07296000"], ["71009.66000000", "0.07296000"], ["71006.67000000", "0.14592000"], ["71003.76000000", "0.07296000"], ["70194.13000000", "0.00000000"], ["64074.72000000", "0.00270000"], ["64074.00000000", "0.00800000"], ["56955.31000000", "0.00000000"]], "a": [["71194.14000000", "0.43128000"], ["71199.16000000", "0.00000000"], ["71214.10000000", "0.00000000"], ["71221.22000000", "0.00141000"]]}
{"e": "depthUpdate", "E": 1773437550314, "s": "BTCUSDT", "U": 90101515802, "u": 90101515830, "b": [["71179.20000000", "1.03195000"], ["71179.19000000", "1.72297000"], ["71166.00000000", "0.00040000"], ["71164.00000000", "0.00396000"], ["71162.00000000", "0.00040000"], ["71160.00000000", "0.00048000"], ["71158.00000000", "0.00040000"], ["71156.00000000", "0.00040000"], ["71136.42000000", "0.00000000"], ["71093.77000000", "0.00241000"], ["71026.57000000", "0.00000000"], ["71017.61000000", "6.46906000"], ["64074.72000000", "0.00306000"], ["64074.00000000", "0.00800000"], ["42736.05000000", "0.00030000"], ["42715.18000000", "0.00000000"], ["42707.35000000", "0.00015000"], ["42706.30000000", "0.00015000"], ["42705.15000000", "0.00030000"], ["42699.38000000", "0.00105000"], ["42697.38000000", "0.00000000"], ["42673.85000000", "0.00015000"]], "a": [["71199.12000000", "0.00141000"], ["71204.55000000", "0.00048000"], ["71205.28000000", "0.00190000"], ["71377.56000000", "0.40932000"]]}
{"e": "depthUpdate", "E": 1773437550414, "s": "BTCUSDT", "U": 90101515831, "u": 90101515839, "b": [["71194.13000000", "2.69535000"], ["71178.16000000", "0.00000000"], ["71103.28000000", "0.00241000"], ["64074.72000000", "0.00333000"], ["64074.00000000", "0.00790000"]], "a": [["71194.14000000", "0.45165000"], ["78313.55000000", "0.00008000"]]}
{"e": "depthUpdate", "E": 1773437550514, "s": "BTCUSDT", "U": 90101515840, "u": 90101515852, "b": [["71112.80000000", "0.00241000"], ["69774.71000000", "0.00000000"], ["64074.72000000", "0.00342000"], ["64074.00000000", "0.00790000"], ["56955.31000000", "0.00035000"]], "a": [["71194.14000000", "0.45213000"], ["71200.00000000", "0.62063000"], ["71204.92000000", "0.00048000"], ["71228.48000000", "0.00000000"], ["71649.86000000", "0.00000000"], ["78313.55000000", "0.00000000"]]}
{"e": "depthUpdate", "E": 1773437550614, "s": "BTCUSDT", "U": 90101515853, "u": 90101515863, "b": [["71122.31000000", "0.00241000"], ["64074.72000000", "0.00360000"], ["56955.31000000", "0.00000000"]], "a": [["71199.12000000", "0.00000000"], ["71213.43000000", "0.00000000"], ["71218.74000000", "0.30422000"], ["71218.91000000", "0.00000000"], ["71218.92000000", "0.00000000"], ["71221.48000000", "0.37887000"], ["71223.54000000", "0.00000000"], ["71326.27000000", "0.00000000"]]}
{"e": "depthUpdate", "E": 1773437550714, "s": "BTCUSDT", "U": 90101515864, "u": 90101515874, "b": [["71131.82000000", "0.00241000"], ["71051.21000000", "0.02199000"], ["64074.72000000", "0.00378000"], ["56955.00000000", "0.00013000"]], "a": [["71199.19000000", "0.00141000"], ["71214.23000000", "0.00000000"], ["71216.68000000", "0.50576000"], ["71326.26000000", "0.09561000"]]}
{"e": "depthUpdate", "E": 1773437550814, "s": "BTCUSDT", "U": 90101515875, "u": 90101515882, "b": [["71194.13000000", "2.59824000"], ["71141.33000000", "0.00241000"], ["71021.57000000", "0.08895000"], ["64074.72000000", "0.00396000"]], "a": [["71398.32000000", "0.08995000"]]}
{"e": "depthUpdate", "E": 1773437550914, "s": "BTCUSDT", "U": 90101515883, "u": 90101515887, "b": [["71194.13000000", "2.69535000"], ["71150.85000000", "0.00241000"], ["64074.72000000", "0.00450000"]], "a": []}
{"e": "depthUpdate", "E": 1773437551014, "s": "BTCUSDT", "U": 90101515888, "u": 90101515891, "b": [["71179.19000000", "1.68082000"], ["71160.36000000", "0.00241000"], ["64074.72000000", "0.00468000"], ["56955.31000000", "0.00035000"]], "a": []}
{"e": "aggTrade", "E": 1773437551096, "s": "BTCUSDT", "a": 3904057797, "p": "71194.13000000", "q": "0.04416000", "f": 6104984088, "l": 6104984088, "T": 1773437551096, "m": true, "M": true}
{"e": "depthUpdate", "E": 1773437551114, "s": "BTCUSDT", "U": 90101515892, "u": 90101515936, "b": [["71194.13000000", "2.65119000"], ["71179.05000000", "0.04215000"], ["71175.98000000", "0.19437000"], ["71169.87000000", "0.00241000"], ["71078.28000000", "0.00000000"], ["71036.95000000", "0.00000000"], ["71035.86000000", "0.00000000"], ["71033.09000000", "0.00000000"], ["71031.24000000", "0.00000000"], ["71029.57000000", "0.00000000"], ["71029.47000000", "0.00000000"], ["71027.88000000", "0.00000000"], ["71027.85000000", "0.00000000"], ["71027.06000000", "0.00000000"], ["71027.04000000", "0.00000000"], ["71026.41000000", "0.00000000"], ["71026.17000000", "0.00000000"], ["71023.58000000", "0.00000000"], ["71022.40000000", "0.00000000"], ["71022.25000000", "0.00000000"], ["71019.94000000", "0.00000000"], ["71019.84000000", "0.00000000"], ["71018.93000000", "0.00000000"], ["71018.79000000", "0.00000000"], ["71017.21000000", "0.00000000"], ["71017.14000000", "0.00000000"], ["71016.28000000", "0.00385000"], ["71014.86000000", "0.00000000"], ["71014.82000000", "0.00000000"], ["71012.85000000", "0.00000000"], ["71012.54000000", "0.00000000"], ["71009.70000000", "0.00000000"], ["71009.66000000", "0.00000000"], ["71006.67000000", "0.00000000"], ["71004.01000000", "0.00000000"], ["71003.76000000", "0.00000000"], ["64074.72000000", "0.00486000"], ["64074.00000000", "0.00790000"]], "a": [["71207.46000000", "0.06691000"], ["71213.57000000", "0.14042000"]]}
{"e": "depthUpdate", "E": 1773437551214, "s": "BTCUSDT", "U": 90101515937, "u": 90101515966, "b": [["71194.13000000", "2.65323000"], ["71192.89000000", "0.00702000"], ["71185.77000000", "0.00702000"], ["71181.11000000", "0.00021000"], ["71179.39000000", "0.00241000"], ["71179.21000000", "0.20138000"], ["71177.55000000", "0.00702000"], ["71176.71000000", "0.00000000"], ["71175.98000000", "0.00000000"], ["71174.47000000", "0.00000000"], ["71146.16000000", "0.00011000"], ["71139.29000000", "0.00000000"], ["71114.01000000", "0.00350000"], ["71111.62000000", "0.00000000"], ["71108.08000000", "0.00243000"], ["71103.26000000", "0.00000000"], ["71083.08000000", "0.04847000"], ["71042.91000000", "0.00140000"], ["71036.13000000", "0.00097000"], ["71007.53000000", "0.00000000"], ["71002.01000000", "0.00000000"], ["64074.72000000", "0.00486000"], ["56955.31000000", "0.00000000"]], "a": [["71194.14000000", "0.45230000"], ["71202.87000000", "0.00702000"], ["71203.52000000", "0.00000000"], ["71205.99000000", "0.00702000"], ["71206.70000000", "0.00702000"], ["71207.45000000", "0.06898000"], ["71207.99000000", "0.00000000"], ["71209.47000000", "0.00000000"], ["71211.97000000", "0.00000000"], ["71213.56000000", "0.10701000"], ["71230.40000000", "0.00000000"], ["71234.81000000", "0.00350000"], ["71302.49000000", "0.00000000"], ["71303.53000000", "0.00000000"], ["71307.32000000", "0.00140000"], ["71310.13000000", "0.00140000"]]}
{"e": "depthUpdate", "E": 1773437551314, "s": "BTCUSDT", "U": 90101515967, "u": 90101515979, "b": [["71088.56000000", "0.10000000"], ["71071.29000000", "0.00000000"], ["70194.13000000", "0.00000000"], ["64074.72000000", "0.00486000"]], "a": [["71198.41000000", "0.00241000"], ["71202.27000000", "0.02572000"], ["71202.87000000", "0.00000000"], ["71203.17000000", "0.00702000"], ["71205.99000000", "0.00000000"], ["71206.69000000", "0.00702000"]]}
{"e": "depthUpdate", "E": 1773437551414, "s": "BTCUSDT", "U": 90101515980, "u": 90101515991, "b": [["71194.13000000", "2.75003000"], ["71184.35000000", "0.00018000"], ["71026.57000000", "1.06121000"], ["64074.72000000", "0.00468000"], ["64074.00000000", "0.00790000"]], "a": [["71202.27000000", "0.02572000"]]}
{"e": "depthUpdate", "E": 1773437551514, "s": "BTCUSDT", "U": 90101515992, "u": 90101515999, "b": [["71194.13000000", "2.75020000"], ["69773.25000000", "0.00008000"], ["64074.72000000", "0.00450000"], ["56955.31000000", "0.00035000"]], "a": [["71197.92000000", "0.00020000"], ["71207.93000000", "0.00241000"]]}
{"e": "depthUpdate", "E": 1773437551614, "s": "BTCUSDT", "U": 90101516000, "u": 90101516008, "b": [["71179.05000000", "0.00000000"], ["71050.52000000", "0.00000000"], ["64074.72000000", "0.00468000"], ["56955.31000000", "0.00000000"]], "a": [["71213.70000000", "0.00000000"], ["71217.44000000", "0.00241000"]]}
{"e": "depthUpdate", "E": 1773437551714, "s": "BTCUSDT", "U": 90101516009, "u": 90101516014, "b": [["71083.08000000", "0.04847000"], ["71076.32000000", "1.14564000"], ["64074.72000000", "0.00468000"]], "a": [["71226.95000000", "0.00241000"]]}
{"e": "depthUpdate", "E": 1773437551814, "s": "BTCUSDT", "U": 90101516015, "u": 90101516018, "b": [["71148.00000000", "0.02929000"], ["64074.72000000", "0.00468000"]], "a": [["71236.47000000", "0.00241000"]]}
{"e": "depthUpdate", "E": 1773437551914, "s": "BTCUSDT", "U": 90101516019, "u": 90101516023, "b": [["64074.72000000", "0.00468000"]], "a": [["71245.98000000", "0.00240000"]]}
{"e": "depthUpdate", "E": 1773437552014, "s": "BTCUSDT", "U": 90101516024, "u": 90101516029, "b": [["64074.72000000", "0.00450000"], ["56955.31000000", "0.00035000"]], "a": [["71205.99000000", "0.00702000"], ["71206.69000000", "0.00000000"], ["71255.49000000", "0.00240000"]]}
{"e": "kline", "E": 1773437552021, "s": "BTCUSDT", "k": {"t": 1773437520000, "T": 1773437579999, "s": "BTCUSDT", "i": "1m", "f": 6104983042, "L": 6104984088, "o": "71164.00000000", "c": "71194.13000000", "h": "71194.14000000", "l": "71155.65000000", "v": "12.57273000", "n": 1047, "x": false, "q": "894670.83572900", "V": "11.25000000", "Q": "800533.23309170", "B": "0"}}
{"e": "depthUpdate", "E": 1773437552114, "s": "BTCUSDT", "U": 90101516030, "u": 90101516057, "b": [["71179.71000000", "0.00702000"], ["71179.21000000", "0.19436000"], ["71177.92000000", "0.00702000"], ["71177.55000000", "0.00000000"], ["71002.84000000", "0.07296000"], ["70832.62000000", "0.00000000"], ["70811.37000000", "0.00000000"], ["64074.72000000", "0.00468000"]], "a": [["71194.14000000", "0.45230000"], ["71194.15000000", "0.00072000"], ["71199.98000000", "0.21522000"], ["71199.99000000", "0.00032000"], ["71201.74000000", "0.02990000"], ["71204.16000000", "0.00008000"], ["71204.17000000", "0.02249000"], ["71204.22000000", "0.00000000"], ["71205.99000000", "0.00000000"], ["71206.69000000", "0.00702000"], ["71207.45000000", "0.56051000"], ["71207.80000000", "1.68093000"], ["71218.74000000", "0.21467000"], ["71221.34000000", "0.00000000"], ["71242.70000000", "0.00000000"], ["71264.06000000", "0.00000000"], ["71265.00000000", "0.00240000"]]}
{"e": "depthUpdate", "E": 1773437552214, "s": "BTCUSDT", "U": 90101516058, "u": 90101516105, "b": [["71175.59000000", "0.07668000"], ["71038.07000000", "0.07296000"], ["71036.59000000", "0.07296000"], ["71035.19000000", "0.07296000"], ["71033.05000000", "0.07296000"], ["71031.12000000", "0.07296000"], ["71029.07000000", "0.07296000"], ["71027.79000000", "0.07296000"], ["71027.67000000", "0.07296000"], ["71026.96000000", "0.07296000"], ["71026.85000000", "0.07296000"], ["71025.71000000", "0.07296000"], ["71025.59000000", "0.07296000"], ["71023.49000000", "0.07296000"], ["71023.38000000", "0.07296000"], ["71022.35000000", "0.07296000"], ["71022.24000000", "0.07731000"], ["71019.68000000", "0.07296000"], ["71019.56000000", "0.07296000"], ["71018.33000000", "0.07296000"], ["71018.22000000", "0.07296000"], ["71016.87000000", "0.07296000"], ["71016.75000000", "0.07296000"], ["71015.99000000", "0.07296000"], ["71015.88000000", "0.07296000"], ["71014.35000000", "0.07296000"], ["71014.24000000", "0.07296000"], ["71011.14000000", "0.07296000"], ["71011.02000000", "0.07296000"], ["71009.52000000", "0.07296000"], ["71009.40000000", "0.07296000"], ["71006.32000000", "0.07296000"], ["71006.21000000", "0.07296000"], ["71002.95000000", "0.07296000"], ["64074.72000000", "0.00468000"], ["56955.31000000", "0.00000000"]], "a": [["71199.98000000", "0.21522000"], ["71199.99000000", "0.00016000"], ["71203.17000000", "0.00718000"], ["71204.16000000", "0.00000000"], ["71274.52000000", "0.00269000"], ["71291.86000000", "0.02199000"]]}
{"e": "depthUpdate", "E": 1773437552314, "s": "BTCUSDT", "U": 90101516106, "u": 90101516112, "b": [["70900.00000000", "0.83234000"], ["64074.72000000", "0.00486000"]], "a": [["71214.23000000", "0.00000000"], ["71284.03000000", "0.00240000"]]}
{"e": "depthUpdate", "E": 1773437552414, "s": "BTCUSDT", "U": 90101516113, "u": 90101516117, "b": [["70881.66000000", "0.00190000"], ["64074.72000000", "0.00486000"]], "a": [["71194.14000000", "0.43735000"], ["71500.28000000", "0.00188000"]]}
{"e": "depthUpdate", "E": 1773437552514, "s": "BTCUSDT", "U": 90101516118, "u": 90101516122, "b": [["69773.25000000", "0.00000000"], ["64074.72000000", "0.00486000"], ["56955.31000000", "0.00035000"]], "a": [["71207.46000000", "0.00000000"]]}
{"e": "depthUpdate", "E": 1773437552614, "s": "BTCUSDT", "U": 90101516123, "u": 90101516138, "b": [["71189.80000000", "0.02941000"], ["71189.38000000", "0.00702000"], ["71179.71000000", "0.00000000"], ["71179.22000000", "0.00702000"], ["71177.92000000", "0.00000000"], ["71177.44000000", "0.00702000"], ["64074.72000000", "0.00468000"], ["64074.00000000", "0.00790000"], ["56955.31000000", "0.00000000"], ["42716.48000000", "0.00015000"]], "a": [["71205.99000000", "0.00000000"], ["71206.68000000", "0.00702000"], ["71206.70000000", "0.00000000"], ["71372.58000000", "0.00399000"], ["71391.55000000", "0.00000000"]]}
{"e": "depthUpdate", "E": 1773437552714, "s": "BTCUSDT", "U": 90101516139, "u": 90101516150, "b": [["71194.13000000", "2.75028000"], ["71192.89000000", "0.00710000"], ["71189.70000000", "0.01562000"], ["71189.34000000", "0.00839000"], ["71119.24000000", "0.04978000"], ["71100.12000000", "0.00000000"], ["64074.72000000", "0.00486000"]], "a": [["71214.23000000", "0.00000000"], ["71326.27000000", "0.38713000"]]}
{"e": "depthUpdate", "E": 1773437552814, "s": "BTCUSDT", "U": 90101516151, "u": 90101516157, "b": [["71192.89000000", "0.00008000"], ["71191.82000000", "0.00702000"], ["64074.72000000", "0.00486000"]], "a": [["71202.26000000", "0.00000000"], ["71202.87000000", "0.00702000"], ["71203.17000000", "0.00016000"], ["71205.27000000", "0.00702000"], ["71206.69000000", "0.00000000"], ["71326.26000000", "0.19894000"]]}
{"e": "depthUpdate", "E": 1773437552914, "s": "BTCUSDT", "U": 90101516158, "u": 90101516175, "b": [["71192.89000000", "0.00000000"], ["71192.49000000", "0.17715000"], ["71191.82000000", "0.00710000"], ["71183.98000000", "0.00209000"], ["71156.00000000", "0.00080000"], ["64074.72000000", "0.00468000"]], "a": [["71194.14000000", "0.45227000"], ["71202.27000000", "0.02572000"], ["71202.87000000", "0.00718000"], ["71203.17000000", "0.00000000"]]}
{"e": "depthUpdate", "E": 1773437553014, "s": "BTCUSDT", "U": 90101516176, "u": 90101516182, "b": [["71178.83000000", "0.04215000"], ["64074.72000000", "0.00486000"], ["56955.31000000", "0.00035000"], ["56955.00000000", "0.00813000"]], "a": []}
{"e": "depthUpdate", "E": 1773437553114, "s": "BTCUSDT", "U": 90101516183, "u": 90101516199, "b": [["71068.46000000", "0.00000000"], ["70838.16000000", "0.10000000"], ["70816.90000000", "0.18568000"], ["64074.72000000", "0.00486000"], ["56955.00000000", "0.00013000"]], "a": [["71201.24000000", "0.06741000"], ["71201.25000000", "0.10000000"], ["71201.74000000", "0.00032000"], ["71205.27000000", "0.00000000"], ["71206.67000000", "0.00702000"], ["71222.61000000", "0.30000000"], ["71243.97000000", "0.50000000"], ["71253.38000000", "0.23623000"], ["71265.33000000", "0.70000000"]]}
{"e": "depthUpdate", "E": 1773437553214, "s": "BTCUSDT", "U": 90101516200, "u": 90101516222, "b": [["64074.72000000", "0.00468000"], ["56955.31000000", "0.00000000"]], "a": [["71200.49000000", "0.01620000"], ["71201.23000000", "0.00016000"], ["71201.24000000", "0.06757000"], ["71201.25000000", "0.10016000"], ["71201.74000000", "0.00000000"], ["71202.87000000", "0.00702000"], ["71214.22000000", "0.00000000"], ["71265.16000000", "0.85457000"]]}
{"e": "depthUpdate", "E": 1773437553314, "s": "BTCUSDT", "U": 90101516223, "u": 90101516227, "b": [["64074.72000000", "0.00486000"]], "a": []}
{"e": "depthUpdate", "E": 1773437553414, "s": "BTCUSDT", "U": 90101516228, "u": 90101516232, "b": [["71017.61000000", "0.00000000"], ["64074.72000000", "0.00504000"]], "a": [["71194.14000000", "0.45403000"], ["71377.56000000", "0.00000000"]]}
{"e": "depthUpdate", "E": 1773437553514, "s": "BTCUSDT", "U": 90101516233, "u": 90101516236, "b": [["69773.16000000", "0.00008000"], ["64074.72000000", "0.00504000"], ["56955.31000000", "0.00035000"]], "a": []}
{"e": "depthUpdate", "E": 1773437553614, "s": "BTCUSDT", "U": 90101516237, "u": 90101516244, "b": [["71125.23000000", "0.24181000"], ["70881.66000000", "0.00000000"], ["64074.72000000", "0.00486000"], ["56955.31000000", "0.00000000"]], "a": [["71207.46000000", "0.03667000"], ["71500.28000000", "0.00000000"]]}
{"e": "depthUpdate", "E": 1773437553714, "s": "BTCUSDT", "U": 90101516245, "u": 90101516251, "b": [["71017.60000000", "6.50462000"], ["64074.72000000", "0.00504000"], ["64074.00000000", "0.00810000"]], "a": [["71228.52000000", "0.14623000"], ["71377.56000000", "0.40932000"]]}
{"e": "depthUpdate", "E": 1773437553814, "s": "BTCUSDT", "U": 90101516252, "u": 90101516256, "b": [["64074.72000000", "0.00486000"], ["64074.00000000", "0.00790000"]], "a": [["71374.29000000", "0.02809000"]]}
{"e": "aggTrade", "E": 1773437553886, "s": "BTCUSDT", "a": 3904057798, "p": "71194.13000000", "q": "0.14053000", "f": 6104984089, "l": 6104984089, "T": 1773437553886, "m": true, "M": true}
{"e": "depthUpdate", "E": 1773437553914, "s": "BTCUSDT", "U": 90101516257, "u": 90101516265, "b": [["71194.13000000", "2.60975000"], ["71026.57000000", "0.00000000"], ["71019.49000000", "1.06121000"], ["64074.72000000", "0.00504000"], ["64074.00000000", "0.00790000"]], "a": [["71196.87000000", "0.04852000"]]}
{"e": "depthUpdate", "E": 1773437554014, "s": "BTCUSDT", "U": 90101516266, "u": 90101516287, "b": [["64074.72000000", "0.00486000"], ["56955.31000000", "0.00035000"]], "a": [["71194.14000000", "0.45419000"], ["71194.15000000", "0.00080000"], ["71196.86000000", "0.00024000"], ["71196.87000000", "0.04868000"], ["71201.24000000", "0.06741000"], ["71202.27000000", "0.02556000"], ["71326.26000000", "0.09561000"], ["71326.27000000", "0.00000000"]]}
{"e": "kline", "E": 1773437554027, "s": "BTCUSDT", "k": {"t": 1773437520000, "T": 1773437579999, "s": "BTCUSDT", "i": "1m", "f": 6104983042, "L": 6104984089, "o": "71164.00000000", "c": "71194.13000000", "h": "71194.14000000", "l": "71155.65000000", "v": "12.71326000", "n": 1048, "x": false, "q": "904675.74681790", "V": "11.25000000", "Q": "800533.23309170", "B": "0"}}
{"e": "aggTrade", "E": 1773437554095, "s": "BTCUSDT", "a": 3904057799, "p": "71194.14000000", "q": "0.00007000", "f": 6104984090, "l": 6104984090, "T": 1773437554095, "m": false, "M": true}
{"e": "depthUpdate", "E": 1773437554115, "s": "BTCUSDT", "U": 90101516288, "u": 90101516329, "b": [["71194.13000000", "2.60967000"], ["71189.70000000", "0.01570000"], ["71175.59000000", "0.00372000"], ["71038.07000000", "0.00000000"], ["71036.59000000", "0.00000000"], ["71035.19000000", "0.00000000"], ["71033.05000000", "0.00000000"], ["71031.12000000", "0.00000000"], ["71029.07000000", "0.00000000"], ["71027.79000000", "0.00000000"], ["71027.67000000", "0.00000000"], ["71026.96000000", "0.00000000"], ["71026.85000000", "0.00000000"], ["71025.71000000", "0.00000000"], ["71025.59000000", "0.00000000"], ["71023.49000000", "0.00000000"], ["71023.38000000", "0.00000000"], ["71022.35000000", "0.00000000"], ["71022.24000000", "0.00435000"], ["71019.68000000", "0.00000000"], ["71018.33000000", "0.00000000"], ["71018.22000000", "0.00000000"], ["71016.87000000", "0.00000000"], ["71016.75000000", "0.00000000"], ["71015.99000000", "0.00000000"], ["71015.88000000", "0.00000000"], ["71014.35000000", "0.00000000"], ["71014.24000000", "0.00000000"], ["71011.14000000", "0.00000000"], ["71011.02000000", "0.00000000"], ["71009.52000000", "0.00000000"], ["71009.40000000", "0.00000000"], ["71006.32000000", "0.00000000"], ["71006.21000000", "0.00000000"], ["71002.95000000", "0.00000000"], ["71002.84000000", "0.00000000"], ["64074.72000000", "0.00486000"]], "a": [["71194.14000000", "0.45412000"], ["71214.22000000", "0.00000000"], ["71377.35000000", "0.00000000"]]}
{"e": "depthUpdate", "E": 1773437554214, "s": "BTCUSDT", "U": 90101516330, "u": 90101516334, "b": [["71019.56000000", "0.00000000"], ["64074.72000000", "0.00486000"], ["56955.31000000", "0.00000000"]], "a": [["73600.00000000", "1.17875000"]]}
{"e": "depthUpdate", "E": 1773437554314, "s": "BTCUSDT", "U": 90101516335, "u": 90101516342, "b": [["71192.51000000", "0.00057000"], ["71129.84000000", "0.00000000"], ["70194.13000000", "0.00020000"], ["64074.72000000", "0.00468000"]], "a": [["71207.46000000", "0.00000000"], ["71328.63000000", "0.38713000"], ["71541.23000000", "0.00030000"]]}
{"e": "depthUpdate", "E": 1773437554414, "s": "BTCUSDT", "U": 90101516343, "u": 90101516349, "b": [["64074.72000000", "0.00468000"]], "a": [["71328.62000000", "0.33350000"], ["71328.76000000", "0.00000000"]]}
{"e": "depthUpdate", "E": 1773437554514, "s": "BTCUSDT", "U": 90101516350, "u": 90101516354, "b": [["69773.16000000", "0.00000000"], ["64074.72000000", "0.00486000"], ["56955.31000000", "0.00035000"]], "a": []}
{"e": "depthUpdate", "E": 1773437554614, "s": "BTCUSDT", "U": 90101516355, "u": 90101516526, "b": [["71194.13000000", "2.61669000"], ["71193.15000000", "0.00000000"], ["71192.81000000", "0.00029000"], ["71191.83000000", "0.00702000"], ["71191.82000000", "0.00008000"], ["71189.38000000", "0.00000000"], ["71189.15000000", "0.00702000"], ["71187.55000000", "0.00000000"], ["71187.01000000", "0.00702000"], ["71186.10000000", "0.02810000"], ["71185.77000000", "0.00000000"], ["71182.98000000", "0.01058000"], ["71182.47000000", "0.50566000"], ["71181.61000000", "0.00702000"], ["71181.51000000", "0.00000000"], ["71179.90000000", "0.00000000"], ["71179.89000000", "0.00000000"], ["71179.22000000", "0.00000000"], ["71178.72000000", "0.00120000"], ["71178.70000000", "0.00012000"], ["71177.44000000", "0.00000000"], ["71176.56000000", "0.00190000"], ["71170.70000000", "0.00000000"], ["71166.37000000", "0.05548000"], ["71166.05000000", "0.00000000"], ["71166.02000000", "0.00000000"], ["71164.59000000", "0.00000000"], ["71151.50000000", "0.00009000"], ["71129.61000000", "0.00000000"], ["71120.57000000", "0.00000000"], ["71102.23000000", "0.05477000"], ["71023.87000000", "0.10680000"], ["64074.72000000", "0.00486000"], ["64074.00000000", "0.00790000"], ["56955.31000000", "0.00000000"]], "a": [["71194.14000000", "0.03384000"], ["71194.15000000", "0.00056000"], ["71194.44000000", "0.00008000"], ["71196.86000000", "0.00008000"], ["71196.87000000", "0.00016000"], ["71197.14000000", "0.00000000"], ["71197.55000000", "0.00141000"], ["71199.19000000", "0.00000000"], ["71199.56000000", "0.00023000"], ["71199.57000000", "0.00016000"], ["71199.97000000", "0.00008000"], ["71199.98000000", "0.00016000"], ["71200.00000000", "0.61863000"], ["71200.49000000", "0.00016000"], ["71200.93000000", "0.01601000"], ["71201.23000000", "0.00000000"], ["71201.24000000", "0.00032000"], ["71201.74000000", "0.00016000"], ["71201.78000000", "0.00000000"], ["71202.27000000", "0.00000000"], ["71202.87000000", "0.00000000"], ["71202.97000000", "0.02521000"], ["71204.17000000", "0.00000000"], ["71204.85000000", "0.00000000"], ["71205.81000000", "0.00000000"], ["71206.66000000", "0.00702000"], ["71206.67000000", "0.00000000"], ["71206.68000000", "0.00000000"], ["71206.71000000", "0.00000000"], ["71207.45000000", "0.06898000"], ["71207.80000000", "0.00011000"], ["71207.99000000", "0.00702000"], ["71208.89000000", "0.00000000"], ["71209.60000000", "0.00000000"], ["71209.95000000", "0.00702000"], ["71210.31000000", "0.02000000"], ["71212.74000000", "0.19056000"], ["71212.75000000", "0.00000000"], ["71212.76000000", "0.00000000"], ["71213.56000000", "0.00000000"], ["71213.57000000", "0.00000000"], ["71213.77000000", "0.00000000"], ["71213.97000000", "0.00000000"], ["71214.18000000", "0.00000000"], ["71214.19000000", "0.00000000"], ["71214.48000000", "0.00000000"], ["71214.67000000", "0.00000000"], ["71214.72000000", "0.14042000"], ["71215.77000000", "0.00000000"], ["71216.04000000", "0.70593000"], ["71216.05000000", "3.19858000"], ["71216.06000000", "0.00000000"], ["71216.07000000", "0.00000000"], ["71216.68000000", "0.00000000"], ["71218.73000000", "0.10701000"], ["71218.74000000", "0.06381000"], ["71218.75000000", "0.00000000"], ["71221.48000000", "0.00000000"], ["71223.74000000", "0.37885000"], ["71224.50000000", "0.00200000"], ["71226.65000000", "0.00120000"], ["71226.68000000", "0.00000000"], ["71227.49000000", "0.00000000"], ["71227.97000000", "0.00000000"], ["71228.48000000", "0.00200000"], ["71229.63000000", "0.00702000"], ["71232.02000000", "0.00000000"], ["71232.04000000", "0.00200000"], ["71232.73000000", "0.00000000"], ["71233.55000000", "0.00000000"], ["71235.85000000", "0.00000000"], ["71238.01000000", "0.00431000"], ["71241.06000000", "0.00000000"], ["71241.44000000", "0.00702000"], ["71242.80000000", "0.00702000"], ["71244.57000000", "0.04423000"], ["71247.82000000", "0.00000000"], ["71248.35000000", "0.00000000"], ["71248.46000000", "0.00000000"], ["71249.19000000", "0.00000000"], ["71249.21000000", "0.00000000"], ["71249.39000000", "0.00868000"], ["71249.55000000", "0.00000000"], ["71253.27000000", "0.00000000"], ["71257.34000000", "0.00702000"], ["71258.01000000", "0.91204000"], ["71280.00000000", "0.07068000"], ["71328.62000000", "0.00000000"], ["71328.63000000", "0.00000000"], ["71329.50000000", "0.00000000"], ["71329.52000000", "0.00000000"], ["71329.63000000", "0.00000000"], ["71352.17000000", "0.09795000"], ["71352.26000000", "0.09795000"], ["71352.35000000", "0.09795000"], ["71352.44000000", "0.09795000"], ["71352.55000000", "0.09795000"], ["71373.60000000", "0.00000000"], ["71374.39000000", "0.00000000"], ["71375.25000000", "0.00000000"], ["71375.91000000", "0.00000000"], ["71377.04000000", "0.00000000"], ["71381.18000000", "0.00000000"], ["71397.82000000", "0.09395000"], ["71398.34000000", "0.09395000"]]}
{"e": "aggTrade", "E": 1773437554615, "s": "BTCUSDT", "a": 3904057800, "p": "71194.14000000", "q": "0.03384000", "f": 6104984091, "l": 6104984107, "T": 1773437554615, "m": false, "M": true}
{"e": "aggTrade", "E": 1773437554615, "s": "BTCUSDT", "a": 3904057801, "p": "71194.15000000", "q": "0.00056000", "f": 6104984108, "l": 6104984114, "T": 1773437554615, "m": false, "M": true}
{"e": "aggTrade", "E": 1773437554615, "s": "BTCUSDT", "a": 3904057802, "p": "71194.21000000", "q": "0.00015000", "f": 6104984115, "l": 6104984115, "T": 1773437554615, "m": false, "M": true}
{"e": "aggTrade", "E": 1773437554615, "s": "BTCUSDT", "a": 3904057803, "p": "71194.44000000", "q": "0.00008000", "f": 6104984116, "l": 6104984116, "T": 1773437554615, "m": false, "M": true}
{"e": "aggTrade", "E": 1773437554615, "s": "BTCUSDT", "a": 3904057804, "p": "71196.00000000", "q": "0.00080000", "f": 6104984117, "l": 6104984118, "T": 1773437554615, "m": false, "M": true}
{"e": "aggTrade", "E": 1773437554615, "s": "BTCUSDT", "a": 3904057805, "p": "71196.05000000", "q": "0.00008000", "f": 6104984119, "l": 6104984119, "T": 1773437554615, "m": false, "M": true}
{"e": "aggTrade", "E": 1773437554615, "s": "BTCUSDT", "a": 3904057806, "p": "71196.06000000", "q": "0.00008000", "f": 6104984120, "l": 6104984120, "T": 1773437554615, "m": false, "M": true}
{"e": "aggTrade", "E": 1773437554615, "s": "BTCUSDT", "a": 3904057807, "p": "71196.07000000", "q": "0.00008000", "f": 6104984121, "l": 6104984121, "T": 1773437554615, "m": false, "M": true}
{"e": "aggTrade", "E": 1773437554615, "s": "BTCUSDT", "a": 3904057808, "p": "71196.58000000", "q": "0.00008000", "f": 6104984122, "l": 6104984122, "T": 1773437554615, "m": false, "M": true}
{"e": "aggTrade", "E": 1773437554615, "s": "BTCUSDT", "a": 3904057809, "p": "71196.86000000", "q": "0.00008000", "f": 6104984123, "l": 6104984123, "T": 1773437554615, "m": false, "M": true}
{"e": "aggTrade", "E": 1773437554615, "s": "BTCUSDT", "a": 3904057810, "p": "71196.87000000", "q": "0.00016000", "f": 6104984124, "l": 6104984125, "T": 1773437554615, "m": false, "M": true}
{"e": "aggTrade", "E": 1773437554615, "s": "BTCUSDT", "a": 3904057811, "p": "71196.92000000", "q": "0.00361000", "f": 6104984126, "l": 6104984126, "T": 1773437554615, "m": false, "M": true}
{"e": "aggTrade", "E": 1773437554615, "s": "BTCUSDT", "a": 3904057812, "p": "71197.55000000", "q": "0.00141000", "f": 6104984127, "l": 6104984127, "T": 1773437554615, "m": false, "M": true}
{"e": "aggTrade", "E": 1773437554615, "s": "BTCUSDT", "a": 3904057813, "p": "71197.56000000", "q": "0.00008000", "f": 6104984128, "l": 6104984128, "T": 1773437554615, "m": false, "M": true}
{"e": "aggTrade", "E": 1773437554615, "s": "BTCUSDT", "a": 3904057814, "p": "71197.71000000", "q": "0.00008000", "f": 6104984129, "l": 6104984129, "T": 1773437554615, "m": false, "M": true}
{"e": "aggTrade", "E": 1773437554615, "s": "BTCUSDT", "a": 3904057815, "p": "71197.92000000", "q": "0.00020000", "f": 6104984130, "l": 6104984130, "T": 1773437554615, "m": false, "M": true}
{"e": "aggTrade", "E": 1773437554615, "s": "BTCUSDT", "a": 3904057816, "p": "71198.00000000", "q": "0.00080000", "f": 6104984131, "l": 6104984132, "T": 1773437554615, "m": false, "M": true}
{"e": "aggTrade", "E": 1773437554615, "s": "BTCUSDT", "a": 3904057817, "p": "71198.41000000", "q": "0.00241000", "f": 6104984133, "l": 6104984133, "T": 1773437554615, "m": false, "M": true}
{"e": "aggTrade", "E": 1773437554615, "s": "BTCUSDT", "a": 3904057818, "p": "71198.54000000", "q": "0.00300000", "f": 6104984134, "l": 6104984134, "T": 1773437554615, "m": false, "M": true}
{"e": "aggTrade", "E": 1773437554615, "s": "BTCUSDT", "a": 3904057819, "p": "71199.00000000", "q": "0.00008000", "f": 6104984135, "l": 6104984135, "T": 1773437554615, "m": false, "M": true}
{"e": "aggTrade", "E": 1773437554615, "s": "BTCUSDT", "a": 3904057820, "p": "71199.56000000", "q": "0.00023000", "f": 6104984136, "l": 6104984137, "T": 1773437554615, "m": false, "M": true}
{"e": "aggTrade", "E": 1773437554615, "s": "BTCUSDT", "a": 3904057821, "p": "71199.57000000", "q": "0.00016000", "f": 6104984138, "l": 6104984139, "T": 1773437554615, "m": false, "M": true}
{"e": "aggTrade", "E": 1773437554615, "s": "BTCUSDT", "a": 3904057822, "p": "71199.83000000", "q": "0.00008000", "f": 6104984140, "l": 6104984140, "T": 1773437554615, "m": false, "M": true}
{"e": "aggTrade", "E": 1773437554615, "s": "BTCUSDT", "a": 3904057823, "p": "71199.97000000", "q": "0.00008000", "f": 6104984141, "l": 6104984141, "T": 1773437554615, "m": false, "M": true}
{"e": "aggTrade", "E": 1773437554615, "s": "BTCUSDT", "a": 3904057824, "p": "71199.98000000", "q": "0.00016000", "f": 6104984142, "l": 6104984143, "T": 1773437554615, "m": false, "M": true}
{"e": "aggTrade", "E": 1773437554615, "s": "BTCUSDT", "a": 3904057825, "p": "71199.99000000", "q": "0.00024000", "f": 6104984144, "l": 6104984146, "T": 1773437554615, "m": false, "M": true}
{"e": "aggTrade", "E": 1773437554617, "s": "BTCUSDT", "a": 3904057826, "p": "71200.00000000", "q": "0.00008000", "f": 6104984147, "l": 6104984147, "T": 1773437554617, "m": false, "M": true}
{"e": "depthUpdate", "E": 1773437554714, "s": "BTCUSDT", "U": 90101516527, "u": 90101517090, "b": [["71199.99000000", "4.93214000"], ["71199.98000000", "0.00008000"], ["71199.97000000", "0.00000000"], ["71199.56000000", "0.00000000"], ["71198.53000000", "0.00000000"], ["71198.22000000", "0.00200000"], ["71197.44000000", "0.00021000"], ["71196.91000000", "0.00000000"], ["71196.86000000", "0.00000000"], ["71196.85000000", "0.00000000"], ["71196.44000000", "0.00200000"], ["71196.06000000", "0.00000000"], ["71196.05000000", "0.00000000"], ["71196.04000000", "0.00000000"], ["71195.99000000", "0.17360000"], ["71194.66000000", "0.00200000"], ["71194.43000000", "0.00000000"], ["71194.20000000", "0.00000000"], ["71194.15000000", "0.22186000"], ["71194.14000000", "0.00702000"], ["71194.13000000", "0.35950000"], ["71194.12000000", "0.00000000"], ["71193.66000000", "0.00008000"], ["71193.14000000", "0.00008000"], ["71192.89000000", "0.03510000"], ["71192.64000000", "0.02523000"], ["71192.49000000", "0.00008000"], ["71191.83000000", "0.00710000"], ["71191.82000000", "0.00000000"], ["71191.55000000", "0.05572000"], ["71191.26000000", "0.00141000"], ["71190.70000000", "0.00995000"], ["71189.93000000", "0.00011000"], ["71189.81000000", "0.00382000"], ["71189.70000000", "0.00008000"], ["71189.60000000", "0.00008000"], ["71189.32000000", "0.00340000"], ["71189.15000000", "0.00000000"], ["71188.90000000", "0.00241000"], ["71188.59000000", "0.19434000"], ["71188.30000000", "0.03000000"], ["71187.38000000", "0.00000000"], ["71187.36000000", "0.00140000"], ["71187.01000000", "0.00000000"], ["71186.92000000", "0.00008000"], ["71185.55000000", "0.00702000"], ["71185.46000000", "0.42832000"], ["71185.45000000", "0.00000000"], ["71185.39000000", "0.00000000"], ["71183.68000000", "0.00140000"], ["71182.98000000", "0.00356000"], ["71182.69000000", "0.00356000"], ["71181.61000000", "0.00000000"], ["71181.48000000", "0.00148000"], ["71180.88000000", "0.00000000"], ["71179.69000000", "0.00000000"], ["71179.21000000", "0.00000000"], ["71178.64000000", "0.02659000"], ["71178.60000000", "0.00200000"], ["71177.43000000", "0.02008000"], ["71177.21000000", "0.06000000"], ["71174.73000000", "0.00141000"], ["71173.49000000", "0.00000000"], ["71172.70000000", "0.00200000"], ["71172.30000000", "0.00200000"], ["71171.53000000", "0.00000000"], ["71170.91000000", "0.00000000"], ["71169.74000000", "0.00000000"], ["71167.96000000", "0.00000000"], ["71166.50000000", "0.00000000"], ["71166.48000000", "0.00000000"], ["71166.18000000", "0.00000000"], ["71166.17000000", "0.00356000"], ["71165.28000000", "0.00000000"], ["71164.51000000", "0.03451000"], ["71160.84000000", "0.70252000"], ["71160.70000000", "0.00000000"], ["71160.03000000", "0.02716000"], ["71159.11000000", "0.00011000"], ["71159.10000000", "0.00000000"], ["71156.29000000", "0.00029000"], ["71154.80000000", "0.00000000"], ["71154.40000000", "0.00000000"], ["71153.47000000", "0.00426000"], ["71153.08000000", "0.00632000"], ["71152.73000000", "0.00000000"], ["71152.01000000", "0.00011000"], ["71150.80000000", "0.00426000"], ["71146.16000000", "0.00000000"], ["71142.16000000", "0.00000000"], ["71141.87000000", "0.00000000"], ["71139.98000000", "0.00000000"], ["71135.32000000", "0.06437000"], ["71128.22000000", "0.00000000"], ["71123.36000000", "0.00008000"], ["71123.16000000", "0.11966000"], ["71122.60000000", "0.00000000"], ["71121.08000000", "0.07823000"], ["71119.25000000", "0.00348000"], ["71114.02000000", "0.00243000"], ["71114.01000000", "0.00000000"], ["71108.08000000", "0.00000000"], ["71107.12000000", "1.43380000"], ["71105.50000000", "0.00000000"], ["71102.31000000", "0.00000000"], ["71096.01000000", "0.06283000"], ["71095.97000000", "0.00000000"], ["71084.85000000", "0.09396000"], ["71083.43000000", "0.00000000"], ["71083.08000000", "0.00000000"], ["71067.97000000", "0.00000000"], ["70994.57000000", "0.00000000"], ["70959.35000000", "0.00000000"], ["70946.26000000", "0.00000000"], ["65496.45000000", "0.00016000"], ["64080.00000000", "0.04363000"], ["64074.72000000", "0.00000000"], ["49839.61000000", "0.00000000"], ["49838.36000000", "0.00000000"], ["49837.12000000", "0.00000000"]], "a": [["71194.14000000", "0.00000000"], ["71194.15000000", "0.00000000"], ["71194.21000000", "0.00000000"], ["71194.44000000", "0.00000000"], ["71196.00000000", "0.00000000"], ["71196.05000000", "0.00000000"], ["71196.06000000", "0.00000000"], ["71196.07000000", "0.00000000"], ["71196.58000000", "0.00000000"], ["71196.86000000", "0.00000000"], ["71196.87000000", "0.00000000"], ["71196.92000000", "0.00000000"], ["71197.55000000", "0.00000000"], ["71197.56000000", "0.00000000"], ["71197.71000000", "0.00000000"], ["71197.92000000", "0.00000000"], ["71198.00000000", "0.00000000"], ["71198.41000000", "0.00000000"], ["71198.54000000", "0.00000000"], ["71199.00000000", "0.00000000"], ["71199.56000000", "0.00000000"], ["71199.57000000", "0.00000000"], ["71199.83000000", "0.00000000"], ["71199.97000000", "0.00000000"], ["71199.98000000", "0.00000000"], ["71199.99000000", "0.00000000"], ["71200.00000000", "1.03967000"], ["71200.01000000", "0.00048000"], ["71200.49000000", "0.00000000"], ["71200.67000000", "0.00000000"], ["71200.92000000", "0.00008000"], ["71200.93000000", "0.00040000"], ["71200.94000000", "0.01561000"], ["71201.24000000", "0.00024000"], ["71201.62000000", "0.00000000"], ["71201.74000000", "0.00008000"], ["71201.75000000", "0.00016000"], ["71202.62000000", "0.00000000"], ["71202.96000000", "0.00000000"], ["71202.97000000", "0.00000000"], ["71203.56000000", "0.00000000"], ["71203.61000000", "0.00000000"], ["71203.66000000", "0.00000000"], ["71203.78000000", "0.02627000"], ["71203.79000000", "0.02580000"], ["71204.44000000", "0.00029000"], ["71204.55000000", "0.00000000"], ["71204.81000000", "0.00000000"], ["71205.32000000", "0.00000000"], ["71205.84000000", "0.00016000"], ["71205.85000000", "0.04748000"], ["71206.65000000", "0.00000000"], ["71206.66000000", "0.00000000"], ["71206.97000000", "0.00000000"], ["71206.98000000", "0.00000000"], ["71207.44000000", "0.00008000"], ["71207.45000000", "0.03376000"], ["71207.77000000", "0.07504000"], ["71207.99000000", "0.00000000"], ["71208.74000000", "0.00048000"], ["71208.89000000", "0.00000000"], ["71209.47000000", "0.00000000"], ["71209.48000000", "0.00000000"], ["71209.95000000", "0.00000000"], ["71210.18000000", "0.00000000"], ["71210.30000000", "0.00000000"], ["71210.31000000", "0.00000000"], ["71211.02000000", "0.00702000"], ["71211.57000000", "0.00702000"], ["71212.17000000", "0.00000000"], ["71212.41000000", "0.00000000"], ["71212.45000000", "0.00000000"], ["71212.46000000", "0.00208000"], ["71212.73000000", "0.09587000"], ["71213.88000000", "0.15000000"], ["71214.44000000", "0.00702000"], ["71214.61000000", "0.02000000"], ["71214.72000000", "0.00000000"], ["71215.78000000", "0.00000000"], ["71216.03000000", "1.28372000"], ["71216.05000000", "1.68082000"], ["71216.84000000", "0.00000000"], ["71216.97000000", "0.00000000"], ["71217.24000000", "0.03490000"], ["71217.32000000", "0.14042000"], ["71217.39000000", "0.00008000"], ["71218.72000000", "0.07115000"], ["71218.73000000", "0.00000000"], ["71218.74000000", "0.00000000"], ["71221.35000000", "0.02460000"], ["71221.37000000", "0.42131000"], ["71222.62000000", "0.00000000"], ["71222.87000000", "0.10701000"], ["71222.88000000", "0.00000000"], ["71224.52000000", "0.00000000"], ["71225.44000000", "0.19152000"], ["71226.94000000", "0.00000000"], ["71227.16000000", "0.00012000"], ["71227.33000000", "0.00000000"], ["71227.46000000", "0.00000000"], ["71227.73000000", "0.00000000"], ["71228.48000000", "0.00902000"], ["71229.15000000", "0.50571000"], ["71230.26000000", "0.00200000"], ["71231.18000000", "0.00000000"], ["71231.85000000", "0.00000000"], ["71232.03000000", "0.00140000"], ["71232.44000000", "0.00702000"], ["71234.81000000", "0.00000000"], ["71235.60000000", "0.50528000"], ["71235.69000000", "0.09013000"], ["71237.00000000", "0.00011000"], ["71237.01000000", "0.00000000"], ["71238.19000000", "0.00000000"], ["71239.45000000", "0.00000000"], ["71240.57000000", "0.00350000"], ["71244.56000000", "0.00361000"], ["71246.03000000", "0.00000000"], ["71246.15000000", "0.00433000"], ["71246.16000000", "0.00000000"], ["71246.43000000", "0.06326000"], ["71246.53000000", "0.00428000"], ["71248.32000000", "0.00021000"], ["71249.39000000", "0.00000000"], ["71250.74000000", "0.00000000"], ["71251.31000000", "0.00000000"], ["71251.93000000", "0.00000000"], ["71252.02000000", "0.00000000"], ["71252.19000000", "0.00000000"], ["71252.96000000", "0.00000000"], ["71253.38000000", "0.00000000"], ["71257.63000000", "0.00000000"], ["71258.34000000", "0.01466000"], ["71260.34000000", "0.00000000"], ["71260.60000000", "0.00000000"], ["71262.20000000", "0.01718000"], ["71265.31000000", "0.01087000"], ["71265.75000000", "0.00111000"], ["71267.48000000", "0.00000000"], ["71269.32000000", "0.00008000"], ["71271.48000000", "0.00000000"], ["71272.04000000", "0.00008000"], ["71274.39000000", "0.00000000"], ["71275.07000000", "0.02950000"], ["71288.42000000", "0.84944000"], ["71289.88000000", "2.55832000"], ["71293.55000000", "0.00000000"], ["71295.18000000", "0.00000000"], ["71307.32000000", "0.00000000"], ["71310.13000000", "0.00000000"], ["71312.06000000", "0.00140000"], ["71315.93000000", "0.00140000"], ["71317.75000000", "0.56191000"], ["71321.86000000", "0.08395000"], ["71346.27000000", "0.00000000"], ["71352.02000000", "0.00000000"], ["71352.56000000", "0.09795000"], ["71353.24000000", "0.00000000"], ["71363.71000000", "0.00000000"], ["71365.02000000", "0.00000000"], ["71367.03000000", "0.00000000"], ["71367.86000000", "0.00000000"], ["71368.03000000", "0.00000000"], ["71370.08000000", "0.00000000"], ["71382.91000000", "0.02809000"], ["71388.79000000", "0.12794000"], ["71389.71000000", "0.04198000"], ["71390.76000000", "0.07296000"], ["71391.88000000", "0.21888000"], ["71391.96000000", "0.02809000"], ["71391.97000000", "0.07297000"], ["71392.12000000", "0.02809000"]]}
{"e": "depthUpdate", "E": 1773437554814, "s": "BTCUSDT", "U": 90101517091, "u": 90101517179, "b": [["71199.99000000", "4.94430000"], ["71198.23000000", "0.00000000"], ["71196.45000000", "0.01404000"], ["71196.00000000", "0.07488000"], ["71195.99000000", "0.17368000"], ["71194.15000000", "0.00008000"], ["71194.14000000", "0.00710000"], ["71194.13000000", "0.02248000"], ["71192.89000000", "0.03518000"], ["71192.74000000", "0.00000000"], ["71192.49000000", "0.00000000"], ["71191.83000000", "0.00008000"], ["71191.80000000", "2.53023000"], ["71191.79000000", "0.02102000"], ["71189.80000000", "0.02933000"], ["71189.70000000", "0.00000000"], ["71185.55000000", "0.00000000"], ["71183.99000000", "0.00702000"], ["71167.30000000", "0.14635000"], ["71166.37000000", "0.00000000"], ["71158.50000000", "0.00000000"], ["71154.98000000", "1.73630000"], ["71087.85000000", "0.04425000"], ["70969.92000000", "0.00041000"], ["64080.00000000", "0.04381000"]], "a": [["71200.00000000", "1.04041000"], ["71200.93000000", "0.00024000"], ["71200.94000000", "0.01577000"], ["71201.24000000", "0.03156000"], ["71201.25000000", "0.10016000"], ["71201.74000000", "0.00000000"], ["71201.75000000", "0.00000000"], ["71202.26000000", "0.00008000"], ["71203.77000000", "0.00016000"], ["71203.78000000", "0.02643000"], ["71203.79000000", "0.02596000"], ["71205.85000000", "0.04764000"], ["71207.44000000", "0.00000000"], ["71207.45000000", "0.53138000"], ["71207.77000000", "0.07520000"], ["71210.33000000", "1.68082000"], ["71211.46000000", "0.00141000"], ["71216.02000000", "1.44078000"], ["71216.03000000", "2.71752000"], ["71216.04000000", "0.00702000"], ["71217.32000000", "0.00000000"], ["71217.40000000", "0.00000000"], ["71218.78000000", "0.00000000"], ["71219.50000000", "0.00000000"], ["71221.22000000", "0.00000000"], ["71221.49000000", "0.00000000"], ["71222.21000000", "0.00000000"], ["71223.40000000", "0.50537000"], ["71253.60000000", "0.81049000"], ["71253.61000000", "0.00000000"], ["71284.58000000", "0.00000000"], ["71301.44000000", "0.12525000"], ["71366.29000000", "0.00399000"], ["71372.58000000", "0.00000000"]]}
{"e": "depthUpdate", "E": 1773437554914, "s": "BTCUSDT", "U": 90101517180, "u": 90101517222, "b": [["71199.99000000", "4.94445000"], ["71196.45000000", "0.00710000"], ["71196.00000000", "0.07496000"], ["71195.99000000", "0.17360000"], ["71194.67000000", "0.00702000"], ["71194.15000000", "0.00000000"], ["71194.14000000", "0.00008000"], ["71191.83000000", "0.00000000"], ["71191.82000000", "0.00702000"], ["71188.59000000", "0.00000000"], ["71187.53000000", "0.00008000"], ["71184.92000000", "0.02000000"], ["71184.57000000", "0.02400000"], ["71184.21000000", "0.02800000"], ["71183.99000000", "0.00724000"], ["71183.98000000", "0.00200000"], ["71183.23000000", "0.19435000"], ["71174.91000000", "0.00000000"], ["71149.26000000", "0.02000000"], ["71138.20000000", "0.48709000"], ["71087.85000000", "0.00000000"], ["64080.00000000", "0.04399000"]], "a": [["71200.00000000", "1.04049000"], ["71200.94000000", "0.01577000"], ["71201.23000000", "0.00008000"], ["71201.24000000", "0.00040000"], ["71205.84000000", "0.00008000"], ["71212.73000000", "0.05858000"], ["71212.74000000", "0.00000000"], ["71216.03000000", "2.53023000"], ["71245.55000000", "0.03665000"], ["71253.62000000", "0.00868000"], ["71301.44000000", "0.00000000"]]}
{"e": "depthUpdate", "E": 1773437555014, "s": "BTCUSDT", "U": 90101517223, "u": 90101517270, "b": [["71199.99000000", "5.04125000"], ["71195.99000000", "0.17368000"], ["71195.00000000", "0.00300000"], ["71194.91000000", "0.02483000"], ["71194.67000000", "0.00710000"], ["71194.14000000", "0.00000000"], ["71192.64000000", "0.02531000"], ["71191.82000000", "0.00801000"], ["71191.81000000", "0.79861000"], ["71189.80000000", "0.00356000"], ["71185.75000000", "0.00702000"], ["71184.53000000", "0.00356000"], ["71184.35000000", "0.00008000"], ["71183.99000000", "0.00702000"], ["71178.58000000", "0.00000000"], ["71177.43000000", "0.00008000"], ["71177.08000000", "0.00000000"], ["71175.79000000", "0.50571000"], ["71154.92000000", "0.00000000"], ["71083.36000000", "0.04425000"], ["70559.19000000", "0.00019000"], ["70543.08000000", "0.00000000"], ["64080.00000000", "0.04435000"], ["64079.00000000", "0.00010000"], ["56960.00000000", "0.00035000"]], "a": [["71200.94000000", "0.01577000"], ["71201.24000000", "0.00024000"], ["71204.03000000", "0.00502000"], ["71211.46000000", "0.00000000"], ["71214.96000000", "0.00300000"], ["71217.24000000", "0.00000000"], ["71228.30000000", "0.11748000"], ["71239.87000000", "0.00244000"], ["71246.43000000", "0.00000000"], ["71250.05000000", "0.00000000"], ["71252.34000000", "0.02199000"], ["71261.17000000", "0.07801000"], ["71294.55000000", "0.00000000"], ["71296.77000000", "0.09666000"], ["71296.94000000", "0.00000000"]]}
{"e": "depthUpdate", "E": 1773437555114, "s": "BTCUSDT", "U": 90101517271, "u": 90101517295, "b": [["71199.99000000", "5.04266000"], ["71198.06000000", "0.00141000"], ["71198.01000000", "0.00008000"], ["71195.99000000", "0.17360000"], ["71176.72000000", "0.00000000"], ["64080.00000000", "0.04481000"]], "a": [["71203.79000000", "0.02596000"], ["71204.03000000", "0.00518000"], ["71217.50000000", "0.00000000"], ["71218.21000000", "0.11372000"], ["71218.22000000", "0.00000000"], ["71218.72000000", "0.00000000"], ["71219.42000000", "0.00000000"], ["71226.55000000", "0.00141000"], ["71296.77000000", "0.06791000"], ["71298.19000000", "0.06386000"]]}
{"e": "depthUpdate", "E": 1773437555214, "s": "BTCUSDT", "U": 90101517296, "u": 90101517317, "b": [["71188.74000000", "0.02800000"], ["71188.47000000", "0.02800000"], ["71183.99000000", "0.00000000"], ["71183.24000000", "0.00702000"], ["71181.17000000", "0.00000000"], ["71153.08000000", "0.03432000"], ["71152.82000000", "0.02800000"], ["71111.97000000", "0.00000000"], ["71031.99000000", "0.00862000"], ["71027.29000000", "0.00000000"], ["65496.45000000", "0.00000000"], ["64080.00000000", "0.04509000"], ["56960.00000000", "0.00000000"]], "a": [["71206.73000000", "0.00000000"], ["71218.21000000", "0.07181000"], ["71252.34000000", "0.00000000"], ["71263.67000000", "0.00244000"], ["71298.19000000", "0.12525000"]]}
{"e": "aggTrade", "E": 1773437555214, "s": "BTCUSDT", "a": 3904057827, "p": "71200.00000000", "q": "0.05512000", "f": 6104984148, "l": 6104984149, "T": 1773437555214, "m": false, "M": true}
{"e": "depthUpdate", "E": 1773437555314, "s": "BTCUSDT", "U": 90101517318, "u": 90101517342, "b": [["71194.91000000", "0.00000000"], ["71190.21000000", "0.00008000"], ["71188.58000000", "0.72030000"], ["71188.12000000", "0.05400000"], ["71185.99000000", "0.02400000"], ["71185.19000000", "0.03400000"], ["71177.46000000", "0.02600000"], ["71174.53000000", "0.00000000"], ["71152.46000000", "0.02600000"], ["71150.33000000", "0.02400000"], ["71131.16000000", "0.00000000"], ["71113.33000000", "0.00078000"], ["71105.24000000", "0.00000000"], ["71090.41000000", "0.10000000"], ["70194.13000000", "0.00000000"], ["64080.00000000", "0.04517000"], ["64074.00000000", "0.00780000"]], "a": [["71200.00000000", "0.98537000"], ["71272.25000000", "0.00008000"], ["71290.08000000", "0.10000000"], ["71352.47000000", "0.09495000"], ["71352.57000000", "0.09495000"]]}
{"e": "depthUpdate", "E": 1773437555414, "s": "BTCUSDT", "U": 90101517343, "u": 90101517354, "b": [["71178.08000000", "0.00000000"], ["71177.46000000", "0.00000000"], ["71175.33000000", "0.00000000"], ["71130.57000000", "0.00000000"], ["71112.74000000", "0.00000000"], ["71073.58000000", "0.00000000"], ["64080.00000000", "0.04535000"], ["64079.99000000", "0.00009000"]], "a": [["71338.07000000", "0.38713000"], ["78320.00000000", "0.00300000"]]}
{"e": "depthUpdate", "E": 1773437555514, "s": "BTCUSDT", "U": 90101517355, "u": 90101517366, "b": [["71188.04000000", "0.03200000"], ["69780.12000000", "0.00008000"], ["64080.00000000", "0.04553000"], ["64079.99000000", "0.00000000"], ["56960.00000000", "0.00035000"]], "a": [["71200.00000000", "1.04716000"], ["71217.74000000", "0.03457000"], ["71246.93000000", "0.06284000"], ["78320.00000000", "0.00292000"]]}
{"e": "depthUpdate", "E": 1773437555614, "s": "BTCUSDT", "U": 90101517367, "u": 90101517376, "b": [["71188.76000000", "0.02400000"], ["71188.05000000", "0.02400000"], ["71180.68000000", "0.00000000"], ["71132.15000000", "0.00000000"], ["64080.00000000", "0.04589000"], ["56960.00000000", "0.00000000"]], "a": [["71208.19000000", "0.00702000"], ["71211.02000000", "0.00000000"], ["71219.41000000", "0.00000000"]]}
{"e": "depthUpdate", "E": 1773437555714, "s": "BTCUSDT", "U": 90101517377, "u": 90101517393, "b": [["71188.86000000", "0.02556000"], ["71185.65000000", "0.02200000"], ["71181.40000000", "0.00000000"], ["71180.69000000", "0.00000000"], ["71178.64000000", "0.00200000"], ["71111.48000000", "0.00000000"], ["71110.62000000", "0.00000000"], ["64080.00000000", "0.04607000"], ["56960.00000000", "0.00000000"]], "a": [["71201.55000000", "0.00008000"], ["71207.77000000", "0.07520000"], ["71221.35000000", "0.00000000"], ["71324.85000000", "0.00008000"]]}
{"e": "depthUpdate", "E": 1773437555814, "s": "BTCUSDT", "U": 90101517394, "u": 90101517405, "b": [["71199.99000000", "5.04526000"], ["71195.21000000", "0.00840000"], ["71194.89000000", "0.02534000"], ["71191.79000000", "0.00487000"], ["71189.34000000", "0.00000000"], ["71178.30000000", "0.00000000"], ["71132.28000000", "0.00000000"], ["64080.00000000", "0.04643000"]], "a": [["71218.21000000", "0.13911000"], ["71218.75000000", "0.14041000"], ["71219.47000000", "0.14041000"]]}
{"e": "aggTrade", "E": 1773437555911, "s": "BTCUSDT", "a": 3904057828, "p": "71199.99000000", "q": "0.01369000", "f": 6104984150, "l": 6104984150, "T": 1773437555911, "m": true, "M": true}
{"e": "depthUpdate", "E": 1773437555914, "s": "BTCUSDT", "U": 90101517406, "u": 90101517417, "b": [["71199.99000000", "5.03157000"], ["71196.80000000", "0.01618000"], ["71195.99000000", "0.17368000"], ["71195.21000000", "0.00848000"], ["71192.64000000", "0.02523000"], ["71181.50000000", "0.00000000"], ["71151.79000000", "0.02800000"], ["64080.00000000", "0.04661000"]], "a": [["71200.00000000", "1.04700000"], ["71200.94000000", "0.00016000"], ["71202.26000000", "0.00000000"]]}
{"e": "depthUpdate", "E": 1773437556014, "s": "BTCUSDT", "U": 90101517418, "u": 90101517438, "b": [["71199.99000000", "5.03165000"], ["71192.89000000", "0.03510000"], ["71146.31000000", "0.19767000"], ["64080.00000000", "0.04679000"], ["56960.00000000", "0.00035000"]], "a": [["71200.00000000", "1.04692000"], ["71200.93000000", "0.00000000"], ["71200.94000000", "0.00000000"], ["71201.45000000", "0.01584000"], ["71203.77000000", "0.00024000"], ["71205.84000000", "0.00016000"], ["71207.44000000", "0.00008000"], ["71208.19000000", "0.00718000"]]}
{"e": "kline", "E": 1773437556018, "s": "BTCUSDT", "k": {"t": 1773437520000, "T": 1773437579999, "s": "BTCUSDT", "i": "1m", "f": 6104983042, "L": 6104984150, "o": "71164.00000000", "c": "71199.99000000", "h": "71200.00000000", "l": "71155.65000000", "v": "12.83083000", "n": 1109, "x": false, "q": "913046.49675670", "V": "11.35388000", "Q": "807929.25516740", "B": "0"}}
{"e": "aggTrade", "E": 1773437556018, "s": "BTCUSDT", "a": 3904057829, "p": "71200.00000000", "q": "0.00024000", "f": 6104984151, "l": 6104984151, "T": 1773437556017, "m": false, "M": true}
{"e": "depthUpdate", "E": 1773437556114, "s": "BTCUSDT", "U": 90101517439, "u": 90101517465, "b": [["71199.99000000", "5.03157000"], ["71196.80000000", "0.01626000"], ["71168.64000000", "0.00000000"], ["71152.17000000", "0.00000000"], ["71083.36000000", "0.00000000"], ["64080.00000000", "0.04715000"]], "a": [["71200.00000000", "1.04676000"], ["71200.01000000", "0.00056000"], ["71200.92000000", "0.00000000"], ["71201.25000000", "0.10016000"], ["71201.44000000", "0.00024000"], ["71201.45000000", "0.01600000"], ["71207.44000000", "0.00000000"], ["71208.19000000", "0.00702000"], ["71227.21000000", "0.50534000"], ["71257.15000000", "0.00000000"]]}
{"e": "depthUpdate", "E": 1773437556214, "s": "BTCUSDT", "U": 90101517466, "u": 90101517512, "b": [["71179.87000000", "0.07657000"], ["71135.26000000", "0.02800000"], ["71084.60000000", "0.04425000"], ["71042.41000000", "0.07296000"], ["71040.71000000", "0.07296000"], ["71039.40000000", "0.07296000"], ["71037.91000000", "0.07296000"], ["71036.42000000", "0.07296000"], ["71035.13000000", "0.07296000"], ["71032.16000000", "0.07296000"], ["71030.61000000", "0.07296000"], ["71028.83000000", "0.07296000"], ["71028.75000000", "0.07296000"], ["71027.10000000", "0.07296000"], ["71026.96000000", "0.07296000"], ["71026.55000000", "0.07296000"], ["71026.38000000", "0.07296000"], ["71025.59000000", "0.07296000"], ["71025.43000000", "0.07296000"], ["71024.17000000", "0.07296000"], ["71023.04000000", "0.07296000"], ["71021.79000000", "0.07296000"], ["71020.57000000", "0.07296000"], ["71019.49000000", "1.13417000"], ["71019.00000000", "0.07296000"], ["71018.29000000", "0.07296000"], ["71017.09000000", "0.07296000"], ["71016.24000000", "0.07296000"], ["71015.98000000", "0.07296000"], ["71015.05000000", "0.07296000"], ["71014.62000000", "0.07328000"], ["71013.84000000", "0.07296000"], ["71013.02000000", "0.07296000"], ["71011.75000000", "0.07296000"], ["71009.45000000", "0.07296000"], ["70199.99000000", "0.00040000"], ["64080.00000000", "0.04751000"], ["64079.00000000", "0.00010000"], ["56960.00000000", "0.00000000"]], "a": [["71296.77000000", "0.09666000"], ["71336.54000000", "0.21405000"], ["71392.23000000", "0.07296000"]]}
{"e": "depthUpdate", "E": 1773437556314, "s": "BTCUSDT", "U": 90101517513, "u": 90101517519, "b": [["71160.00000000", "0.00088000"], ["71158.00000000", "0.00080000"], ["71134.64000000", "0.02600000"], ["71114.27000000", "0.00000000"], ["64080.00000000", "0.04769000"]], "a": [["71219.41000000", "0.00000000"]]}
{"e": "depthUpdate", "E": 1773437556414, "s": "BTCUSDT", "U": 90101517520, "u": 90101517543, "b": [["71191.81000000", "0.79870000"], ["71178.63000000", "0.00014000"], ["71170.43000000", "0.00000000"], ["71157.27000000", "0.00014000"], ["71149.07000000", "0.00000000"], ["71135.91000000", "0.00014000"], ["71127.72000000", "0.00000000"], ["71114.55000000", "0.00014000"], ["71106.36000000", "0.00000000"], ["71093.19000000", "0.00014000"], ["71085.00000000", "0.02000000"], ["70000.00000000", "35.21968000"], ["64080.00000000", "0.04769000"]], "a": [["71213.16000000", "0.00050000"], ["71221.36000000", "0.00214000"], ["71234.52000000", "0.00000000"], ["71242.72000000", "0.00014000"], ["71255.87000000", "0.00000000"], ["71264.08000000", "0.00014000"], ["71277.23000000", "0.00000000"], ["71285.44000000", "0.00014000"], ["71298.59000000", "0.00000000"], ["71306.80000000", "0.00014000"]]}
{"e": "depthUpdate", "E": 1773437556514, "s": "BTCUSDT", "U": 90101517544, "u": 90101517562, "b": [["71196.59000000", "0.00008000"], ["71175.86000000", "0.37578000"], ["71164.51000000", "0.00000000"], ["71153.46000000", "0.71537000"], ["71147.54000000", "0.00000000"], ["71027.51000000", "0.02199000"], ["71007.77000000", "0.00000000"], ["70686.66000000", "0.02106000"], ["69780.12000000", "0.00000000"], ["64080.00000000", "0.04805000"], ["56960.00000000", "0.00035000"]], "a": [["71227.25000000", "0.36203000"], ["71228.63000000", "0.00000000"], ["71228.64000000", "0.04214000"], ["71249.66000000", "0.04793000"]]}
{"e": "depthUpdate", "E": 1773437556614, "s": "BTCUSDT", "U": 90101517563, "u": 90101517696, "b": [["71199.99000000", "5.03888000"], ["71196.45000000", "0.00008000"], ["71194.20000000", "0.12000000"], ["71192.87000000", "0.00008000"], ["71192.51000000", "0.00000000"], ["71191.83000000", "1.68082000"], ["71190.02000000", "0.00008000"], ["71189.26000000", "0.02000000"], ["71187.17000000", "0.00008000"], ["71186.40000000", "0.50563000"], ["71183.75000000", "0.05267000"], ["71180.98000000", "0.00000000"], ["71179.68000000", "0.00000000"], ["71170.47000000", "0.00000000"], ["71168.42000000", "0.03501000"], ["71166.54000000", "0.00000000"], ["71159.04000000", "0.11862000"], ["71147.01000000", "0.02400000"], ["71129.85000000", "0.00057000"], ["71113.28000000", "0.00000000"], ["71094.54000000", "0.01474000"], ["71085.57000000", "0.04425000"], ["71084.60000000", "0.00000000"], ["71083.87000000", "0.00000000"], ["71018.07000000", "0.00000000"], ["70679.55000000", "0.00702000"], ["64080.00000000", "0.04823000"], ["56960.00000000", "0.00000000"]], "a": [["71200.00000000", "0.62715000"], ["71201.45000000", "0.00016000"], ["71202.10000000", "0.01549000"], ["71203.78000000", "0.00032000"], ["71203.79000000", "0.00016000"], ["71204.44000000", "0.00000000"], ["71205.34000000", "0.00000000"], ["71205.85000000", "0.00016000"], ["71207.12000000", "0.00208000"], ["71207.45000000", "0.00016000"], ["71207.58000000", "0.00000000"], ["71209.96000000", "0.00000000"], ["71209.97000000", "0.00008000"], ["71210.33000000", "0.00000000"], ["71211.57000000", "0.00000000"], ["71211.58000000", "0.00000000"], ["71211.84000000", "0.04748000"], ["71212.82000000", "0.00008000"], ["71213.87000000", "0.00702000"], ["71213.88000000", "0.00000000"], ["71215.08000000", "0.07000000"], ["71216.01000000", "0.00000000"], ["71216.03000000", "0.00000000"], ["71216.04000000", "0.00000000"], ["71216.05000000", "0.00000000"], ["71216.56000000", "0.00000000"], ["71217.28000000", "0.10000000"], ["71217.74000000", "0.00000000"], ["71218.75000000", "0.00000000"], ["71219.47000000", "0.00000000"], ["71220.94000000", "0.00000000"], ["71221.24000000", "0.14041000"], ["71221.39000000", "0.00000000"], ["71222.28000000", "0.14041000"], ["71223.40000000", "0.00000000"], ["71225.38000000", "0.00000000"], ["71225.48000000", "0.00000000"], ["71226.94000000", "0.09595000"], ["71227.21000000", "0.60229000"], ["71227.25000000", "0.00000000"], ["71228.30000000", "0.00008000"], ["71229.02000000", "2.53023000"], ["71229.04000000", "1.68082000"], ["71231.50000000", "0.00000000"], ["71232.44000000", "0.00000000"], ["71232.73000000", "1.43380000"], ["71232.75000000", "0.00000000"], ["71235.60000000", "0.50728000"], ["71235.69000000", "0.04916000"], ["71237.56000000", "1.43380000"], ["71237.58000000", "1.11643000"], ["71238.88000000", "0.00702000"], ["71239.46000000", "0.82182000"], ["71240.00000000", "0.00120000"], ["71246.93000000", "0.00000000"], ["71248.05000000", "0.00000000"], ["71249.66000000", "0.00000000"], ["71250.13000000", "0.06161000"], ["71261.17000000", "0.00000000"], ["71262.00000000", "0.04491000"], ["71262.03000000", "0.91198000"], ["71264.37000000", "0.07750000"], ["71281.85000000", "0.00000000"], ["71298.43000000", "2.53023000"], ["71316.86000000", "0.00000000"], ["71317.41000000", "0.00000000"], ["71319.89000000", "0.00000000"], ["71326.16000000", "0.00000000"], ["71328.94000000", "0.00000000"], ["71351.65000000", "0.00000000"], ["71352.16000000", "0.00000000"], ["71352.36000000", "0.09595000"], ["71352.45000000", "0.09595000"], ["71352.56000000", "0.19390000"], ["71354.95000000", "0.00000000"], ["71356.17000000", "0.00000000"], ["71357.74000000", "0.00000000"], ["71367.73000000", "0.00000000"], ["71367.80000000", "0.00000000"], ["71381.40000000", "2.09557000"], ["71397.82000000", "0.19090000"], ["71398.34000000", "0.19090000"], ["75344.88000000", "0.01661000"]]}
{"e": "depthUpdate", "E": 1773437556714, "s": "BTCUSDT", "U": 90101517697, "u": 90101517943, "b": [["71199.99000000", "5.11037000"], ["71198.91000000", "0.00361000"], ["71198.07000000", "0.00702000"], ["71198.06000000", "0.00000000"], ["71196.80000000", "0.01626000"], ["71196.45000000", "0.00000000"], ["71196.00000000", "0.10971000"], ["71195.99000000", "0.18363000"], ["71195.01000000", "0.00702000"], ["71194.89000000", "0.02542000"], ["71194.67000000", "0.00008000"], ["71194.20000000", "0.12008000"], ["71194.13000000", "0.00403000"], ["71193.56000000", "0.00009000"], ["71191.84000000", "1.28588000"], ["71191.83000000", "1.68190000"], ["71191.82000000", "0.00000000"], ["71191.81000000", "0.00000000"], ["71189.27000000", "0.00702000"], ["71188.31000000", "0.00000000"], ["71186.41000000", "0.00702000"], ["71185.46000000", "0.42130000"], ["71185.39000000", "0.00702000"], ["71183.24000000", "0.00000000"], ["71182.21000000", "0.06000000"], ["71179.87000000", "0.07296000"], ["71178.64000000", "0.02659000"], ["71177.21000000", "0.00000000"], ["71168.32000000", "0.05548000"], ["71165.58000000", "0.02711000"], ["71160.03000000", "0.02949000"], ["71158.92000000", "0.04387000"], ["71154.98000000", "1.68082000"], ["71154.66000000", "0.03086000"], ["71147.64000000", "0.00000000"], ["71147.11000000", "0.02200000"], ["71146.33000000", "0.30357000"], ["71143.10000000", "0.00000000"], ["71138.16000000", "0.00112000"], ["71131.59000000", "0.16030000"], ["71124.79000000", "0.00000000"], ["71123.85000000", "0.00180000"], ["71107.29000000", "0.00000000"], ["71106.61000000", "1.25045000"], ["71103.75000000", "0.07836000"], ["71101.53000000", "0.05617000"], ["71085.05000000", "0.00000000"], ["71073.70000000", "0.02808000"], ["71065.85000000", "0.00000000"], ["71044.05000000", "0.02808000"], ["71023.87000000", "0.00000000"], ["71017.60000000", "0.00000000"], ["71010.01000000", "0.07296000"], ["71008.51000000", "0.00000000"], ["71007.80000000", "0.07296000"], ["64080.00000000", "0.04805000"], ["56956.54000000", "0.00040000"]], "a": [["71200.00000000", "0.19281000"], ["71200.13000000", "0.00008000"], ["71201.25000000", "0.10016000"], ["71201.44000000", "0.00000000"], ["71201.45000000", "0.00000000"], ["71202.09000000", "0.00000000"], ["71202.10000000", "0.00016000"], ["71202.47000000", "0.00024000"], ["71202.48000000", "0.00000000"], ["71203.77000000", "0.00000000"], ["71203.78000000", "0.00000000"], ["71203.79000000", "0.00000000"], ["71204.02000000", "0.00008000"], ["71204.03000000", "0.00377000"], ["71204.25000000", "0.00016000"], ["71204.26000000", "0.00000000"], ["71205.84000000", "0.00000000"], ["71205.85000000", "0.00000000"], ["71207.11000000", "0.00000000"], ["71207.12000000", "0.00008000"], ["71207.45000000", "0.00000000"], ["71207.76000000", "0.00016000"], ["71208.01000000", "0.01611000"], ["71208.19000000", "0.00000000"], ["71208.89000000", "0.00000000"], ["71208.90000000", "0.00000000"], ["71209.87000000", "0.02547000"], ["71211.02000000", "0.00000000"], ["71211.52000000", "0.00029000"], ["71211.83000000", "0.01937000"], ["71212.45000000", "0.00702000"], ["71212.73000000", "0.00000000"], ["71214.44000000", "0.00000000"], ["71214.61000000", "0.00000000"], ["71215.07000000", "0.58846000"], ["71215.78000000", "0.00702000"], ["71216.01000000", "1.68082000"], ["71216.02000000", "0.00200000"], ["71216.52000000", "0.00000000"], ["71217.04000000", "0.00000000"], ["71218.21000000", "0.07181000"], ["71218.92000000", "0.02000000"], ["71220.06000000", "0.00000000"], ["71221.03000000", "0.00000000"], ["71221.24000000", "0.00000000"], ["71221.35000000", "0.02460000"], ["71221.38000000", "1.44103000"], ["71222.28000000", "0.00000000"], ["71223.31000000", "2.53023000"], ["71223.74000000", "0.00000000"], ["71224.93000000", "0.00000000"], ["71225.03000000", "0.00000000"], ["71227.21000000", "0.67525000"], ["71228.13000000", "0.04891000"], ["71228.64000000", "0.00000000"], ["71229.01000000", "1.79789000"], ["71229.03000000", "0.00000000"], ["71229.15000000", "0.00000000"], ["71229.29000000", "0.00000000"], ["71229.63000000", "0.00000000"], ["71230.41000000", "0.00000000"], ["71230.97000000", "0.00702000"], ["71231.58000000", "0.00000000"], ["71232.12000000", "0.00000000"], ["71232.74000000", "0.00000000"], ["71233.82000000", "0.00200000"], ["71236.11000000", "0.00702000"], ["71237.57000000", "0.00000000"], ["71239.16000000", "0.00200000"], ["71239.46000000", "0.00000000"], ["71242.80000000", "0.00000000"], ["71243.55000000", "0.02808000"], ["71244.55000000", "0.02668000"], ["71245.55000000", "0.00000000"], ["71246.48000000", "0.00000000"], ["71246.49000000", "0.00000000"], ["71246.58000000", "0.00000000"], ["71248.48000000", "0.00000000"], ["71250.13000000", "0.00000000"], ["71250.22000000", "0.00000000"], ["71251.50000000", "0.05581000"], ["71253.62000000", "0.00000000"], ["71253.78000000", "0.00000000"], ["71257.34000000", "0.00000000"], ["71261.03000000", "0.00702000"], ["71262.02000000", "1.17902000"], ["71262.67000000", "0.00008000"], ["71264.37000000", "0.00000000"], ["71264.46000000", "0.00000000"], ["71275.96000000", "0.00000000"], ["71275.99000000", "0.00000000"], ["71277.98000000", "0.00000000"], ["71282.96000000", "0.70132000"], ["71295.22000000", "0.02949000"], ["71299.08000000", "0.04645000"], ["71300.57000000", "0.03802000"], ["71307.33000000", "0.03943000"], ["71316.85000000", "0.00000000"], ["71333.22000000", "1.40165000"], ["71353.09000000", "0.00000000"], ["71365.03000000", "0.00000000"], ["71365.97000000", "0.00000000"], ["71367.60000000", "0.00000000"], ["71369.28000000", "0.00000000"], ["71371.23000000", "0.00000000"], ["71371.73000000", "0.00000000"], ["71372.36000000", "0.00000000"], ["71372.54000000", "0.00000000"], ["71373.19000000", "0.00000000"], ["71376.80000000", "0.00000000"], ["71377.56000000", "0.00000000"], ["71383.05000000", "0.00000000"], ["71383.14000000", "0.08289000"], ["71384.03000000", "0.07296000"], ["71385.50000000", "0.07296000"], ["71387.22000000", "0.07296000"], ["71388.17000000", "0.07296000"], ["71389.84000000", "0.07296000"], ["71390.91000000", "0.07296000"], ["71396.04000000", "0.00000000"], ["71439.84000000", "0.11575000"]]}
{"e": "aggTrade", "E": 1773437556714, "s": "BTCUSDT", "a": 3904057830, "p": "71200.00000000", "q": "0.43442000", "f": 6104984152, "l": 6104984152, "T": 1773437556713, "m": false, "M": true}
{"e": "aggTrade", "E": 1773437556728, "s": "BTCUSDT", "a": 3904057831, "p": "71200.00000000", "q": "0.00636000", "f": 6104984153, "l": 6104984153, "T": 1773437556727, "m": false, "M": true}
{"e": "aggTrade", "E": 1773437556737, "s": "BTCUSDT", "a": 3904057832, "p": "71200.00000000", "q": "0.00632000", "f": 6104984154, "l": 6104984154, "T": 1773437556737, "m": false, "M": true}
{"e": "depthUpdate", "E": 1773437556814, "s": "BTCUSDT", "U": 90101517944, "u": 90101518053, "b": [["71199.99000000", "5.11739000"], ["71198.81000000", "0.01601000"], ["71198.08000000", "0.00141000"], ["71198.07000000", "0.00008000"], ["71195.21000000", "0.00848000"], ["71195.01000000", "0.00710000"], ["71194.89000000", "0.02542000"], ["71194.67000000", "0.00000000"], ["71194.20000000", "0.12008000"], ["71194.13000000", "0.00395000"], ["71192.87000000", "0.00710000"], ["71191.84000000", "1.28696000"], ["71191.83000000", "1.68082000"], ["71191.26000000", "0.00000000"], ["71185.75000000", "0.00000000"], ["71182.70000000", "0.00680000"], ["71182.21000000", "0.00000000"], ["71176.20000000", "0.00200000"], ["71168.40000000", "0.00000000"], ["71161.90000000", "0.00000000"], ["71085.40000000", "0.09695000"], ["70994.69000000", "0.00000000"], ["70903.88000000", "0.07586000"], ["70842.34000000", "0.00000000"], ["64080.00000000", "0.04823000"], ["56960.00000000", "0.00020000"]], "a": [["71200.00000000", "0.17934000"], ["71201.25000000", "0.10016000"], ["71202.10000000", "0.00000000"], ["71202.47000000", "0.00000000"], ["71204.03000000", "0.00361000"], ["71204.25000000", "0.00000000"], ["71204.31000000", "0.00029000"], ["71204.92000000", "0.00000000"], ["71205.28000000", "0.00000000"], ["71207.77000000", "0.07520000"], ["71208.00000000", "0.00120000"], ["71208.01000000", "0.00016000"], ["71209.21000000", "0.00048000"], ["71209.86000000", "0.00000000"], ["71209.87000000", "0.00016000"], ["71210.35000000", "0.00141000"], ["71211.10000000", "0.00000000"], ["71211.82000000", "0.00016000"], ["71211.83000000", "0.01953000"], ["71214.55000000", "0.00047000"], ["71215.37000000", "0.00188000"], ["71222.27000000", "0.00000000"], ["71223.75000000", "0.06000000"], ["71225.40000000", "0.00200000"], ["71225.44000000", "0.00190000"], ["71227.21000000", "0.16991000"], ["71228.12000000", "0.50569000"], ["71232.28000000", "0.00086000"], ["71232.67000000", "0.00000000"], ["71233.20000000", "0.00200000"], ["71234.11000000", "0.37885000"], ["71234.76000000", "0.00000000"], ["71238.42000000", "0.50526000"], ["71244.74000000", "0.35976000"], ["71245.00000000", "0.00629000"], ["71250.69000000", "0.00702000"], ["71267.15000000", "0.05018000"], ["71279.07000000", "0.00000000"], ["71318.48000000", "0.22066000"], ["71366.29000000", "0.00000000"], ["71371.30000000", "0.00399000"], ["71391.70000000", "0.07296000"], ["71398.33000000", "0.00143000"]]}
{"e": "depthUpdate", "E": 1773437556914, "s": "BTCUSDT", "U": 90101518054, "u": 90101518077, "b": [["71199.99000000", "5.11739000"], ["71198.81000000", "0.01609000"], ["71198.07000000", "0.00000000"], ["71185.11000000", "0.06000000"], ["71122.22000000", "0.48719000"], ["64080.00000000", "0.04823000"]], "a": [["71200.00000000", "0.17918000"], ["71200.01000000", "0.00040000"], ["71207.77000000", "0.07520000"], ["71208.01000000", "0.00000000"], ["71209.87000000", "0.00000000"], ["71232.67000000", "0.00000000"], ["71248.95000000", "0.48633000"], ["71290.08000000", "0.00000000"]]}
{"e": "depthUpdate", "E": 1773437557014, "s": "BTCUSDT", "U": 90101518078, "u": 90101518101, "b": [["71179.24000000", "0.37886000"], ["71149.98000000", "0.00000000"], ["71085.57000000", "0.06218000"], ["71024.15000000", "6.66742000"], ["64080.00000000", "0.04823000"], ["56960.00000000", "0.00055000"]], "a": [["71210.35000000", "0.00000000"], ["71211.03000000", "0.00546000"], ["71211.83000000", "0.01969000"], ["71227.20000000", "0.22084000"], ["71228.12000000", "0.00000000"], ["71232.67000000", "0.00000000"], ["71232.94000000", "0.37886000"], ["71234.11000000", "0.00000000"], ["71291.86000000", "0.00000000"], ["71298.19000000", "0.00000000"], ["71348.72000000", "0.04598000"], ["71351.54000000", "0.04598000"], ["71394.58000000", "0.40635000"]]}
{"e": "depthUpdate", "E": 1773437557114, "s": "BTCUSDT", "U": 90101518102, "u": 90101518118, "b": [["70838.16000000", "0.00000000"], ["70816.90000000", "0.00000000"], ["64080.00000000", "0.04805000"]], "a": [["71201.24000000", "0.00008000"], ["71201.25000000", "0.00016000"], ["71209.38000000", "0.00141000"], ["71222.61000000", "0.00000000"], ["71227.15000000", "0.50569000"], ["71227.20000000", "0.06989000"], ["71243.97000000", "0.00000000"], ["71256.31000000", "0.00868000"], ["71265.33000000", "0.00000000"], ["71304.57000000", "0.06386000"]]}
{"e": "depthUpdate", "E": 1773437557214, "s": "BTCUSDT", "U": 90101518119, "u": 90101518184, "b": [["71199.99000000", "5.11178000"], ["71198.72000000", "0.00008000"], ["71198.23000000", "0.00702000"], ["71188.58000000", "1.05188000"], ["71187.10000000", "0.55000000"], ["71179.87000000", "0.00000000"], ["71042.41000000", "0.00000000"], ["71040.71000000", "0.00000000"], ["71039.87000000", "0.00862000"], ["71039.40000000", "0.00000000"], ["71037.91000000", "0.00000000"], ["71036.42000000", "0.00000000"], ["71035.13000000", "0.00000000"], ["71032.16000000", "0.00000000"], ["71031.99000000", "0.00000000"], ["71030.61000000", "0.00000000"], ["71028.83000000", "0.00000000"], ["71028.75000000", "0.00000000"], ["71027.10000000", "0.00000000"], ["71026.96000000", "0.00000000"], ["71026.55000000", "0.00000000"], ["71026.38000000", "0.00000000"], ["71025.59000000", "0.00000000"], ["71025.43000000", "0.00000000"], ["71024.17000000", "0.00000000"], ["71023.04000000", "0.00000000"], ["71021.79000000", "0.00000000"], ["71020.57000000", "0.00000000"], ["71019.49000000", "1.06121000"], ["71019.00000000", "0.00000000"], ["71018.29000000", "0.00000000"], ["71017.09000000", "0.00000000"], ["71016.24000000", "0.00000000"], ["71015.98000000", "0.00000000"], ["71015.05000000", "0.00000000"], ["71014.62000000", "0.00032000"], ["71013.84000000", "0.00000000"], ["71013.02000000", "0.00000000"], ["71011.75000000", "0.00000000"], ["71010.01000000", "0.00000000"], ["71009.45000000", "0.00000000"], ["71007.80000000", "0.00000000"], ["70199.99000000", "0.00000000"], ["64080.00000000", "0.04823000"], ["56960.00000000", "0.00020000"]], "a": [["71200.00000000", "0.17926000"], ["71201.24000000", "0.00000000"], ["71201.25000000", "0.00000000"], ["71221.61000000", "0.03496000"], ["71221.99000000", "0.14040000"], ["71222.66000000", "0.00000000"], ["71222.71000000", "0.14040000"], ["71227.14000000", "0.22088000"], ["71227.20000000", "0.00000000"], ["71232.17000000", "0.11816000"], ["71250.80000000", "0.06176000"], ["71262.07000000", "0.24235000"], ["71265.04000000", "0.07720000"]]}
{"e": "depthUpdate", "E": 1773437557314, "s": "BTCUSDT", "U": 90101518185, "u": 90101518218, "b": [["71198.81000000", "0.01609000"], ["71198.23000000", "0.00710000"], ["71194.20000000", "0.12000000"], ["71172.00000000", "0.00040000"], ["71170.00000000", "0.00040000"], ["71168.00000000", "0.00040000"], ["71096.69000000", "0.10000000"], ["71031.29000000", "1.06113000"], ["71019.49000000", "0.00000000"], ["64080.00000000", "0.04823000"]], "a": [["71200.00000000", "0.17918000"], ["71201.23000000", "0.00000000"], ["71208.10000000", "0.00016000"], ["71208.11000000", "0.01548000"], ["71209.88000000", "0.00024000"], ["71209.89000000", "0.02518000"], ["71214.45000000", "0.00000000"], ["71218.94000000", "0.06000000"], ["71222.45000000", "0.01810000"], ["71232.66000000", "0.00000000"], ["71268.48000000", "0.02000000"], ["71294.29000000", "0.10000000"], ["71296.77000000", "0.82469000"], ["71333.21000000", "0.48845000"], ["71333.78000000", "0.00000000"]]}
{"e": "depthUpdate", "E": 1773437557414, "s": "BTCUSDT", "U": 90101518219, "u": 90101518236, "b": [["71086.60000000", "0.00000000"], ["64080.00000000", "0.04841000"], ["64079.00000000", "0.00010000"]], "a": [["71207.77000000", "0.07520000"], ["71208.11000000", "0.01564000"], ["71209.89000000", "0.02534000"], ["71232.67000000", "0.04214000"], ["71232.82000000", "0.00000000"], ["71268.48000000", "0.00000000"], ["71392.21000000", "0.07296000"]]}
{"e": "depthUpdate", "E": 1773437557514, "s": "BTCUSDT", "U": 90101518237, "u": 90101518285, "b": [["71199.99000000", "5.10476000"], ["71198.82000000", "0.00000000"], ["71198.23000000", "0.00008000"], ["71197.45000000", "0.00702000"], ["71196.81000000", "0.00000000"], ["71195.22000000", "0.00702000"], ["71195.01000000", "0.00008000"], ["71192.90000000", "0.00702000"], ["71192.87000000", "0.00008000"], ["71191.86000000", "1.28336000"], ["71191.85000000", "1.68082000"], ["71191.84000000", "0.00108000"], ["71191.83000000", "0.00000000"], ["71189.27000000", "0.00000000"], ["71189.26000000", "0.00000000"], ["71187.38000000", "0.00000000"], ["71186.41000000", "0.00000000"], ["71185.75000000", "0.00702000"], ["71185.66000000", "0.00702000"], ["71185.53000000", "0.02000000"], ["71184.93000000", "0.00000000"], ["71183.47000000", "0.00702000"], ["71168.32000000", "0.00000000"], ["71159.75000000", "0.05548000"], ["71158.92000000", "0.00000000"], ["71150.86000000", "0.04387000"], ["69780.68000000", "0.00008000"], ["64080.00000000", "0.04823000"], ["56960.00000000", "0.00055000"]], "a": [["71200.00000000", "0.58368000"], ["71207.76000000", "0.03984000"], ["71208.90000000", "0.00200000"], ["71209.38000000", "0.00000000"], ["71209.88000000", "0.00008000"], ["71211.82000000", "0.00000000"], ["71211.83000000", "0.07733000"], ["71211.84000000", "0.00000000"], ["71213.86000000", "0.19491000"], ["71215.06000000", "0.17771000"], ["71232.67000000", "0.00000000"], ["71237.38000000", "0.00000000"], ["71239.04000000", "0.05581000"], ["71239.16000000", "0.00000000"], ["71247.26000000", "0.16991000"], ["71251.50000000", "0.00000000"], ["71256.31000000", "0.00000000"], ["71283.75000000", "1.69826000"]]}
{"e": "aggTrade", "E": 1773437557564, "s": "BTCUSDT", "a": 3904057833, "p": "71199.99000000", "q": "0.98685000", "f": 6104984155, "l": 6104984175, "T": 1773437557563, "m": true, "M": true}
{"e": "aggTrade", "E": 1773437557566, "s": "BTCUSDT", "a": 3904057834, "p": "71199.99000000", "q": "0.08509000", "f": 6104984176, "l": 6104984178, "T": 1773437557565, "m": true, "M": true}
{"e": "aggTrade", "E": 1773437557566, "s": "BTCUSDT", "a": 3904057835, "p": "71199.99000000", "q": "0.31619000", "f": 6104984179, "l": 6104984193, "T": 1773437557566, "m": true, "M": true}
{"e": "aggTrade", "E": 1773437557566, "s": "BTCUSDT", "a": 3904057836, "p": "71199.98000000", "q": "0.00072000", "f": 6104984194, "l": 6104984202, "T": 1773437557566, "m": true, "M": true}
{"e": "aggTrade", "E": 1773437557566, "s": "BTCUSDT", "a": 3904057837, "p": "71198.82000000", "q": "0.00008000", "f": 6104984203, "l": 6104984203, "T": 1773437557566, "m": true, "M": true}
{"e": "aggTrade", "E": 1773437557566, "s": "BTCUSDT", "a": 3904057838, "p": "71198.81000000", "q": "0.00016000", "f": 6104984204, "l": 6104984205, "T": 1773437557566, "m": true, "M": true}
{"e": "aggTrade", "E": 1773437557566, "s": "BTCUSDT", "a": 3904057839, "p": "71198.72000000", "q": "0.00008000", "f": 6104984206, "l": 6104984206, "T": 1773437557566, "m": true, "M": true}
{"e": "aggTrade", "E": 1773437557566, "s": "BTCUSDT", "a": 3904057840, "p": "71198.01000000", "q": "0.00008000", "f": 6104984207, "l": 6104984207, "T": 1773437557566, "m": true, "M": true}
{"e": "aggTrade", "E": 1773437557566, "s": "BTCUSDT", "a": 3904057841, "p": "71197.46000000", "q": "0.00008000", "f": 6104984208, "l": 6104984208, "T": 1773437557566, "m": true, "M": true}
{"e": "aggTrade", "E": 1773437557566, "s": "BTCUSDT", "a": 3904057842, "p": "71197.45000000", "q": "0.00016000", "f": 6104984209, "l": 6104984210, "T": 1773437557566, "m": true, "M": true}
{"e": "aggTrade", "E": 1773437557566, "s": "BTCUSDT", "a": 3904057843, "p": "71196.81000000", "q": "0.00008000", "f": 6104984211, "l": 6104984211, "T": 1773437557566, "m": true, "M": true}
{"e": "depthUpdate", "E": 1773437557614, "s": "BTCUSDT", "U": 90101518286, "u": 90101519128, "b": [["71199.99000000", "0.00000000"], ["71199.98000000", "0.00000000"], ["71198.91000000", "0.00000000"], ["71198.82000000", "0.00000000"], ["71198.81000000", "0.00000000"], ["71198.72000000", "0.00000000"], ["71198.23000000", "0.00000000"], ["71198.22000000", "0.00000000"], ["71198.08000000", "0.00000000"], ["71198.01000000", "0.00000000"], ["71197.46000000", "0.00000000"], ["71197.45000000", "0.00000000"], ["71197.44000000", "0.00000000"], ["71196.81000000", "0.00000000"], ["71196.80000000", "0.23507000"], ["71196.79000000", "0.00072000"], ["71196.44000000", "0.00000000"], ["71196.40000000", "0.00000000"], ["71196.01000000", "0.00024000"], ["71196.00000000", "0.00040000"], ["71195.99000000", "0.00016000"], ["71195.22000000", "0.00024000"], ["71195.21000000", "0.00016000"], ["71195.01000000", "0.00000000"], ["71194.90000000", "0.00000000"], ["71194.89000000", "0.00016000"], ["71194.66000000", "0.00000000"], ["71194.62000000", "0.00000000"], ["71194.53000000", "0.00141000"], ["71194.20000000", "0.00016000"], ["71194.13000000", "0.00039000"], ["71193.87000000", "0.01561000"], ["71193.67000000", "0.00000000"], ["71192.90000000", "0.00016000"], ["71192.89000000", "0.00016000"], ["71192.88000000", "0.00000000"], ["71192.87000000", "0.00000000"], ["71192.81000000", "0.00000000"], ["71192.65000000", "0.00016000"], ["71192.64000000", "0.00000000"], ["71191.88000000", "0.02578000"], ["71191.87000000", "0.00016000"], ["71191.86000000", "0.00115000"], ["71191.85000000", "0.00000000"], ["71191.84000000", "0.00000000"], ["71191.80000000", "0.00000000"], ["71191.79000000", "0.00000000"], ["71191.55000000", "0.00000000"], ["71191.11000000", "0.00000000"], ["71191.10000000", "0.00000000"], ["71190.71000000", "0.00000000"], ["71190.70000000", "0.00000000"], ["71190.22000000", "0.00000000"], ["71189.81000000", "0.00361000"], ["71189.80000000", "0.00000000"], ["71189.40000000", "0.00000000"], ["71189.37000000", "0.00000000"], ["71189.32000000", "0.00140000"], ["71188.86000000", "0.02200000"], ["71188.59000000", "0.00008000"], ["71188.56000000", "0.00000000"], ["71188.31000000", "0.00000000"], ["71188.30000000", "0.00000000"], ["71187.50000000", "0.00000000"], ["71187.41000000", "0.00141000"], ["71187.37000000", "0.00000000"], ["71186.41000000", "0.00000000"], ["71186.40000000", "0.00000000"], ["71186.10000000", "0.00000000"], ["71185.75000000", "0.00000000"], ["71185.66000000", "0.00000000"], ["71185.53000000", "0.00000000"], ["71185.46000000", "0.00000000"], ["71185.44000000", "0.00000000"], ["71185.40000000", "0.00000000"], ["71185.39000000", "0.00000000"], ["71185.32000000", "0.00000000"], ["71185.30000000", "0.00000000"], ["71185.20000000", "0.00000000"], ["71185.11000000", "0.00000000"], ["71185.02000000", "0.82967000"], ["71185.01000000", "0.00000000"], ["71184.99000000", "0.00000000"], ["71184.58000000", "0.00000000"], ["71184.53000000", "0.00000000"], ["71184.32000000", "0.00008000"], ["71184.22000000", "0.00702000"], ["71184.03000000", "0.00000000"], ["71183.76000000", "0.00000000"], ["71183.75000000", "0.00000000"], ["71183.47000000", "0.00000000"], ["71183.46000000", "0.00000000"], ["71183.23000000", "0.00000000"], ["71183.22000000", "0.00000000"], ["71183.14000000", "0.00000000"], ["71182.98000000", "0.00000000"], ["71182.97000000", "0.00000000"], ["71182.90000000", "0.00000000"], ["71182.69000000", "0.00000000"], ["71182.47000000", "0.00000000"], ["71182.23000000", "0.00000000"], ["71182.21000000", "0.00000000"], ["71181.61000000", "0.00000000"], ["71181.26000000", "0.00000000"], ["71181.10000000", "0.00000000"], ["71181.03000000", "0.00000000"], ["71180.40000000", "0.03000000"], ["71180.30000000", "0.00000000"], ["71179.71000000", "0.00000000"], ["71179.25000000", "0.00000000"], ["71179.24000000", "0.00000000"], ["71179.21000000", "2.56533000"], ["71179.19000000", "0.00000000"], ["71179.18000000", "0.00000000"], ["71179.17000000", "0.00000000"], ["71178.83000000", "0.00000000"], ["71178.60000000", "0.00000000"], ["71178.37000000", "0.00000000"], ["71178.06000000", "0.00000000"], ["71177.95000000", "0.00000000"], ["71177.79000000", "0.12000000"], ["71177.55000000", "0.00000000"], ["71177.54000000", "0.00000000"], ["71177.46000000", "0.00000000"], ["71177.23000000", "0.00000000"], ["71176.87000000", "0.00702000"], ["71176.79000000", "0.00141000"], ["71176.70000000", "0.00140000"], ["71175.98000000", "0.00000000"], ["71175.96000000", "2.53023000"], ["71175.79000000", "0.00000000"], ["71174.73000000", "0.00000000"], ["71174.45000000", "0.00000000"], ["71173.59000000", "0.00021000"], ["71173.58000000", "0.00000000"], ["71172.70000000", "0.00000000"], ["71172.30000000", "0.00000000"], ["71172.01000000", "0.00000000"], ["71171.85000000", "0.00000000"], ["71170.99000000", "1.68784000"], ["71170.97000000", "0.00000000"], ["71170.95000000", "2.53023000"], ["71170.90000000", "0.00000000"], ["71170.81000000", "0.00000000"], ["71170.40000000", "0.02810000"], ["71170.32000000", "0.00000000"], ["71170.09000000", "0.00000000"], ["71169.73000000", "0.02000000"], ["71169.16000000", "0.00702000"], ["71169.15000000", "0.00000000"], ["71168.99000000", "0.00000000"], ["71168.48000000", "0.42376000"], ["71168.47000000", "0.03963000"], ["71168.42000000", "0.00011000"], ["71168.32000000", "0.00702000"], ["71167.96000000", "0.00200000"], ["71167.64000000", "0.00702000"], ["71167.44000000", "2.53023000"], ["71167.14000000", "0.00361000"], ["71166.92000000", "0.00000000"], ["71166.77000000", "0.00008000"], ["71166.76000000", "0.00000000"], ["71166.18000000", "0.00200000"], ["71166.17000000", "0.00000000"], ["71166.03000000", "0.00044000"], ["71165.58000000", "0.00000000"], ["71165.42000000", "0.00000000"], ["71165.41000000", "0.00000000"], ["71164.77000000", "0.00140000"], ["71164.40000000", "0.00200000"], ["71164.38000000", "0.00000000"], ["71164.00000000", "0.00040000"], ["71163.80000000", "0.00200000"], ["71163.78000000", "0.00000000"], ["71162.62000000", "0.00200000"], ["71162.59000000", "0.00000000"], ["71162.58000000", "0.00000000"], ["71161.21000000", "0.00000000"], ["71161.04000000", "0.00000000"], ["71160.84000000", "0.00200000"], ["71160.42000000", "0.00000000"], ["71159.93000000", "0.00000000"], ["71159.75000000", "0.00000000"], ["71159.11000000", "0.00000000"], ["71159.06000000", "0.00200000"], ["71159.04000000", "0.00000000"], ["71157.80000000", "0.00200000"], ["71157.40000000", "0.00200000"], ["71156.14000000", "0.00000000"], ["71155.65000000", "0.00011000"], ["71155.64000000", "0.00000000"], ["71155.01000000", "0.00000000"], ["71154.41000000", "0.00000000"], ["71154.26000000", "0.00383000"], ["71153.35000000", "0.00000000"], ["71152.01000000", "0.00000000"], ["71150.86000000", "0.00000000"], ["71149.94000000", "0.00000000"], ["71148.75000000", "0.00011000"], ["71147.87000000", "0.00000000"], ["71146.69000000", "0.00021000"], ["71146.33000000", "0.00000000"], ["71141.60000000", "0.00000000"], ["71140.31000000", "0.00000000"], ["71135.32000000", "0.00000000"], ["71134.61000000", "0.00000000"], ["71134.01000000", "0.06273000"], ["71131.59000000", "0.01076000"], ["71127.12000000", "0.00000000"], ["71125.69000000", "0.00000000"], ["71125.23000000", "0.00000000"], ["71125.07000000", "1.18813000"], ["71125.06000000", "0.70296000"], ["71122.93000000", "0.00000000"], ["71122.22000000", "0.00000000"], ["71121.08000000", "0.00000000"], ["71120.38000000", "0.00000000"], ["71119.78000000", "0.07658000"], ["71119.25000000", "0.00000000"], ["71119.24000000", "0.00000000"], ["71119.00000000", "0.00000000"], ["71116.78000000", "0.70296000"], ["71116.57000000", "0.00350000"], ["71114.02000000", "0.00000000"], ["71110.70000000", "0.00242000"], ["71110.26000000", "0.14954000"], ["71101.53000000", "0.00000000"], ["71097.88000000", "0.00000000"], ["71084.85000000", "0.00000000"], ["71084.84000000", "0.00000000"], ["71084.77000000", "0.00000000"], ["71083.87000000", "0.05267000"], ["71073.90000000", "0.00008000"], ["71073.70000000", "0.00000000"], ["71062.05000000", "1.40700000"], ["71059.82000000", "0.05629000"], ["71031.29000000", "0.00000000"], ["71013.71000000", "0.09894000"], ["71012.71000000", "0.09894000"], ["71011.60000000", "0.09894000"], ["71010.94000000", "0.09894000"], ["70969.92000000", "0.00000000"], ["70962.44000000", "0.00038000"], ["68280.80000000", "0.00009000"], ["68266.55000000", "0.00000000"], ["64080.00000000", "0.04337000"], ["64077.12000000", "0.00018000"], ["56960.00000000", "0.00020000"], ["49838.55000000", "0.00000000"]], "a": [["71196.81000000", "2.11821000"], ["71196.82000000", "0.00016000"], ["71197.45000000", "0.00000000"], ["71197.46000000", "0.00000000"], ["71197.52000000", "0.00021000"], ["71198.22000000", "0.00200000"], ["71198.24000000", "0.16838000"], ["71198.73000000", "0.00000000"], ["71198.82000000", "0.00000000"], ["71198.91000000", "0.00000000"], ["71198.92000000", "0.00000000"], ["71199.99000000", "0.48310000"], ["71200.00000000", "0.11893000"], ["71200.01000000", "0.00000000"], ["71200.57000000", "0.00009000"], ["71201.78000000", "0.00200000"], ["71202.78000000", "0.10000000"], ["71202.88000000", "0.00008000"], ["71203.25000000", "0.02587000"], ["71203.51000000", "0.00000000"], ["71203.52000000", "0.00000000"], ["71203.56000000", "0.00200000"], ["71203.99000000", "0.00000000"], ["71204.02000000", "0.00000000"], ["71204.27000000", "0.00008000"], ["71204.30000000", "1.68082000"], ["71204.57000000", "0.01609000"], ["71205.11000000", "0.00021000"], ["71205.21000000", "0.00000000"], ["71205.34000000", "0.00200000"], ["71205.82000000", "0.17576000"], ["71205.92000000", "1.09643000"], ["71206.58000000", "0.01000000"], ["71207.07000000", "0.00000000"], ["71207.12000000", "0.00208000"], ["71207.48000000", "0.00140000"], ["71207.58000000", "0.00009000"], ["71207.75000000", "0.10701000"], ["71207.76000000", "0.51804000"], ["71207.77000000", "0.00016000"], ["71208.10000000", "0.00000000"], ["71208.53000000", "0.17827000"], ["71208.61000000", "0.00000000"], ["71208.77000000", "0.00000000"], ["71209.21000000", "0.00000000"], ["71209.27000000", "0.00141000"], ["71209.88000000", "1.43388000"], ["71209.89000000", "0.00016000"], ["71209.98000000", "0.00000000"], ["71210.16000000", "1.09643000"], ["71210.27000000", "0.05581000"], ["71210.31000000", "1.68082000"], ["71210.67000000", "0.00000000"], ["71211.14000000", "0.18995000"], ["71211.83000000", "0.17717000"], ["71212.45000000", "0.00000000"], ["71212.61000000", "0.00000000"], ["71212.82000000", "0.00000000"], ["71213.07000000", "1.43380000"], ["71213.13000000", "1.09643000"], ["71213.21000000", "0.00702000"], ["71213.84000000", "0.19348000"], ["71213.85000000", "0.00000000"], ["71213.87000000", "0.00000000"], ["71214.62000000", "0.00995000"], ["71215.07000000", "1.24865000"], ["71215.08000000", "0.06000000"], ["71215.55000000", "0.00000000"], ["71215.78000000", "0.00000000"], ["71215.89000000", "0.00141000"], ["71216.00000000", "2.53143000"], ["71217.28000000", "0.00000000"], ["71217.54000000", "0.04423000"], ["71218.92000000", "0.00000000"], ["71219.43000000", "0.00021000"], ["71221.34000000", "0.00000000"], ["71221.37000000", "0.00000000"], ["71221.61000000", "0.00000000"], ["71221.96000000", "0.05267000"], ["71221.99000000", "0.00000000"], ["71222.70000000", "0.00000000"], ["71222.87000000", "0.00000000"], ["71223.52000000", "0.00000000"], ["71223.75000000", "0.00000000"], ["71225.38000000", "0.00000000"], ["71226.55000000", "0.00000000"], ["71226.70000000", "0.00000000"], ["71228.48000000", "0.00000000"], ["71228.54000000", "0.70185000"], ["71229.62000000", "0.00000000"], ["71230.26000000", "0.00000000"], ["71230.65000000", "0.16633000"], ["71230.97000000", "0.00000000"], ["71231.64000000", "0.00000000"], ["71232.03000000", "0.00000000"], ["71232.04000000", "0.00000000"], ["71232.72000000", "1.09643000"], ["71233.82000000", "0.00000000"], ["71235.27000000", "0.00000000"], ["71235.60000000", "0.00000000"], ["71235.99000000", "0.70178000"], ["71238.42000000", "0.00000000"], ["71239.04000000", "0.00000000"], ["71241.84000000", "0.00000000"], ["71242.79000000", "0.91223000"], ["71244.57000000", "0.00000000"], ["71245.43000000", "0.70169000"], ["71247.26000000", "0.00000000"], ["71248.32000000", "0.00000000"], ["71248.95000000", "0.00000000"], ["71258.01000000", "0.00000000"], ["71262.03000000", "0.00000000"], ["71264.07000000", "0.14954000"], ["71267.09000000", "0.00000000"], ["71274.73000000", "1.40280000"], ["71275.14000000", "0.00000000"], ["71282.96000000", "0.00000000"], ["71288.42000000", "0.69990000"], ["71304.57000000", "0.12524000"], ["71324.85000000", "0.00000000"], ["71331.69000000", "0.00399000"], ["71333.21000000", "0.00000000"], ["71333.22000000", "0.00000000"], ["71371.30000000", "0.00000000"], ["71381.40000000", "2.16852000"], ["71382.59000000", "0.07295000"], ["71382.91000000", "0.00000000"], ["71384.98000000", "0.07295000"], ["71386.33000000", "0.07295000"], ["71386.99000000", "0.04915000"], ["71387.44000000", "0.07295000"], ["71388.31000000", "0.05056000"], ["71388.34000000", "0.07295000"], ["71389.94000000", "0.04915000"], ["71391.08000000", "0.07295000"], ["71650.56000000", "0.00020000"], ["74368.83000000", "0.00996000"]]}
